--- Logging error ---
Traceback (most recent call last):
  File "/usr/lib/python3.10/logging/__init__.py", line 440, in format
    return self._format(record)
  File "/usr/lib/python3.10/logging/__init__.py", line 436, in _format
    return self._fmt % values
KeyError: 'funcname'

During handling of the above exception, another exception occurred:

Traceback (most recent call last):
  File "/usr/lib/python3.10/logging/__init__.py", line 1100, in emit
    msg = self.format(record)
  File "/usr/lib/python3.10/logging/__init__.py", line 943, in format
    return fmt.format(record)
  File "/usr/lib/python3.10/logging/__init__.py", line 681, in format
    s = self.formatMessage(record)
  File "/usr/lib/python3.10/logging/__init__.py", line 650, in formatMessage
    return self._style.format(record)
  File "/usr/lib/python3.10/logging/__init__.py", line 442, in format
    raise ValueError('Formatting field not found in record: %s' % e)
ValueError: Formatting field not found in record: 'funcname'
Call stack:
  File "/usr/bin/uvicorn", line 33, in <module>
    sys.exit(load_entry_point('uvicorn==0.15.0', 'console_scripts', 'uvicorn')())
  File "/usr/lib/python3/dist-packages/click/core.py", line 1128, in __call__
    return self.main(*args, **kwargs)
  File "/usr/lib/python3/dist-packages/click/core.py", line 1053, in main
    rv = self.invoke(ctx)
  File "/usr/lib/python3/dist-packages/click/core.py", line 1395, in invoke
    return ctx.invoke(self.callback, **ctx.params)
  File "/usr/lib/python3/dist-packages/click/core.py", line 754, in invoke
    return __callback(*args, **kwargs)
  File "/usr/lib/python3/dist-packages/uvicorn/main.py", line 425, in main
    run(app, **kwargs)
  File "/usr/lib/python3/dist-packages/uvicorn/main.py", line 442, in run
    ChangeReload(config, target=server.run, sockets=[sock]).run()
  File "/usr/lib/python3/dist-packages/uvicorn/supervisors/basereload.py", line 45, in run
    if self.should_restart():
  File "/usr/lib/python3/dist-packages/uvicorn/supervisors/statreload.py", line 41, in should_restart
    logger.warning(message, display_path)
Message: "StatReload detected file change in '%s'. Reloading..."
Arguments: ('main.py',)
2024-04-30 17:38:23,638 - uvicorn.error - INFO - Shutting down
2024-04-30 17:38:23,739 - uvicorn.error - INFO - Waiting for application shutdown.
2024-04-30 17:38:23,739 - uvicorn.error - INFO - Application shutdown complete.
2024-04-30 17:38:23,740 - uvicorn.error - INFO - Finished server process [14554]
2024-04-30 17:38:23,940 - asyncio - DEBUG - Using selector: EpollSelector
2024-04-30 17:38:24,503 - main - INFO - program_started
2024-04-30 17:38:24,504 - uvicorn.error - INFO - Started server process [14814]
2024-04-30 17:38:24,504 - uvicorn.error - INFO - Waiting for application startup.
2024-04-30 17:38:24,504 - uvicorn.error - INFO - Application startup complete.
2024-04-30 17:38:29,679 - root - INFO - get_payments: received payload <{'user_id': 1234, 'rows': ['id', 'paymentto', 'paymentby', 'amount', 'paidon', 'paymentmode', 'paymentstatus', 'description', 'banktransactionid', 'paymentfor', 'dated', 'createdby', 'isdeleted', 'entityid', 'officeid', 'tds', 'professiontax', 'month', 'deduction'], 'filters': [], 'sort_by': [], 'order': 'asc', 'pg_no': 1, 'pg_size': 15, 'search_key': 'anvay'}>
2024-04-30 17:38:29,708 - root - INFO - QUERY IS : <b'SELECT roleid FROM usertable WHERE id = 1234'>
2024-04-30 17:38:29,722 - root - INFO - QUERY IS : <b'SELECT firstname,lastname,id FROM usertable order by firstname'>
2024-04-30 17:38:29,736 - root - INFO - QUERY IS : <b'SELECT DISTINCT id,name from mode_of_payment order by name'>
2024-04-30 17:38:29,747 - root - INFO - QUERY IS : <b'SELECT DISTINCT id,name from entity order by name'>
2024-04-30 17:38:29,759 - root - INFO - QUERY IS : <b'SELECT DISTINCT id,name from payment_for order by name'>
2024-04-30 17:38:29,768 - root - INFO - QUERY IS : <b'SELECT DISTINCT id,status from z_paymentrequeststatus order by status'>
2024-04-30 17:38:29,769 - root - INFO - filtAndPagination_v2: Prepared final query [SELECT id,paymentto,paymentby,amount,paidon,paymentmode,paymentstatus,description,banktransactionid,paymentfor,dated,createdby,isdeleted,entityid,officeid,tds,professiontax,month,deduction FROM get_payments_view]
2024-04-30 17:38:30,228 - root - INFO - Cursor message is SELECT 2013
2024-04-30 17:38:30,575 - root - INFO - filterAndPaginate_v2: Given filter yeilds <2013> entries
2024-04-30 17:38:30,583 - root - INFO - filterAndPaginate_v2: Given search key <anvay> yeilds <988> entries
2024-04-30 17:38:30,586 - uvicorn.access - send - INFO - 127.0.0.1:60182 - "POST /getPayments HTTP/1.1" 200
2024-04-30 17:39:10,978 - root - INFO - get_payments: received payload <{'user_id': 1234, 'rows': ['id', 'paymentto', 'paymentby', 'amount', 'paidon', 'paymentmode', 'paymentstatus', 'description', 'banktransactionid', 'paymentfor', 'dated', 'createdby', 'isdeleted', 'entityid', 'officeid', 'tds', 'professiontax', 'month', 'deduction'], 'filters': [], 'sort_by': [], 'order': 'asc', 'pg_no': 1, 'pg_size': 15, 'search_key': 'anvay'}>
2024-04-30 17:39:10,998 - root - INFO - QUERY IS : <b'SELECT roleid FROM usertable WHERE id = 1234'>
2024-04-30 17:39:11,015 - root - INFO - QUERY IS : <b'SELECT firstname,lastname,id FROM usertable order by firstname'>
2024-04-30 17:39:11,027 - root - INFO - QUERY IS : <b'SELECT DISTINCT id,name from mode_of_payment order by name'>
2024-04-30 17:39:11,041 - root - INFO - QUERY IS : <b'SELECT DISTINCT id,name from entity order by name'>
2024-04-30 17:39:11,054 - root - INFO - QUERY IS : <b'SELECT DISTINCT id,name from payment_for order by name'>
2024-04-30 17:39:11,066 - root - INFO - QUERY IS : <b'SELECT DISTINCT id,status from z_paymentrequeststatus order by status'>
2024-04-30 17:39:11,066 - root - INFO - filtAndPagination_v2: Prepared final query [SELECT id,paymentto,paymentby,amount,paidon,paymentmode,paymentstatus,description,banktransactionid,paymentfor,dated,createdby,isdeleted,entityid,officeid,tds,professiontax,month,deduction FROM get_payments_view]
2024-04-30 17:39:11,534 - root - INFO - Cursor message is SELECT 2013
2024-04-30 17:39:12,089 - root - INFO - filterAndPaginate_v2: Given filter yeilds <2013> entries
2024-04-30 17:39:12,096 - root - INFO - filterAndPaginate_v2: Given search key <anvay> yeilds <988> entries
2024-04-30 17:39:12,101 - uvicorn.access - send - INFO - 127.0.0.1:51928 - "POST /getPayments HTTP/1.1" 200
--- Logging error ---
Traceback (most recent call last):
  File "/usr/lib/python3.10/logging/__init__.py", line 440, in format
    return self._format(record)
  File "/usr/lib/python3.10/logging/__init__.py", line 436, in _format
    return self._fmt % values
KeyError: 'funcname'

During handling of the above exception, another exception occurred:

Traceback (most recent call last):
  File "/usr/lib/python3.10/logging/__init__.py", line 1100, in emit
    msg = self.format(record)
  File "/usr/lib/python3.10/logging/__init__.py", line 943, in format
    return fmt.format(record)
  File "/usr/lib/python3.10/logging/__init__.py", line 681, in format
    s = self.formatMessage(record)
  File "/usr/lib/python3.10/logging/__init__.py", line 650, in formatMessage
    return self._style.format(record)
  File "/usr/lib/python3.10/logging/__init__.py", line 442, in format
    raise ValueError('Formatting field not found in record: %s' % e)
ValueError: Formatting field not found in record: 'funcname'
Call stack:
  File "/usr/bin/uvicorn", line 33, in <module>
    sys.exit(load_entry_point('uvicorn==0.15.0', 'console_scripts', 'uvicorn')())
  File "/usr/lib/python3/dist-packages/click/core.py", line 1128, in __call__
    return self.main(*args, **kwargs)
  File "/usr/lib/python3/dist-packages/click/core.py", line 1053, in main
    rv = self.invoke(ctx)
  File "/usr/lib/python3/dist-packages/click/core.py", line 1395, in invoke
    return ctx.invoke(self.callback, **ctx.params)
  File "/usr/lib/python3/dist-packages/click/core.py", line 754, in invoke
    return __callback(*args, **kwargs)
  File "/usr/lib/python3/dist-packages/uvicorn/main.py", line 425, in main
    run(app, **kwargs)
  File "/usr/lib/python3/dist-packages/uvicorn/main.py", line 442, in run
    ChangeReload(config, target=server.run, sockets=[sock]).run()
  File "/usr/lib/python3/dist-packages/uvicorn/supervisors/basereload.py", line 45, in run
    if self.should_restart():
  File "/usr/lib/python3/dist-packages/uvicorn/supervisors/statreload.py", line 41, in should_restart
    logger.warning(message, display_path)
Message: "StatReload detected file change in '%s'. Reloading..."
Arguments: ('main.py',)
2024-04-30 17:39:19,523 - uvicorn.error - INFO - Shutting down
2024-04-30 17:39:19,624 - uvicorn.error - INFO - Waiting for application shutdown.
2024-04-30 17:39:19,624 - uvicorn.error - INFO - Application shutdown complete.
2024-04-30 17:39:19,624 - uvicorn.error - INFO - Finished server process [14814]
2024-04-30 17:39:19,809 - asyncio - __init__ - DEBUG - Using selector: EpollSelector
2024-04-30 17:39:20,396 - main - <module> - INFO - program_started
2024-04-30 17:39:20,396 - uvicorn.error - serve - INFO - Started server process [15043]
2024-04-30 17:39:20,397 - uvicorn.error - startup - INFO - Waiting for application startup.
2024-04-30 17:39:20,397 - uvicorn.error - startup - INFO - Application startup complete.
2024-04-30 17:39:25,856 - root - get_payments - INFO - get_payments: received payload <{'user_id': 1234, 'rows': ['id', 'paymentto', 'paymentby', 'amount', 'paidon', 'paymentmode', 'paymentstatus', 'description', 'banktransactionid', 'paymentfor', 'dated', 'createdby', 'isdeleted', 'entityid', 'officeid', 'tds', 'professiontax', 'month', 'deduction'], 'filters': [], 'sort_by': [], 'order': 'asc', 'pg_no': 1, 'pg_size': 15, 'search_key': 'anvay'}>
2024-04-30 17:39:25,890 - root - logMessage - INFO - QUERY IS : <b'SELECT roleid FROM usertable WHERE id = 1234'>
2024-04-30 17:39:25,912 - root - logMessage - INFO - QUERY IS : <b'SELECT firstname,lastname,id FROM usertable order by firstname'>
2024-04-30 17:39:25,929 - root - logMessage - INFO - QUERY IS : <b'SELECT DISTINCT id,name from mode_of_payment order by name'>
2024-04-30 17:39:25,947 - root - logMessage - INFO - QUERY IS : <b'SELECT DISTINCT id,name from entity order by name'>
2024-04-30 17:39:25,973 - root - logMessage - INFO - QUERY IS : <b'SELECT DISTINCT id,name from payment_for order by name'>
2024-04-30 17:39:25,990 - root - logMessage - INFO - QUERY IS : <b'SELECT DISTINCT id,status from z_paymentrequeststatus order by status'>
2024-04-30 17:39:25,991 - root - filterAndPaginate_v2 - INFO - filtAndPagination_v2: Prepared final query [SELECT id,paymentto,paymentby,amount,paidon,paymentmode,paymentstatus,description,banktransactionid,paymentfor,dated,createdby,isdeleted,entityid,officeid,tds,professiontax,month,deduction FROM get_payments_view]
2024-04-30 17:39:26,429 - root - filterAndPaginate_v2 - INFO - Cursor message is SELECT 2013
2024-04-30 17:39:26,756 - root - filterAndPaginate_v2 - INFO - filterAndPaginate_v2: Given filter yeilds <2013> entries
2024-04-30 17:39:26,763 - root - filterAndPaginate_v2 - INFO - filterAndPaginate_v2: Given search key <anvay> yeilds <988> entries
2024-04-30 17:39:26,766 - uvicorn.access - send - INFO - 127.0.0.1:50198 - "POST /getPayments HTTP/1.1" 200
2024-04-30 17:39:41,046 - root - get_payments - INFO - get_payments: received payload <{'user_id': 1234, 'rows': ['id', 'paymentto', 'paymentby', 'amount', 'paidon', 'paymentmode', 'paymentstatus', 'description', 'banktransactionid', 'paymentfor', 'dated', 'createdby', 'isdeleted', 'entityid', 'officeid', 'tds', 'professiontax', 'month', 'deduction'], 'filters': [], 'sort_by': [], 'order': 'asc', 'pg_no': 1, 'pg_size': 15, 'search_key': 'anvay'}>
2024-04-30 17:39:41,069 - root - logMessage - INFO - QUERY IS : <b'SELECT roleid FROM usertable WHERE id = 1234'>
2024-04-30 17:39:41,086 - root - logMessage - INFO - QUERY IS : <b'SELECT firstname,lastname,id FROM usertable order by firstname'>
2024-04-30 17:39:41,099 - root - logMessage - INFO - QUERY IS : <b'SELECT DISTINCT id,name from mode_of_payment order by name'>
2024-04-30 17:39:41,114 - root - logMessage - INFO - QUERY IS : <b'SELECT DISTINCT id,name from entity order by name'>
2024-04-30 17:39:41,126 - root - logMessage - INFO - QUERY IS : <b'SELECT DISTINCT id,name from payment_for order by name'>
2024-04-30 17:39:41,139 - root - logMessage - INFO - QUERY IS : <b'SELECT DISTINCT id,status from z_paymentrequeststatus order by status'>
2024-04-30 17:39:41,139 - root - filterAndPaginate_v2 - INFO - filtAndPagination_v2: Prepared final query [SELECT id,paymentto,paymentby,amount,paidon,paymentmode,paymentstatus,description,banktransactionid,paymentfor,dated,createdby,isdeleted,entityid,officeid,tds,professiontax,month,deduction FROM get_payments_view]
2024-04-30 17:39:41,659 - root - filterAndPaginate_v2 - INFO - Cursor message is SELECT 2013
2024-04-30 17:39:42,062 - root - filterAndPaginate_v2 - INFO - filterAndPaginate_v2: Given filter yeilds <2013> entries
2024-04-30 17:39:42,070 - root - filterAndPaginate_v2 - INFO - filterAndPaginate_v2: Given search key <anvay> yeilds <988> entries
2024-04-30 17:39:42,072 - uvicorn.access - send - INFO - 127.0.0.1:60554 - "POST /getPayments HTTP/1.1" 200
--- Logging error ---
Traceback (most recent call last):
  File "/usr/lib/python3.10/logging/__init__.py", line 440, in format
    return self._format(record)
  File "/usr/lib/python3.10/logging/__init__.py", line 436, in _format
    return self._fmt % values
KeyError: 'funcname'

During handling of the above exception, another exception occurred:

Traceback (most recent call last):
  File "/usr/lib/python3.10/logging/__init__.py", line 1100, in emit
    msg = self.format(record)
  File "/usr/lib/python3.10/logging/__init__.py", line 943, in format
    return fmt.format(record)
  File "/usr/lib/python3.10/logging/__init__.py", line 681, in format
    s = self.formatMessage(record)
  File "/usr/lib/python3.10/logging/__init__.py", line 650, in formatMessage
    return self._style.format(record)
  File "/usr/lib/python3.10/logging/__init__.py", line 442, in format
    raise ValueError('Formatting field not found in record: %s' % e)
ValueError: Formatting field not found in record: 'funcname'
Call stack:
  File "/usr/bin/uvicorn", line 33, in <module>
    sys.exit(load_entry_point('uvicorn==0.15.0', 'console_scripts', 'uvicorn')())
  File "/usr/lib/python3/dist-packages/click/core.py", line 1128, in __call__
    return self.main(*args, **kwargs)
  File "/usr/lib/python3/dist-packages/click/core.py", line 1053, in main
    rv = self.invoke(ctx)
  File "/usr/lib/python3/dist-packages/click/core.py", line 1395, in invoke
    return ctx.invoke(self.callback, **ctx.params)
  File "/usr/lib/python3/dist-packages/click/core.py", line 754, in invoke
    return __callback(*args, **kwargs)
  File "/usr/lib/python3/dist-packages/uvicorn/main.py", line 425, in main
    run(app, **kwargs)
  File "/usr/lib/python3/dist-packages/uvicorn/main.py", line 442, in run
    ChangeReload(config, target=server.run, sockets=[sock]).run()
  File "/usr/lib/python3/dist-packages/uvicorn/supervisors/basereload.py", line 45, in run
    if self.should_restart():
  File "/usr/lib/python3/dist-packages/uvicorn/supervisors/statreload.py", line 41, in should_restart
    logger.warning(message, display_path)
Message: "StatReload detected file change in '%s'. Reloading..."
Arguments: ('main.py',)
2024-04-30 17:39:50,598 - uvicorn.error - shutdown - INFO - Shutting down
2024-04-30 17:39:50,698 - uvicorn.error - shutdown - INFO - Waiting for application shutdown.
2024-04-30 17:39:50,699 - uvicorn.error - shutdown - INFO - Application shutdown complete.
2024-04-30 17:39:50,699 - uvicorn.error - serve - INFO - Finished server process [15043]
--- Logging error ---
Traceback (most recent call last):
  File "/usr/lib/python3.10/logging/__init__.py", line 440, in format
    return self._format(record)
  File "/usr/lib/python3.10/logging/__init__.py", line 436, in _format
    return self._fmt % values
KeyError: 'endpt'

During handling of the above exception, another exception occurred:

Traceback (most recent call last):
  File "/usr/lib/python3.10/logging/__init__.py", line 1100, in emit
    msg = self.format(record)
  File "/usr/lib/python3.10/logging/__init__.py", line 943, in format
    return fmt.format(record)
  File "/usr/lib/python3.10/logging/__init__.py", line 681, in format
    s = self.formatMessage(record)
  File "/usr/lib/python3.10/logging/__init__.py", line 650, in formatMessage
    return self._style.format(record)
  File "/usr/lib/python3.10/logging/__init__.py", line 442, in format
    raise ValueError('Formatting field not found in record: %s' % e)
ValueError: Formatting field not found in record: 'endpt'
Call stack:
  File "<string>", line 1, in <module>
  File "/usr/lib/python3.10/multiprocessing/spawn.py", line 116, in spawn_main
    exitcode = _main(fd, parent_sentinel)
  File "/usr/lib/python3.10/multiprocessing/spawn.py", line 129, in _main
    return self._bootstrap(parent_sentinel)
  File "/usr/lib/python3.10/multiprocessing/process.py", line 314, in _bootstrap
    self.run()
  File "/usr/lib/python3.10/multiprocessing/process.py", line 108, in run
    self._target(*self._args, **self._kwargs)
  File "/usr/lib/python3/dist-packages/uvicorn/subprocess.py", line 76, in subprocess_started
    target(sockets=sockets)
  File "/usr/lib/python3/dist-packages/uvicorn/server.py", line 68, in run
    return asyncio.run(self.serve(sockets=sockets))
  File "/usr/lib/python3.10/asyncio/runners.py", line 39, in run
    loop = events.new_event_loop()
  File "/usr/lib/python3.10/asyncio/events.py", line 783, in new_event_loop
    return get_event_loop_policy().new_event_loop()
  File "/usr/lib/python3.10/asyncio/events.py", line 673, in new_event_loop
    return self._loop_factory()
  File "/usr/lib/python3.10/asyncio/unix_events.py", line 64, in __init__
    super().__init__(selector)
  File "/usr/lib/python3.10/asyncio/selector_events.py", line 54, in __init__
    logger.debug('Using selector: %s', selector.__class__.__name__)
Message: 'Using selector: %s'
Arguments: ('EpollSelector',)
--- Logging error ---
Traceback (most recent call last):
  File "/usr/lib/python3.10/logging/__init__.py", line 440, in format
    return self._format(record)
  File "/usr/lib/python3.10/logging/__init__.py", line 436, in _format
    return self._fmt % values
KeyError: 'endpt'

During handling of the above exception, another exception occurred:

Traceback (most recent call last):
  File "/usr/lib/python3.10/logging/__init__.py", line 1100, in emit
    msg = self.format(record)
  File "/usr/lib/python3.10/logging/__init__.py", line 943, in format
    return fmt.format(record)
  File "/usr/lib/python3.10/logging/__init__.py", line 681, in format
    s = self.formatMessage(record)
  File "/usr/lib/python3.10/logging/__init__.py", line 650, in formatMessage
    return self._style.format(record)
  File "/usr/lib/python3.10/logging/__init__.py", line 442, in format
    raise ValueError('Formatting field not found in record: %s' % e)
ValueError: Formatting field not found in record: 'endpt'
Call stack:
  File "<string>", line 1, in <module>
  File "/usr/lib/python3.10/multiprocessing/spawn.py", line 116, in spawn_main
    exitcode = _main(fd, parent_sentinel)
  File "/usr/lib/python3.10/multiprocessing/spawn.py", line 129, in _main
    return self._bootstrap(parent_sentinel)
  File "/usr/lib/python3.10/multiprocessing/process.py", line 314, in _bootstrap
    self.run()
  File "/usr/lib/python3.10/multiprocessing/process.py", line 108, in run
    self._target(*self._args, **self._kwargs)
  File "/usr/lib/python3/dist-packages/uvicorn/subprocess.py", line 76, in subprocess_started
    target(sockets=sockets)
  File "/usr/lib/python3/dist-packages/uvicorn/server.py", line 68, in run
    return asyncio.run(self.serve(sockets=sockets))
  File "/usr/lib/python3.10/asyncio/runners.py", line 44, in run
    return loop.run_until_complete(main)
  File "/usr/lib/python3.10/asyncio/base_events.py", line 636, in run_until_complete
    self.run_forever()
  File "/usr/lib/python3.10/asyncio/base_events.py", line 603, in run_forever
    self._run_once()
  File "/usr/lib/python3.10/asyncio/base_events.py", line 1909, in _run_once
    handle._run()
  File "/usr/lib/python3.10/asyncio/events.py", line 80, in _run
    self._context.run(self._callback, *self._args)
  File "/usr/lib/python3/dist-packages/uvicorn/server.py", line 76, in serve
    config.load()
  File "/usr/lib/python3/dist-packages/uvicorn/config.py", line 448, in load
    self.loaded_app = import_from_string(self.app)
  File "/usr/lib/python3/dist-packages/uvicorn/importer.py", line 21, in import_from_string
    module = importlib.import_module(module_str)
  File "/usr/lib/python3.10/importlib/__init__.py", line 126, in import_module
    return _bootstrap._gcd_import(name[level:], package, level)
  File "<frozen importlib._bootstrap>", line 1050, in _gcd_import
  File "<frozen importlib._bootstrap>", line 1027, in _find_and_load
  File "<frozen importlib._bootstrap>", line 1006, in _find_and_load_unlocked
  File "<frozen importlib._bootstrap>", line 688, in _load_unlocked
  File "<frozen importlib._bootstrap_external>", line 883, in exec_module
  File "<frozen importlib._bootstrap>", line 241, in _call_with_frames_removed
  File "/mnt/e/cura/cura_backend/./main.py", line 4132, in <module>
    logger.info("program_started")
Message: 'program_started'
Arguments: ()
--- Logging error ---
Traceback (most recent call last):
  File "/usr/lib/python3.10/logging/__init__.py", line 440, in format
    return self._format(record)
  File "/usr/lib/python3.10/logging/__init__.py", line 436, in _format
    return self._fmt % values
KeyError: 'endpt'

During handling of the above exception, another exception occurred:

Traceback (most recent call last):
  File "/usr/lib/python3.10/logging/__init__.py", line 1100, in emit
    msg = self.format(record)
  File "/usr/lib/python3.10/logging/__init__.py", line 943, in format
    return fmt.format(record)
  File "/usr/lib/python3.10/logging/__init__.py", line 681, in format
    s = self.formatMessage(record)
  File "/usr/lib/python3.10/logging/__init__.py", line 650, in formatMessage
    return self._style.format(record)
  File "/usr/lib/python3.10/logging/__init__.py", line 442, in format
    raise ValueError('Formatting field not found in record: %s' % e)
ValueError: Formatting field not found in record: 'endpt'
Call stack:
  File "<string>", line 1, in <module>
  File "/usr/lib/python3.10/multiprocessing/spawn.py", line 116, in spawn_main
    exitcode = _main(fd, parent_sentinel)
  File "/usr/lib/python3.10/multiprocessing/spawn.py", line 129, in _main
    return self._bootstrap(parent_sentinel)
  File "/usr/lib/python3.10/multiprocessing/process.py", line 314, in _bootstrap
    self.run()
  File "/usr/lib/python3.10/multiprocessing/process.py", line 108, in run
    self._target(*self._args, **self._kwargs)
  File "/usr/lib/python3/dist-packages/uvicorn/subprocess.py", line 76, in subprocess_started
    target(sockets=sockets)
  File "/usr/lib/python3/dist-packages/uvicorn/server.py", line 68, in run
    return asyncio.run(self.serve(sockets=sockets))
  File "/usr/lib/python3.10/asyncio/runners.py", line 44, in run
    return loop.run_until_complete(main)
  File "/usr/lib/python3.10/asyncio/base_events.py", line 636, in run_until_complete
    self.run_forever()
  File "/usr/lib/python3.10/asyncio/base_events.py", line 603, in run_forever
    self._run_once()
  File "/usr/lib/python3.10/asyncio/base_events.py", line 1909, in _run_once
    handle._run()
  File "/usr/lib/python3.10/asyncio/events.py", line 80, in _run
    self._context.run(self._callback, *self._args)
  File "/usr/lib/python3/dist-packages/uvicorn/server.py", line 84, in serve
    logger.info(message, process_id, extra={"color_message": color_message})
Message: 'Started server process [%d]'
Arguments: (15174,)
--- Logging error ---
Traceback (most recent call last):
  File "/usr/lib/python3.10/logging/__init__.py", line 440, in format
    return self._format(record)
  File "/usr/lib/python3.10/logging/__init__.py", line 436, in _format
    return self._fmt % values
KeyError: 'endpt'

During handling of the above exception, another exception occurred:

Traceback (most recent call last):
  File "/usr/lib/python3.10/logging/__init__.py", line 1100, in emit
    msg = self.format(record)
  File "/usr/lib/python3.10/logging/__init__.py", line 943, in format
    return fmt.format(record)
  File "/usr/lib/python3.10/logging/__init__.py", line 681, in format
    s = self.formatMessage(record)
  File "/usr/lib/python3.10/logging/__init__.py", line 650, in formatMessage
    return self._style.format(record)
  File "/usr/lib/python3.10/logging/__init__.py", line 442, in format
    raise ValueError('Formatting field not found in record: %s' % e)
ValueError: Formatting field not found in record: 'endpt'
Call stack:
  File "<string>", line 1, in <module>
  File "/usr/lib/python3.10/multiprocessing/spawn.py", line 116, in spawn_main
    exitcode = _main(fd, parent_sentinel)
  File "/usr/lib/python3.10/multiprocessing/spawn.py", line 129, in _main
    return self._bootstrap(parent_sentinel)
  File "/usr/lib/python3.10/multiprocessing/process.py", line 314, in _bootstrap
    self.run()
  File "/usr/lib/python3.10/multiprocessing/process.py", line 108, in run
    self._target(*self._args, **self._kwargs)
  File "/usr/lib/python3/dist-packages/uvicorn/subprocess.py", line 76, in subprocess_started
    target(sockets=sockets)
  File "/usr/lib/python3/dist-packages/uvicorn/server.py", line 68, in run
    return asyncio.run(self.serve(sockets=sockets))
  File "/usr/lib/python3.10/asyncio/runners.py", line 44, in run
    return loop.run_until_complete(main)
  File "/usr/lib/python3.10/asyncio/base_events.py", line 636, in run_until_complete
    self.run_forever()
  File "/usr/lib/python3.10/asyncio/base_events.py", line 603, in run_forever
    self._run_once()
  File "/usr/lib/python3.10/asyncio/base_events.py", line 1909, in _run_once
    handle._run()
  File "/usr/lib/python3.10/asyncio/events.py", line 80, in _run
    self._context.run(self._callback, *self._args)
  File "/usr/lib/python3/dist-packages/uvicorn/server.py", line 86, in serve
    await self.startup(sockets=sockets)
  File "/usr/lib/python3/dist-packages/uvicorn/server.py", line 97, in startup
    await self.lifespan.startup()
  File "/usr/lib/python3/dist-packages/uvicorn/lifespan/on.py", line 45, in startup
    self.logger.info("Waiting for application startup.")
Message: 'Waiting for application startup.'
Arguments: ()
--- Logging error ---
Traceback (most recent call last):
  File "/usr/lib/python3.10/logging/__init__.py", line 440, in format
    return self._format(record)
  File "/usr/lib/python3.10/logging/__init__.py", line 436, in _format
    return self._fmt % values
KeyError: 'endpt'

During handling of the above exception, another exception occurred:

Traceback (most recent call last):
  File "/usr/lib/python3.10/logging/__init__.py", line 1100, in emit
    msg = self.format(record)
  File "/usr/lib/python3.10/logging/__init__.py", line 943, in format
    return fmt.format(record)
  File "/usr/lib/python3.10/logging/__init__.py", line 681, in format
    s = self.formatMessage(record)
  File "/usr/lib/python3.10/logging/__init__.py", line 650, in formatMessage
    return self._style.format(record)
  File "/usr/lib/python3.10/logging/__init__.py", line 442, in format
    raise ValueError('Formatting field not found in record: %s' % e)
ValueError: Formatting field not found in record: 'endpt'
Call stack:
  File "<string>", line 1, in <module>
  File "/usr/lib/python3.10/multiprocessing/spawn.py", line 116, in spawn_main
    exitcode = _main(fd, parent_sentinel)
  File "/usr/lib/python3.10/multiprocessing/spawn.py", line 129, in _main
    return self._bootstrap(parent_sentinel)
  File "/usr/lib/python3.10/multiprocessing/process.py", line 314, in _bootstrap
    self.run()
  File "/usr/lib/python3.10/multiprocessing/process.py", line 108, in run
    self._target(*self._args, **self._kwargs)
  File "/usr/lib/python3/dist-packages/uvicorn/subprocess.py", line 76, in subprocess_started
    target(sockets=sockets)
  File "/usr/lib/python3/dist-packages/uvicorn/server.py", line 68, in run
    return asyncio.run(self.serve(sockets=sockets))
  File "/usr/lib/python3.10/asyncio/runners.py", line 44, in run
    return loop.run_until_complete(main)
  File "/usr/lib/python3.10/asyncio/base_events.py", line 636, in run_until_complete
    self.run_forever()
  File "/usr/lib/python3.10/asyncio/base_events.py", line 603, in run_forever
    self._run_once()
  File "/usr/lib/python3.10/asyncio/base_events.py", line 1909, in _run_once
    handle._run()
  File "/usr/lib/python3.10/asyncio/events.py", line 80, in _run
    self._context.run(self._callback, *self._args)
  File "/usr/lib/python3/dist-packages/uvicorn/server.py", line 86, in serve
    await self.startup(sockets=sockets)
  File "/usr/lib/python3/dist-packages/uvicorn/server.py", line 97, in startup
    await self.lifespan.startup()
  File "/usr/lib/python3/dist-packages/uvicorn/lifespan/on.py", line 59, in startup
    self.logger.info("Application startup complete.")
Message: 'Application startup complete.'
Arguments: ()
--- Logging error ---
Traceback (most recent call last):
  File "/usr/lib/python3.10/logging/__init__.py", line 440, in format
    return self._format(record)
  File "/usr/lib/python3.10/logging/__init__.py", line 436, in _format
    return self._fmt % values
KeyError: 'funcname'

During handling of the above exception, another exception occurred:

Traceback (most recent call last):
  File "/usr/lib/python3.10/logging/__init__.py", line 1100, in emit
    msg = self.format(record)
  File "/usr/lib/python3.10/logging/__init__.py", line 943, in format
    return fmt.format(record)
  File "/usr/lib/python3.10/logging/__init__.py", line 681, in format
    s = self.formatMessage(record)
  File "/usr/lib/python3.10/logging/__init__.py", line 650, in formatMessage
    return self._style.format(record)
  File "/usr/lib/python3.10/logging/__init__.py", line 442, in format
    raise ValueError('Formatting field not found in record: %s' % e)
ValueError: Formatting field not found in record: 'funcname'
Call stack:
  File "/usr/bin/uvicorn", line 33, in <module>
    sys.exit(load_entry_point('uvicorn==0.15.0', 'console_scripts', 'uvicorn')())
  File "/usr/lib/python3/dist-packages/click/core.py", line 1128, in __call__
    return self.main(*args, **kwargs)
  File "/usr/lib/python3/dist-packages/click/core.py", line 1053, in main
    rv = self.invoke(ctx)
  File "/usr/lib/python3/dist-packages/click/core.py", line 1395, in invoke
    return ctx.invoke(self.callback, **ctx.params)
  File "/usr/lib/python3/dist-packages/click/core.py", line 754, in invoke
    return __callback(*args, **kwargs)
  File "/usr/lib/python3/dist-packages/uvicorn/main.py", line 425, in main
    run(app, **kwargs)
  File "/usr/lib/python3/dist-packages/uvicorn/main.py", line 442, in run
    ChangeReload(config, target=server.run, sockets=[sock]).run()
  File "/usr/lib/python3/dist-packages/uvicorn/supervisors/basereload.py", line 45, in run
    if self.should_restart():
  File "/usr/lib/python3/dist-packages/uvicorn/supervisors/statreload.py", line 41, in should_restart
    logger.warning(message, display_path)
Message: "StatReload detected file change in '%s'. Reloading..."
Arguments: ('main.py',)
--- Logging error ---
Traceback (most recent call last):
  File "/usr/lib/python3.10/logging/__init__.py", line 440, in format
    return self._format(record)
  File "/usr/lib/python3.10/logging/__init__.py", line 436, in _format
    return self._fmt % values
KeyError: 'endpt'

During handling of the above exception, another exception occurred:

Traceback (most recent call last):
  File "/usr/lib/python3.10/logging/__init__.py", line 1100, in emit
    msg = self.format(record)
  File "/usr/lib/python3.10/logging/__init__.py", line 943, in format
    return fmt.format(record)
  File "/usr/lib/python3.10/logging/__init__.py", line 681, in format
    s = self.formatMessage(record)
  File "/usr/lib/python3.10/logging/__init__.py", line 650, in formatMessage
    return self._style.format(record)
  File "/usr/lib/python3.10/logging/__init__.py", line 442, in format
    raise ValueError('Formatting field not found in record: %s' % e)
ValueError: Formatting field not found in record: 'endpt'
Call stack:
  File "<string>", line 1, in <module>
  File "/usr/lib/python3.10/multiprocessing/spawn.py", line 116, in spawn_main
    exitcode = _main(fd, parent_sentinel)
  File "/usr/lib/python3.10/multiprocessing/spawn.py", line 129, in _main
    return self._bootstrap(parent_sentinel)
  File "/usr/lib/python3.10/multiprocessing/process.py", line 314, in _bootstrap
    self.run()
  File "/usr/lib/python3.10/multiprocessing/process.py", line 108, in run
    self._target(*self._args, **self._kwargs)
  File "/usr/lib/python3/dist-packages/uvicorn/subprocess.py", line 76, in subprocess_started
    target(sockets=sockets)
  File "/usr/lib/python3/dist-packages/uvicorn/server.py", line 68, in run
    return asyncio.run(self.serve(sockets=sockets))
  File "/usr/lib/python3.10/asyncio/runners.py", line 44, in run
    return loop.run_until_complete(main)
  File "/usr/lib/python3.10/asyncio/base_events.py", line 636, in run_until_complete
    self.run_forever()
  File "/usr/lib/python3.10/asyncio/base_events.py", line 603, in run_forever
    self._run_once()
  File "/usr/lib/python3.10/asyncio/base_events.py", line 1909, in _run_once
    handle._run()
  File "/usr/lib/python3.10/asyncio/events.py", line 80, in _run
    self._context.run(self._callback, *self._args)
  File "/usr/lib/python3/dist-packages/uvicorn/server.py", line 90, in serve
    await self.shutdown(sockets=sockets)
  File "/usr/lib/python3/dist-packages/uvicorn/server.py", line 263, in shutdown
    logger.info("Shutting down")
Message: 'Shutting down'
Arguments: ()
--- Logging error ---
Traceback (most recent call last):
  File "/usr/lib/python3.10/logging/__init__.py", line 440, in format
    return self._format(record)
  File "/usr/lib/python3.10/logging/__init__.py", line 436, in _format
    return self._fmt % values
KeyError: 'endpt'

During handling of the above exception, another exception occurred:

Traceback (most recent call last):
  File "/usr/lib/python3.10/logging/__init__.py", line 1100, in emit
    msg = self.format(record)
  File "/usr/lib/python3.10/logging/__init__.py", line 943, in format
    return fmt.format(record)
  File "/usr/lib/python3.10/logging/__init__.py", line 681, in format
    s = self.formatMessage(record)
  File "/usr/lib/python3.10/logging/__init__.py", line 650, in formatMessage
    return self._style.format(record)
  File "/usr/lib/python3.10/logging/__init__.py", line 442, in format
    raise ValueError('Formatting field not found in record: %s' % e)
ValueError: Formatting field not found in record: 'endpt'
Call stack:
  File "<string>", line 1, in <module>
  File "/usr/lib/python3.10/multiprocessing/spawn.py", line 116, in spawn_main
    exitcode = _main(fd, parent_sentinel)
  File "/usr/lib/python3.10/multiprocessing/spawn.py", line 129, in _main
    return self._bootstrap(parent_sentinel)
  File "/usr/lib/python3.10/multiprocessing/process.py", line 314, in _bootstrap
    self.run()
  File "/usr/lib/python3.10/multiprocessing/process.py", line 108, in run
    self._target(*self._args, **self._kwargs)
  File "/usr/lib/python3/dist-packages/uvicorn/subprocess.py", line 76, in subprocess_started
    target(sockets=sockets)
  File "/usr/lib/python3/dist-packages/uvicorn/server.py", line 68, in run
    return asyncio.run(self.serve(sockets=sockets))
  File "/usr/lib/python3.10/asyncio/runners.py", line 44, in run
    return loop.run_until_complete(main)
  File "/usr/lib/python3.10/asyncio/base_events.py", line 636, in run_until_complete
    self.run_forever()
  File "/usr/lib/python3.10/asyncio/base_events.py", line 603, in run_forever
    self._run_once()
  File "/usr/lib/python3.10/asyncio/base_events.py", line 1909, in _run_once
    handle._run()
  File "/usr/lib/python3.10/asyncio/events.py", line 80, in _run
    self._context.run(self._callback, *self._args)
  File "/usr/lib/python3/dist-packages/uvicorn/server.py", line 90, in serve
    await self.shutdown(sockets=sockets)
  File "/usr/lib/python3/dist-packages/uvicorn/server.py", line 294, in shutdown
    await self.lifespan.shutdown()
  File "/usr/lib/python3/dist-packages/uvicorn/lifespan/on.py", line 64, in shutdown
    self.logger.info("Waiting for application shutdown.")
Message: 'Waiting for application shutdown.'
Arguments: ()
--- Logging error ---
Traceback (most recent call last):
  File "/usr/lib/python3.10/logging/__init__.py", line 440, in format
    return self._format(record)
  File "/usr/lib/python3.10/logging/__init__.py", line 436, in _format
    return self._fmt % values
KeyError: 'endpt'

During handling of the above exception, another exception occurred:

Traceback (most recent call last):
  File "/usr/lib/python3.10/logging/__init__.py", line 1100, in emit
    msg = self.format(record)
  File "/usr/lib/python3.10/logging/__init__.py", line 943, in format
    return fmt.format(record)
  File "/usr/lib/python3.10/logging/__init__.py", line 681, in format
    s = self.formatMessage(record)
  File "/usr/lib/python3.10/logging/__init__.py", line 650, in formatMessage
    return self._style.format(record)
  File "/usr/lib/python3.10/logging/__init__.py", line 442, in format
    raise ValueError('Formatting field not found in record: %s' % e)
ValueError: Formatting field not found in record: 'endpt'
Call stack:
  File "<string>", line 1, in <module>
  File "/usr/lib/python3.10/multiprocessing/spawn.py", line 116, in spawn_main
    exitcode = _main(fd, parent_sentinel)
  File "/usr/lib/python3.10/multiprocessing/spawn.py", line 129, in _main
    return self._bootstrap(parent_sentinel)
  File "/usr/lib/python3.10/multiprocessing/process.py", line 314, in _bootstrap
    self.run()
  File "/usr/lib/python3.10/multiprocessing/process.py", line 108, in run
    self._target(*self._args, **self._kwargs)
  File "/usr/lib/python3/dist-packages/uvicorn/subprocess.py", line 76, in subprocess_started
    target(sockets=sockets)
  File "/usr/lib/python3/dist-packages/uvicorn/server.py", line 68, in run
    return asyncio.run(self.serve(sockets=sockets))
  File "/usr/lib/python3.10/asyncio/runners.py", line 44, in run
    return loop.run_until_complete(main)
  File "/usr/lib/python3.10/asyncio/base_events.py", line 636, in run_until_complete
    self.run_forever()
  File "/usr/lib/python3.10/asyncio/base_events.py", line 603, in run_forever
    self._run_once()
  File "/usr/lib/python3.10/asyncio/base_events.py", line 1909, in _run_once
    handle._run()
  File "/usr/lib/python3.10/asyncio/events.py", line 80, in _run
    self._context.run(self._callback, *self._args)
  File "/usr/lib/python3/dist-packages/uvicorn/server.py", line 90, in serve
    await self.shutdown(sockets=sockets)
  File "/usr/lib/python3/dist-packages/uvicorn/server.py", line 294, in shutdown
    await self.lifespan.shutdown()
  File "/usr/lib/python3/dist-packages/uvicorn/lifespan/on.py", line 75, in shutdown
    self.logger.info("Application shutdown complete.")
Message: 'Application shutdown complete.'
Arguments: ()
--- Logging error ---
Traceback (most recent call last):
  File "/usr/lib/python3.10/logging/__init__.py", line 440, in format
    return self._format(record)
  File "/usr/lib/python3.10/logging/__init__.py", line 436, in _format
    return self._fmt % values
KeyError: 'endpt'

During handling of the above exception, another exception occurred:

Traceback (most recent call last):
  File "/usr/lib/python3.10/logging/__init__.py", line 1100, in emit
    msg = self.format(record)
  File "/usr/lib/python3.10/logging/__init__.py", line 943, in format
    return fmt.format(record)
  File "/usr/lib/python3.10/logging/__init__.py", line 681, in format
    s = self.formatMessage(record)
  File "/usr/lib/python3.10/logging/__init__.py", line 650, in formatMessage
    return self._style.format(record)
  File "/usr/lib/python3.10/logging/__init__.py", line 442, in format
    raise ValueError('Formatting field not found in record: %s' % e)
ValueError: Formatting field not found in record: 'endpt'
Call stack:
  File "<string>", line 1, in <module>
  File "/usr/lib/python3.10/multiprocessing/spawn.py", line 116, in spawn_main
    exitcode = _main(fd, parent_sentinel)
  File "/usr/lib/python3.10/multiprocessing/spawn.py", line 129, in _main
    return self._bootstrap(parent_sentinel)
  File "/usr/lib/python3.10/multiprocessing/process.py", line 314, in _bootstrap
    self.run()
  File "/usr/lib/python3.10/multiprocessing/process.py", line 108, in run
    self._target(*self._args, **self._kwargs)
  File "/usr/lib/python3/dist-packages/uvicorn/subprocess.py", line 76, in subprocess_started
    target(sockets=sockets)
  File "/usr/lib/python3/dist-packages/uvicorn/server.py", line 68, in run
    return asyncio.run(self.serve(sockets=sockets))
  File "/usr/lib/python3.10/asyncio/runners.py", line 44, in run
    return loop.run_until_complete(main)
  File "/usr/lib/python3.10/asyncio/base_events.py", line 636, in run_until_complete
    self.run_forever()
  File "/usr/lib/python3.10/asyncio/base_events.py", line 603, in run_forever
    self._run_once()
  File "/usr/lib/python3.10/asyncio/base_events.py", line 1909, in _run_once
    handle._run()
  File "/usr/lib/python3.10/asyncio/events.py", line 80, in _run
    self._context.run(self._callback, *self._args)
  File "/usr/lib/python3/dist-packages/uvicorn/server.py", line 94, in serve
    logger.info(message, process_id, extra={"color_message": color_message})
Message: 'Finished server process [%d]'
Arguments: (15174,)
--- Logging error ---
Traceback (most recent call last):
  File "/usr/lib/python3.10/logging/__init__.py", line 440, in format
    return self._format(record)
  File "/usr/lib/python3.10/logging/__init__.py", line 436, in _format
    return self._fmt % values
KeyError: 'endpt'

During handling of the above exception, another exception occurred:

Traceback (most recent call last):
  File "/usr/lib/python3.10/logging/__init__.py", line 1100, in emit
    msg = self.format(record)
  File "/usr/lib/python3.10/logging/__init__.py", line 943, in format
    return fmt.format(record)
  File "/usr/lib/python3.10/logging/__init__.py", line 681, in format
    s = self.formatMessage(record)
  File "/usr/lib/python3.10/logging/__init__.py", line 650, in formatMessage
    return self._style.format(record)
  File "/usr/lib/python3.10/logging/__init__.py", line 442, in format
    raise ValueError('Formatting field not found in record: %s' % e)
ValueError: Formatting field not found in record: 'endpt'
Call stack:
  File "<string>", line 1, in <module>
  File "/usr/lib/python3.10/multiprocessing/spawn.py", line 116, in spawn_main
    exitcode = _main(fd, parent_sentinel)
  File "/usr/lib/python3.10/multiprocessing/spawn.py", line 129, in _main
    return self._bootstrap(parent_sentinel)
  File "/usr/lib/python3.10/multiprocessing/process.py", line 314, in _bootstrap
    self.run()
  File "/usr/lib/python3.10/multiprocessing/process.py", line 108, in run
    self._target(*self._args, **self._kwargs)
  File "/usr/lib/python3/dist-packages/uvicorn/subprocess.py", line 76, in subprocess_started
    target(sockets=sockets)
  File "/usr/lib/python3/dist-packages/uvicorn/server.py", line 68, in run
    return asyncio.run(self.serve(sockets=sockets))
  File "/usr/lib/python3.10/asyncio/runners.py", line 39, in run
    loop = events.new_event_loop()
  File "/usr/lib/python3.10/asyncio/events.py", line 783, in new_event_loop
    return get_event_loop_policy().new_event_loop()
  File "/usr/lib/python3.10/asyncio/events.py", line 673, in new_event_loop
    return self._loop_factory()
  File "/usr/lib/python3.10/asyncio/unix_events.py", line 64, in __init__
    super().__init__(selector)
  File "/usr/lib/python3.10/asyncio/selector_events.py", line 54, in __init__
    logger.debug('Using selector: %s', selector.__class__.__name__)
Message: 'Using selector: %s'
Arguments: ('EpollSelector',)
Process SpawnProcess-24:
Traceback (most recent call last):
  File "/usr/lib/python3.10/multiprocessing/process.py", line 314, in _bootstrap
    self.run()
  File "/usr/lib/python3.10/multiprocessing/process.py", line 108, in run
    self._target(*self._args, **self._kwargs)
  File "/usr/lib/python3/dist-packages/uvicorn/subprocess.py", line 76, in subprocess_started
    target(sockets=sockets)
  File "/usr/lib/python3/dist-packages/uvicorn/server.py", line 68, in run
    return asyncio.run(self.serve(sockets=sockets))
  File "/usr/lib/python3.10/asyncio/runners.py", line 44, in run
    return loop.run_until_complete(main)
  File "/usr/lib/python3.10/asyncio/base_events.py", line 649, in run_until_complete
    return future.result()
  File "/usr/lib/python3/dist-packages/uvicorn/server.py", line 76, in serve
    config.load()
  File "/usr/lib/python3/dist-packages/uvicorn/config.py", line 448, in load
    self.loaded_app = import_from_string(self.app)
  File "/usr/lib/python3/dist-packages/uvicorn/importer.py", line 21, in import_from_string
    module = importlib.import_module(module_str)
  File "/usr/lib/python3.10/importlib/__init__.py", line 126, in import_module
    return _bootstrap._gcd_import(name[level:], package, level)
  File "<frozen importlib._bootstrap>", line 1050, in _gcd_import
  File "<frozen importlib._bootstrap>", line 1027, in _find_and_load
  File "<frozen importlib._bootstrap>", line 1006, in _find_and_load_unlocked
  File "<frozen importlib._bootstrap>", line 688, in _load_unlocked
  File "<frozen importlib._bootstrap_external>", line 879, in exec_module
  File "<frozen importlib._bootstrap_external>", line 1017, in get_code
  File "<frozen importlib._bootstrap_external>", line 947, in source_to_code
  File "<frozen importlib._bootstrap>", line 241, in _call_with_frames_removed
  File "/mnt/e/cura/cura_backend/./main.py", line 758
    ))
    ^
SyntaxError: unmatched ')'
--- Logging error ---
Traceback (most recent call last):
  File "/usr/lib/python3.10/logging/__init__.py", line 440, in format
    return self._format(record)
  File "/usr/lib/python3.10/logging/__init__.py", line 436, in _format
    return self._fmt % values
KeyError: 'funcname'

During handling of the above exception, another exception occurred:

Traceback (most recent call last):
  File "/usr/lib/python3.10/logging/__init__.py", line 1100, in emit
    msg = self.format(record)
  File "/usr/lib/python3.10/logging/__init__.py", line 943, in format
    return fmt.format(record)
  File "/usr/lib/python3.10/logging/__init__.py", line 681, in format
    s = self.formatMessage(record)
  File "/usr/lib/python3.10/logging/__init__.py", line 650, in formatMessage
    return self._style.format(record)
  File "/usr/lib/python3.10/logging/__init__.py", line 442, in format
    raise ValueError('Formatting field not found in record: %s' % e)
ValueError: Formatting field not found in record: 'funcname'
Call stack:
  File "/usr/bin/uvicorn", line 33, in <module>
    sys.exit(load_entry_point('uvicorn==0.15.0', 'console_scripts', 'uvicorn')())
  File "/usr/lib/python3/dist-packages/click/core.py", line 1128, in __call__
    return self.main(*args, **kwargs)
  File "/usr/lib/python3/dist-packages/click/core.py", line 1053, in main
    rv = self.invoke(ctx)
  File "/usr/lib/python3/dist-packages/click/core.py", line 1395, in invoke
    return ctx.invoke(self.callback, **ctx.params)
  File "/usr/lib/python3/dist-packages/click/core.py", line 754, in invoke
    return __callback(*args, **kwargs)
  File "/usr/lib/python3/dist-packages/uvicorn/main.py", line 425, in main
    run(app, **kwargs)
  File "/usr/lib/python3/dist-packages/uvicorn/main.py", line 442, in run
    ChangeReload(config, target=server.run, sockets=[sock]).run()
  File "/usr/lib/python3/dist-packages/uvicorn/supervisors/basereload.py", line 45, in run
    if self.should_restart():
  File "/usr/lib/python3/dist-packages/uvicorn/supervisors/statreload.py", line 41, in should_restart
    logger.warning(message, display_path)
Message: "StatReload detected file change in '%s'. Reloading..."
Arguments: ('main.py',)
--- Logging error ---
Traceback (most recent call last):
  File "/usr/lib/python3.10/logging/__init__.py", line 440, in format
    return self._format(record)
  File "/usr/lib/python3.10/logging/__init__.py", line 436, in _format
    return self._fmt % values
KeyError: 'endpt'

During handling of the above exception, another exception occurred:

Traceback (most recent call last):
  File "/usr/lib/python3.10/logging/__init__.py", line 1100, in emit
    msg = self.format(record)
  File "/usr/lib/python3.10/logging/__init__.py", line 943, in format
    return fmt.format(record)
  File "/usr/lib/python3.10/logging/__init__.py", line 681, in format
    s = self.formatMessage(record)
  File "/usr/lib/python3.10/logging/__init__.py", line 650, in formatMessage
    return self._style.format(record)
  File "/usr/lib/python3.10/logging/__init__.py", line 442, in format
    raise ValueError('Formatting field not found in record: %s' % e)
ValueError: Formatting field not found in record: 'endpt'
Call stack:
  File "<string>", line 1, in <module>
  File "/usr/lib/python3.10/multiprocessing/spawn.py", line 116, in spawn_main
    exitcode = _main(fd, parent_sentinel)
  File "/usr/lib/python3.10/multiprocessing/spawn.py", line 129, in _main
    return self._bootstrap(parent_sentinel)
  File "/usr/lib/python3.10/multiprocessing/process.py", line 314, in _bootstrap
    self.run()
  File "/usr/lib/python3.10/multiprocessing/process.py", line 108, in run
    self._target(*self._args, **self._kwargs)
  File "/usr/lib/python3/dist-packages/uvicorn/subprocess.py", line 76, in subprocess_started
    target(sockets=sockets)
  File "/usr/lib/python3/dist-packages/uvicorn/server.py", line 68, in run
    return asyncio.run(self.serve(sockets=sockets))
  File "/usr/lib/python3.10/asyncio/runners.py", line 39, in run
    loop = events.new_event_loop()
  File "/usr/lib/python3.10/asyncio/events.py", line 783, in new_event_loop
    return get_event_loop_policy().new_event_loop()
  File "/usr/lib/python3.10/asyncio/events.py", line 673, in new_event_loop
    return self._loop_factory()
  File "/usr/lib/python3.10/asyncio/unix_events.py", line 64, in __init__
    super().__init__(selector)
  File "/usr/lib/python3.10/asyncio/selector_events.py", line 54, in __init__
    logger.debug('Using selector: %s', selector.__class__.__name__)
Message: 'Using selector: %s'
Arguments: ('EpollSelector',)
Process SpawnProcess-25:
Traceback (most recent call last):
  File "/usr/lib/python3.10/multiprocessing/process.py", line 314, in _bootstrap
    self.run()
  File "/usr/lib/python3.10/multiprocessing/process.py", line 108, in run
    self._target(*self._args, **self._kwargs)
  File "/usr/lib/python3/dist-packages/uvicorn/subprocess.py", line 76, in subprocess_started
    target(sockets=sockets)
  File "/usr/lib/python3/dist-packages/uvicorn/server.py", line 68, in run
    return asyncio.run(self.serve(sockets=sockets))
  File "/usr/lib/python3.10/asyncio/runners.py", line 44, in run
    return loop.run_until_complete(main)
  File "/usr/lib/python3.10/asyncio/base_events.py", line 649, in run_until_complete
    return future.result()
  File "/usr/lib/python3/dist-packages/uvicorn/server.py", line 76, in serve
    config.load()
  File "/usr/lib/python3/dist-packages/uvicorn/config.py", line 448, in load
    self.loaded_app = import_from_string(self.app)
  File "/usr/lib/python3/dist-packages/uvicorn/importer.py", line 21, in import_from_string
    module = importlib.import_module(module_str)
  File "/usr/lib/python3.10/importlib/__init__.py", line 126, in import_module
    return _bootstrap._gcd_import(name[level:], package, level)
  File "<frozen importlib._bootstrap>", line 1050, in _gcd_import
  File "<frozen importlib._bootstrap>", line 1027, in _find_and_load
  File "<frozen importlib._bootstrap>", line 1006, in _find_and_load_unlocked
  File "<frozen importlib._bootstrap>", line 688, in _load_unlocked
  File "<frozen importlib._bootstrap_external>", line 879, in exec_module
  File "<frozen importlib._bootstrap_external>", line 1017, in get_code
  File "<frozen importlib._bootstrap_external>", line 947, in source_to_code
  File "<frozen importlib._bootstrap>", line 241, in _call_with_frames_removed
  File "/mnt/e/cura/cura_backend/./main.py", line 16
    return f'QUERY IS : <{cursor.mogrify(query,arr)}>')
                                                      ^
SyntaxError: unmatched ')'
--- Logging error ---
Traceback (most recent call last):
  File "/usr/lib/python3.10/logging/__init__.py", line 440, in format
    return self._format(record)
  File "/usr/lib/python3.10/logging/__init__.py", line 436, in _format
    return self._fmt % values
KeyError: 'funcname'

During handling of the above exception, another exception occurred:

Traceback (most recent call last):
  File "/usr/lib/python3.10/logging/__init__.py", line 1100, in emit
    msg = self.format(record)
  File "/usr/lib/python3.10/logging/__init__.py", line 943, in format
    return fmt.format(record)
  File "/usr/lib/python3.10/logging/__init__.py", line 681, in format
    s = self.formatMessage(record)
  File "/usr/lib/python3.10/logging/__init__.py", line 650, in formatMessage
    return self._style.format(record)
  File "/usr/lib/python3.10/logging/__init__.py", line 442, in format
    raise ValueError('Formatting field not found in record: %s' % e)
ValueError: Formatting field not found in record: 'funcname'
Call stack:
  File "/usr/bin/uvicorn", line 33, in <module>
    sys.exit(load_entry_point('uvicorn==0.15.0', 'console_scripts', 'uvicorn')())
  File "/usr/lib/python3/dist-packages/click/core.py", line 1128, in __call__
    return self.main(*args, **kwargs)
  File "/usr/lib/python3/dist-packages/click/core.py", line 1053, in main
    rv = self.invoke(ctx)
  File "/usr/lib/python3/dist-packages/click/core.py", line 1395, in invoke
    return ctx.invoke(self.callback, **ctx.params)
  File "/usr/lib/python3/dist-packages/click/core.py", line 754, in invoke
    return __callback(*args, **kwargs)
  File "/usr/lib/python3/dist-packages/uvicorn/main.py", line 425, in main
    run(app, **kwargs)
  File "/usr/lib/python3/dist-packages/uvicorn/main.py", line 442, in run
    ChangeReload(config, target=server.run, sockets=[sock]).run()
  File "/usr/lib/python3/dist-packages/uvicorn/supervisors/basereload.py", line 45, in run
    if self.should_restart():
  File "/usr/lib/python3/dist-packages/uvicorn/supervisors/statreload.py", line 41, in should_restart
    logger.warning(message, display_path)
Message: "StatReload detected file change in '%s'. Reloading..."
Arguments: ('main.py',)
--- Logging error ---
Traceback (most recent call last):
  File "/usr/lib/python3.10/logging/__init__.py", line 440, in format
    return self._format(record)
  File "/usr/lib/python3.10/logging/__init__.py", line 436, in _format
    return self._fmt % values
KeyError: 'endpt'

During handling of the above exception, another exception occurred:

Traceback (most recent call last):
  File "/usr/lib/python3.10/logging/__init__.py", line 1100, in emit
    msg = self.format(record)
  File "/usr/lib/python3.10/logging/__init__.py", line 943, in format
    return fmt.format(record)
  File "/usr/lib/python3.10/logging/__init__.py", line 681, in format
    s = self.formatMessage(record)
  File "/usr/lib/python3.10/logging/__init__.py", line 650, in formatMessage
    return self._style.format(record)
  File "/usr/lib/python3.10/logging/__init__.py", line 442, in format
    raise ValueError('Formatting field not found in record: %s' % e)
ValueError: Formatting field not found in record: 'endpt'
Call stack:
  File "<string>", line 1, in <module>
  File "/usr/lib/python3.10/multiprocessing/spawn.py", line 116, in spawn_main
    exitcode = _main(fd, parent_sentinel)
  File "/usr/lib/python3.10/multiprocessing/spawn.py", line 129, in _main
    return self._bootstrap(parent_sentinel)
  File "/usr/lib/python3.10/multiprocessing/process.py", line 314, in _bootstrap
    self.run()
  File "/usr/lib/python3.10/multiprocessing/process.py", line 108, in run
    self._target(*self._args, **self._kwargs)
  File "/usr/lib/python3/dist-packages/uvicorn/subprocess.py", line 76, in subprocess_started
    target(sockets=sockets)
  File "/usr/lib/python3/dist-packages/uvicorn/server.py", line 68, in run
    return asyncio.run(self.serve(sockets=sockets))
  File "/usr/lib/python3.10/asyncio/runners.py", line 39, in run
    loop = events.new_event_loop()
  File "/usr/lib/python3.10/asyncio/events.py", line 783, in new_event_loop
    return get_event_loop_policy().new_event_loop()
  File "/usr/lib/python3.10/asyncio/events.py", line 673, in new_event_loop
    return self._loop_factory()
  File "/usr/lib/python3.10/asyncio/unix_events.py", line 64, in __init__
    super().__init__(selector)
  File "/usr/lib/python3.10/asyncio/selector_events.py", line 54, in __init__
    logger.debug('Using selector: %s', selector.__class__.__name__)
Message: 'Using selector: %s'
Arguments: ('EpollSelector',)
--- Logging error ---
Traceback (most recent call last):
  File "/usr/lib/python3.10/logging/__init__.py", line 440, in format
    return self._format(record)
  File "/usr/lib/python3.10/logging/__init__.py", line 436, in _format
    return self._fmt % values
KeyError: 'endpt'

During handling of the above exception, another exception occurred:

Traceback (most recent call last):
  File "/usr/lib/python3.10/logging/__init__.py", line 1100, in emit
    msg = self.format(record)
  File "/usr/lib/python3.10/logging/__init__.py", line 943, in format
    return fmt.format(record)
  File "/usr/lib/python3.10/logging/__init__.py", line 681, in format
    s = self.formatMessage(record)
  File "/usr/lib/python3.10/logging/__init__.py", line 650, in formatMessage
    return self._style.format(record)
  File "/usr/lib/python3.10/logging/__init__.py", line 442, in format
    raise ValueError('Formatting field not found in record: %s' % e)
ValueError: Formatting field not found in record: 'endpt'
Call stack:
  File "<string>", line 1, in <module>
  File "/usr/lib/python3.10/multiprocessing/spawn.py", line 116, in spawn_main
    exitcode = _main(fd, parent_sentinel)
  File "/usr/lib/python3.10/multiprocessing/spawn.py", line 129, in _main
    return self._bootstrap(parent_sentinel)
  File "/usr/lib/python3.10/multiprocessing/process.py", line 314, in _bootstrap
    self.run()
  File "/usr/lib/python3.10/multiprocessing/process.py", line 108, in run
    self._target(*self._args, **self._kwargs)
  File "/usr/lib/python3/dist-packages/uvicorn/subprocess.py", line 76, in subprocess_started
    target(sockets=sockets)
  File "/usr/lib/python3/dist-packages/uvicorn/server.py", line 68, in run
    return asyncio.run(self.serve(sockets=sockets))
  File "/usr/lib/python3.10/asyncio/runners.py", line 44, in run
    return loop.run_until_complete(main)
  File "/usr/lib/python3.10/asyncio/base_events.py", line 636, in run_until_complete
    self.run_forever()
  File "/usr/lib/python3.10/asyncio/base_events.py", line 603, in run_forever
    self._run_once()
  File "/usr/lib/python3.10/asyncio/base_events.py", line 1909, in _run_once
    handle._run()
  File "/usr/lib/python3.10/asyncio/events.py", line 80, in _run
    self._context.run(self._callback, *self._args)
  File "/usr/lib/python3/dist-packages/uvicorn/server.py", line 76, in serve
    config.load()
  File "/usr/lib/python3/dist-packages/uvicorn/config.py", line 448, in load
    self.loaded_app = import_from_string(self.app)
  File "/usr/lib/python3/dist-packages/uvicorn/importer.py", line 21, in import_from_string
    module = importlib.import_module(module_str)
  File "/usr/lib/python3.10/importlib/__init__.py", line 126, in import_module
    return _bootstrap._gcd_import(name[level:], package, level)
  File "<frozen importlib._bootstrap>", line 1050, in _gcd_import
  File "<frozen importlib._bootstrap>", line 1027, in _find_and_load
  File "<frozen importlib._bootstrap>", line 1006, in _find_and_load_unlocked
  File "<frozen importlib._bootstrap>", line 688, in _load_unlocked
  File "<frozen importlib._bootstrap_external>", line 883, in exec_module
  File "<frozen importlib._bootstrap>", line 241, in _call_with_frames_removed
  File "/mnt/e/cura/cura_backend/./main.py", line 4132, in <module>
    logger.info("program_started")
Message: 'program_started'
Arguments: ()
--- Logging error ---
Traceback (most recent call last):
  File "/usr/lib/python3.10/logging/__init__.py", line 440, in format
    return self._format(record)
  File "/usr/lib/python3.10/logging/__init__.py", line 436, in _format
    return self._fmt % values
KeyError: 'endpt'

During handling of the above exception, another exception occurred:

Traceback (most recent call last):
  File "/usr/lib/python3.10/logging/__init__.py", line 1100, in emit
    msg = self.format(record)
  File "/usr/lib/python3.10/logging/__init__.py", line 943, in format
    return fmt.format(record)
  File "/usr/lib/python3.10/logging/__init__.py", line 681, in format
    s = self.formatMessage(record)
  File "/usr/lib/python3.10/logging/__init__.py", line 650, in formatMessage
    return self._style.format(record)
  File "/usr/lib/python3.10/logging/__init__.py", line 442, in format
    raise ValueError('Formatting field not found in record: %s' % e)
ValueError: Formatting field not found in record: 'endpt'
Call stack:
  File "<string>", line 1, in <module>
  File "/usr/lib/python3.10/multiprocessing/spawn.py", line 116, in spawn_main
    exitcode = _main(fd, parent_sentinel)
  File "/usr/lib/python3.10/multiprocessing/spawn.py", line 129, in _main
    return self._bootstrap(parent_sentinel)
  File "/usr/lib/python3.10/multiprocessing/process.py", line 314, in _bootstrap
    self.run()
  File "/usr/lib/python3.10/multiprocessing/process.py", line 108, in run
    self._target(*self._args, **self._kwargs)
  File "/usr/lib/python3/dist-packages/uvicorn/subprocess.py", line 76, in subprocess_started
    target(sockets=sockets)
  File "/usr/lib/python3/dist-packages/uvicorn/server.py", line 68, in run
    return asyncio.run(self.serve(sockets=sockets))
  File "/usr/lib/python3.10/asyncio/runners.py", line 44, in run
    return loop.run_until_complete(main)
  File "/usr/lib/python3.10/asyncio/base_events.py", line 636, in run_until_complete
    self.run_forever()
  File "/usr/lib/python3.10/asyncio/base_events.py", line 603, in run_forever
    self._run_once()
  File "/usr/lib/python3.10/asyncio/base_events.py", line 1909, in _run_once
    handle._run()
  File "/usr/lib/python3.10/asyncio/events.py", line 80, in _run
    self._context.run(self._callback, *self._args)
  File "/usr/lib/python3/dist-packages/uvicorn/server.py", line 84, in serve
    logger.info(message, process_id, extra={"color_message": color_message})
Message: 'Started server process [%d]'
Arguments: (18332,)
--- Logging error ---
Traceback (most recent call last):
  File "/usr/lib/python3.10/logging/__init__.py", line 440, in format
    return self._format(record)
  File "/usr/lib/python3.10/logging/__init__.py", line 436, in _format
    return self._fmt % values
KeyError: 'endpt'

During handling of the above exception, another exception occurred:

Traceback (most recent call last):
  File "/usr/lib/python3.10/logging/__init__.py", line 1100, in emit
    msg = self.format(record)
  File "/usr/lib/python3.10/logging/__init__.py", line 943, in format
    return fmt.format(record)
  File "/usr/lib/python3.10/logging/__init__.py", line 681, in format
    s = self.formatMessage(record)
  File "/usr/lib/python3.10/logging/__init__.py", line 650, in formatMessage
    return self._style.format(record)
  File "/usr/lib/python3.10/logging/__init__.py", line 442, in format
    raise ValueError('Formatting field not found in record: %s' % e)
ValueError: Formatting field not found in record: 'endpt'
Call stack:
  File "<string>", line 1, in <module>
  File "/usr/lib/python3.10/multiprocessing/spawn.py", line 116, in spawn_main
    exitcode = _main(fd, parent_sentinel)
  File "/usr/lib/python3.10/multiprocessing/spawn.py", line 129, in _main
    return self._bootstrap(parent_sentinel)
  File "/usr/lib/python3.10/multiprocessing/process.py", line 314, in _bootstrap
    self.run()
  File "/usr/lib/python3.10/multiprocessing/process.py", line 108, in run
    self._target(*self._args, **self._kwargs)
  File "/usr/lib/python3/dist-packages/uvicorn/subprocess.py", line 76, in subprocess_started
    target(sockets=sockets)
  File "/usr/lib/python3/dist-packages/uvicorn/server.py", line 68, in run
    return asyncio.run(self.serve(sockets=sockets))
  File "/usr/lib/python3.10/asyncio/runners.py", line 44, in run
    return loop.run_until_complete(main)
  File "/usr/lib/python3.10/asyncio/base_events.py", line 636, in run_until_complete
    self.run_forever()
  File "/usr/lib/python3.10/asyncio/base_events.py", line 603, in run_forever
    self._run_once()
  File "/usr/lib/python3.10/asyncio/base_events.py", line 1909, in _run_once
    handle._run()
  File "/usr/lib/python3.10/asyncio/events.py", line 80, in _run
    self._context.run(self._callback, *self._args)
  File "/usr/lib/python3/dist-packages/uvicorn/server.py", line 86, in serve
    await self.startup(sockets=sockets)
  File "/usr/lib/python3/dist-packages/uvicorn/server.py", line 97, in startup
    await self.lifespan.startup()
  File "/usr/lib/python3/dist-packages/uvicorn/lifespan/on.py", line 45, in startup
    self.logger.info("Waiting for application startup.")
Message: 'Waiting for application startup.'
Arguments: ()
--- Logging error ---
Traceback (most recent call last):
  File "/usr/lib/python3.10/logging/__init__.py", line 440, in format
    return self._format(record)
  File "/usr/lib/python3.10/logging/__init__.py", line 436, in _format
    return self._fmt % values
KeyError: 'endpt'

During handling of the above exception, another exception occurred:

Traceback (most recent call last):
  File "/usr/lib/python3.10/logging/__init__.py", line 1100, in emit
    msg = self.format(record)
  File "/usr/lib/python3.10/logging/__init__.py", line 943, in format
    return fmt.format(record)
  File "/usr/lib/python3.10/logging/__init__.py", line 681, in format
    s = self.formatMessage(record)
  File "/usr/lib/python3.10/logging/__init__.py", line 650, in formatMessage
    return self._style.format(record)
  File "/usr/lib/python3.10/logging/__init__.py", line 442, in format
    raise ValueError('Formatting field not found in record: %s' % e)
ValueError: Formatting field not found in record: 'endpt'
Call stack:
  File "<string>", line 1, in <module>
  File "/usr/lib/python3.10/multiprocessing/spawn.py", line 116, in spawn_main
    exitcode = _main(fd, parent_sentinel)
  File "/usr/lib/python3.10/multiprocessing/spawn.py", line 129, in _main
    return self._bootstrap(parent_sentinel)
  File "/usr/lib/python3.10/multiprocessing/process.py", line 314, in _bootstrap
    self.run()
  File "/usr/lib/python3.10/multiprocessing/process.py", line 108, in run
    self._target(*self._args, **self._kwargs)
  File "/usr/lib/python3/dist-packages/uvicorn/subprocess.py", line 76, in subprocess_started
    target(sockets=sockets)
  File "/usr/lib/python3/dist-packages/uvicorn/server.py", line 68, in run
    return asyncio.run(self.serve(sockets=sockets))
  File "/usr/lib/python3.10/asyncio/runners.py", line 44, in run
    return loop.run_until_complete(main)
  File "/usr/lib/python3.10/asyncio/base_events.py", line 636, in run_until_complete
    self.run_forever()
  File "/usr/lib/python3.10/asyncio/base_events.py", line 603, in run_forever
    self._run_once()
  File "/usr/lib/python3.10/asyncio/base_events.py", line 1909, in _run_once
    handle._run()
  File "/usr/lib/python3.10/asyncio/events.py", line 80, in _run
    self._context.run(self._callback, *self._args)
  File "/usr/lib/python3/dist-packages/uvicorn/server.py", line 86, in serve
    await self.startup(sockets=sockets)
  File "/usr/lib/python3/dist-packages/uvicorn/server.py", line 97, in startup
    await self.lifespan.startup()
  File "/usr/lib/python3/dist-packages/uvicorn/lifespan/on.py", line 59, in startup
    self.logger.info("Application startup complete.")
Message: 'Application startup complete.'
Arguments: ()
--- Logging error ---
Traceback (most recent call last):
  File "/usr/lib/python3.10/logging/__init__.py", line 440, in format
    return self._format(record)
  File "/usr/lib/python3.10/logging/__init__.py", line 436, in _format
    return self._fmt % values
KeyError: 'endpt'

During handling of the above exception, another exception occurred:

Traceback (most recent call last):
  File "/usr/lib/python3.10/logging/__init__.py", line 1100, in emit
    msg = self.format(record)
  File "/usr/lib/python3.10/logging/__init__.py", line 943, in format
    return fmt.format(record)
  File "/usr/lib/python3.10/logging/__init__.py", line 681, in format
    s = self.formatMessage(record)
  File "/usr/lib/python3.10/logging/__init__.py", line 650, in formatMessage
    return self._style.format(record)
  File "/usr/lib/python3.10/logging/__init__.py", line 442, in format
    raise ValueError('Formatting field not found in record: %s' % e)
ValueError: Formatting field not found in record: 'endpt'
Call stack:
  File "<string>", line 1, in <module>
  File "/usr/lib/python3.10/multiprocessing/spawn.py", line 116, in spawn_main
    exitcode = _main(fd, parent_sentinel)
  File "/usr/lib/python3.10/multiprocessing/spawn.py", line 129, in _main
    return self._bootstrap(parent_sentinel)
  File "/usr/lib/python3.10/multiprocessing/process.py", line 314, in _bootstrap
    self.run()
  File "/usr/lib/python3.10/multiprocessing/process.py", line 108, in run
    self._target(*self._args, **self._kwargs)
  File "/usr/lib/python3/dist-packages/uvicorn/subprocess.py", line 76, in subprocess_started
    target(sockets=sockets)
  File "/usr/lib/python3/dist-packages/uvicorn/server.py", line 68, in run
    return asyncio.run(self.serve(sockets=sockets))
  File "/usr/lib/python3.10/asyncio/runners.py", line 44, in run
    return loop.run_until_complete(main)
  File "/usr/lib/python3.10/asyncio/base_events.py", line 636, in run_until_complete
    self.run_forever()
  File "/usr/lib/python3.10/asyncio/base_events.py", line 603, in run_forever
    self._run_once()
  File "/usr/lib/python3.10/asyncio/base_events.py", line 1909, in _run_once
    handle._run()
  File "/usr/lib/python3.10/asyncio/events.py", line 80, in _run
    self._context.run(self._callback, *self._args)
  File "/usr/lib/python3/dist-packages/uvicorn/protocols/http/h11_impl.py", line 373, in run_asgi
    result = await app(self.scope, self.receive, self.send)
  File "/usr/lib/python3/dist-packages/uvicorn/middleware/proxy_headers.py", line 75, in __call__
    return await self.app(scope, receive, send)
  File "/home/rudra/.local/lib/python3.10/site-packages/fastapi/applications.py", line 1054, in __call__
    await super().__call__(scope, receive, send)
  File "/home/rudra/.local/lib/python3.10/site-packages/starlette/applications.py", line 123, in __call__
    await self.middleware_stack(scope, receive, send)
  File "/home/rudra/.local/lib/python3.10/site-packages/starlette/middleware/errors.py", line 164, in __call__
    await self.app(scope, receive, _send)
  File "/home/rudra/.local/lib/python3.10/site-packages/starlette/middleware/cors.py", line 93, in __call__
    await self.simple_response(scope, receive, send, request_headers=headers)
  File "/home/rudra/.local/lib/python3.10/site-packages/starlette/middleware/cors.py", line 148, in simple_response
    await self.app(scope, receive, send)
  File "/home/rudra/.local/lib/python3.10/site-packages/starlette/middleware/exceptions.py", line 65, in __call__
    await wrap_app_handling_exceptions(self.app, conn)(scope, receive, send)
  File "/home/rudra/.local/lib/python3.10/site-packages/starlette/_exception_handler.py", line 53, in wrapped_app
    await app(scope, receive, sender)
  File "/home/rudra/.local/lib/python3.10/site-packages/starlette/routing.py", line 756, in __call__
    await self.middleware_stack(scope, receive, send)
  File "/home/rudra/.local/lib/python3.10/site-packages/starlette/routing.py", line 776, in app
    await route.handle(scope, receive, send)
  File "/home/rudra/.local/lib/python3.10/site-packages/starlette/routing.py", line 297, in handle
    await self.app(scope, receive, send)
  File "/home/rudra/.local/lib/python3.10/site-packages/starlette/routing.py", line 77, in app
    await wrap_app_handling_exceptions(app, request)(scope, receive, send)
  File "/home/rudra/.local/lib/python3.10/site-packages/starlette/_exception_handler.py", line 53, in wrapped_app
    await app(scope, receive, sender)
  File "/home/rudra/.local/lib/python3.10/site-packages/starlette/routing.py", line 72, in app
    response = await func(request)
  File "/home/rudra/.local/lib/python3.10/site-packages/fastapi/routing.py", line 278, in app
    raw_response = await run_endpoint_function(
  File "/home/rudra/.local/lib/python3.10/site-packages/fastapi/routing.py", line 191, in run_endpoint_function
    return await dependant.call(**values)
  File "/mnt/e/cura/cura_backend/./main.py", line 1866, in get_users_admin
    logging.info(f'get_users_admin:payload received is {payload}')
Message: "get_users_admin:payload received is {'user_id': 1234}"
Arguments: ()
2024-04-30 17:53:07,275 - uvicorn.access - send - INFO - 127.0.0.1:60370 - "POST /getUsersAdmin HTTP/1.1" 200
--- Logging error ---
Traceback (most recent call last):
  File "/usr/lib/python3.10/logging/__init__.py", line 440, in format
    return self._format(record)
  File "/usr/lib/python3.10/logging/__init__.py", line 436, in _format
    return self._fmt % values
KeyError: 'funcname'

During handling of the above exception, another exception occurred:

Traceback (most recent call last):
  File "/usr/lib/python3.10/logging/__init__.py", line 1100, in emit
    msg = self.format(record)
  File "/usr/lib/python3.10/logging/__init__.py", line 943, in format
    return fmt.format(record)
  File "/usr/lib/python3.10/logging/__init__.py", line 681, in format
    s = self.formatMessage(record)
  File "/usr/lib/python3.10/logging/__init__.py", line 650, in formatMessage
    return self._style.format(record)
  File "/usr/lib/python3.10/logging/__init__.py", line 442, in format
    raise ValueError('Formatting field not found in record: %s' % e)
ValueError: Formatting field not found in record: 'funcname'
Call stack:
  File "/usr/bin/uvicorn", line 33, in <module>
    sys.exit(load_entry_point('uvicorn==0.15.0', 'console_scripts', 'uvicorn')())
  File "/usr/lib/python3/dist-packages/click/core.py", line 1128, in __call__
    return self.main(*args, **kwargs)
  File "/usr/lib/python3/dist-packages/click/core.py", line 1053, in main
    rv = self.invoke(ctx)
  File "/usr/lib/python3/dist-packages/click/core.py", line 1395, in invoke
    return ctx.invoke(self.callback, **ctx.params)
  File "/usr/lib/python3/dist-packages/click/core.py", line 754, in invoke
    return __callback(*args, **kwargs)
  File "/usr/lib/python3/dist-packages/uvicorn/main.py", line 425, in main
    run(app, **kwargs)
  File "/usr/lib/python3/dist-packages/uvicorn/main.py", line 442, in run
    ChangeReload(config, target=server.run, sockets=[sock]).run()
  File "/usr/lib/python3/dist-packages/uvicorn/supervisors/basereload.py", line 45, in run
    if self.should_restart():
  File "/usr/lib/python3/dist-packages/uvicorn/supervisors/statreload.py", line 41, in should_restart
    logger.warning(message, display_path)
Message: "StatReload detected file change in '%s'. Reloading..."
Arguments: ('main.py',)
--- Logging error ---
Traceback (most recent call last):
  File "/usr/lib/python3.10/logging/__init__.py", line 440, in format
    return self._format(record)
  File "/usr/lib/python3.10/logging/__init__.py", line 436, in _format
    return self._fmt % values
KeyError: 'endpt'

During handling of the above exception, another exception occurred:

Traceback (most recent call last):
  File "/usr/lib/python3.10/logging/__init__.py", line 1100, in emit
    msg = self.format(record)
  File "/usr/lib/python3.10/logging/__init__.py", line 943, in format
    return fmt.format(record)
  File "/usr/lib/python3.10/logging/__init__.py", line 681, in format
    s = self.formatMessage(record)
  File "/usr/lib/python3.10/logging/__init__.py", line 650, in formatMessage
    return self._style.format(record)
  File "/usr/lib/python3.10/logging/__init__.py", line 442, in format
    raise ValueError('Formatting field not found in record: %s' % e)
ValueError: Formatting field not found in record: 'endpt'
Call stack:
  File "<string>", line 1, in <module>
  File "/usr/lib/python3.10/multiprocessing/spawn.py", line 116, in spawn_main
    exitcode = _main(fd, parent_sentinel)
  File "/usr/lib/python3.10/multiprocessing/spawn.py", line 129, in _main
    return self._bootstrap(parent_sentinel)
  File "/usr/lib/python3.10/multiprocessing/process.py", line 314, in _bootstrap
    self.run()
  File "/usr/lib/python3.10/multiprocessing/process.py", line 108, in run
    self._target(*self._args, **self._kwargs)
  File "/usr/lib/python3/dist-packages/uvicorn/subprocess.py", line 76, in subprocess_started
    target(sockets=sockets)
  File "/usr/lib/python3/dist-packages/uvicorn/server.py", line 68, in run
    return asyncio.run(self.serve(sockets=sockets))
  File "/usr/lib/python3.10/asyncio/runners.py", line 44, in run
    return loop.run_until_complete(main)
  File "/usr/lib/python3.10/asyncio/base_events.py", line 636, in run_until_complete
    self.run_forever()
  File "/usr/lib/python3.10/asyncio/base_events.py", line 603, in run_forever
    self._run_once()
  File "/usr/lib/python3.10/asyncio/base_events.py", line 1909, in _run_once
    handle._run()
  File "/usr/lib/python3.10/asyncio/events.py", line 80, in _run
    self._context.run(self._callback, *self._args)
  File "/usr/lib/python3/dist-packages/uvicorn/server.py", line 90, in serve
    await self.shutdown(sockets=sockets)
  File "/usr/lib/python3/dist-packages/uvicorn/server.py", line 263, in shutdown
    logger.info("Shutting down")
Message: 'Shutting down'
Arguments: ()
--- Logging error ---
Traceback (most recent call last):
  File "/usr/lib/python3.10/logging/__init__.py", line 440, in format
    return self._format(record)
  File "/usr/lib/python3.10/logging/__init__.py", line 436, in _format
    return self._fmt % values
KeyError: 'endpt'

During handling of the above exception, another exception occurred:

Traceback (most recent call last):
  File "/usr/lib/python3.10/logging/__init__.py", line 1100, in emit
    msg = self.format(record)
  File "/usr/lib/python3.10/logging/__init__.py", line 943, in format
    return fmt.format(record)
  File "/usr/lib/python3.10/logging/__init__.py", line 681, in format
    s = self.formatMessage(record)
  File "/usr/lib/python3.10/logging/__init__.py", line 650, in formatMessage
    return self._style.format(record)
  File "/usr/lib/python3.10/logging/__init__.py", line 442, in format
    raise ValueError('Formatting field not found in record: %s' % e)
ValueError: Formatting field not found in record: 'endpt'
Call stack:
  File "<string>", line 1, in <module>
  File "/usr/lib/python3.10/multiprocessing/spawn.py", line 116, in spawn_main
    exitcode = _main(fd, parent_sentinel)
  File "/usr/lib/python3.10/multiprocessing/spawn.py", line 129, in _main
    return self._bootstrap(parent_sentinel)
  File "/usr/lib/python3.10/multiprocessing/process.py", line 314, in _bootstrap
    self.run()
  File "/usr/lib/python3.10/multiprocessing/process.py", line 108, in run
    self._target(*self._args, **self._kwargs)
  File "/usr/lib/python3/dist-packages/uvicorn/subprocess.py", line 76, in subprocess_started
    target(sockets=sockets)
  File "/usr/lib/python3/dist-packages/uvicorn/server.py", line 68, in run
    return asyncio.run(self.serve(sockets=sockets))
  File "/usr/lib/python3.10/asyncio/runners.py", line 44, in run
    return loop.run_until_complete(main)
  File "/usr/lib/python3.10/asyncio/base_events.py", line 636, in run_until_complete
    self.run_forever()
  File "/usr/lib/python3.10/asyncio/base_events.py", line 603, in run_forever
    self._run_once()
  File "/usr/lib/python3.10/asyncio/base_events.py", line 1909, in _run_once
    handle._run()
  File "/usr/lib/python3.10/asyncio/events.py", line 80, in _run
    self._context.run(self._callback, *self._args)
  File "/usr/lib/python3/dist-packages/uvicorn/server.py", line 90, in serve
    await self.shutdown(sockets=sockets)
  File "/usr/lib/python3/dist-packages/uvicorn/server.py", line 294, in shutdown
    await self.lifespan.shutdown()
  File "/usr/lib/python3/dist-packages/uvicorn/lifespan/on.py", line 64, in shutdown
    self.logger.info("Waiting for application shutdown.")
Message: 'Waiting for application shutdown.'
Arguments: ()
--- Logging error ---
Traceback (most recent call last):
  File "/usr/lib/python3.10/logging/__init__.py", line 440, in format
    return self._format(record)
  File "/usr/lib/python3.10/logging/__init__.py", line 436, in _format
    return self._fmt % values
KeyError: 'endpt'

During handling of the above exception, another exception occurred:

Traceback (most recent call last):
  File "/usr/lib/python3.10/logging/__init__.py", line 1100, in emit
    msg = self.format(record)
  File "/usr/lib/python3.10/logging/__init__.py", line 943, in format
    return fmt.format(record)
  File "/usr/lib/python3.10/logging/__init__.py", line 681, in format
    s = self.formatMessage(record)
  File "/usr/lib/python3.10/logging/__init__.py", line 650, in formatMessage
    return self._style.format(record)
  File "/usr/lib/python3.10/logging/__init__.py", line 442, in format
    raise ValueError('Formatting field not found in record: %s' % e)
ValueError: Formatting field not found in record: 'endpt'
Call stack:
  File "<string>", line 1, in <module>
  File "/usr/lib/python3.10/multiprocessing/spawn.py", line 116, in spawn_main
    exitcode = _main(fd, parent_sentinel)
  File "/usr/lib/python3.10/multiprocessing/spawn.py", line 129, in _main
    return self._bootstrap(parent_sentinel)
  File "/usr/lib/python3.10/multiprocessing/process.py", line 314, in _bootstrap
    self.run()
  File "/usr/lib/python3.10/multiprocessing/process.py", line 108, in run
    self._target(*self._args, **self._kwargs)
  File "/usr/lib/python3/dist-packages/uvicorn/subprocess.py", line 76, in subprocess_started
    target(sockets=sockets)
  File "/usr/lib/python3/dist-packages/uvicorn/server.py", line 68, in run
    return asyncio.run(self.serve(sockets=sockets))
  File "/usr/lib/python3.10/asyncio/runners.py", line 44, in run
    return loop.run_until_complete(main)
  File "/usr/lib/python3.10/asyncio/base_events.py", line 636, in run_until_complete
    self.run_forever()
  File "/usr/lib/python3.10/asyncio/base_events.py", line 603, in run_forever
    self._run_once()
  File "/usr/lib/python3.10/asyncio/base_events.py", line 1909, in _run_once
    handle._run()
  File "/usr/lib/python3.10/asyncio/events.py", line 80, in _run
    self._context.run(self._callback, *self._args)
  File "/usr/lib/python3/dist-packages/uvicorn/server.py", line 90, in serve
    await self.shutdown(sockets=sockets)
  File "/usr/lib/python3/dist-packages/uvicorn/server.py", line 294, in shutdown
    await self.lifespan.shutdown()
  File "/usr/lib/python3/dist-packages/uvicorn/lifespan/on.py", line 75, in shutdown
    self.logger.info("Application shutdown complete.")
Message: 'Application shutdown complete.'
Arguments: ()
--- Logging error ---
Traceback (most recent call last):
  File "/usr/lib/python3.10/logging/__init__.py", line 440, in format
    return self._format(record)
  File "/usr/lib/python3.10/logging/__init__.py", line 436, in _format
    return self._fmt % values
KeyError: 'endpt'

During handling of the above exception, another exception occurred:

Traceback (most recent call last):
  File "/usr/lib/python3.10/logging/__init__.py", line 1100, in emit
    msg = self.format(record)
  File "/usr/lib/python3.10/logging/__init__.py", line 943, in format
    return fmt.format(record)
  File "/usr/lib/python3.10/logging/__init__.py", line 681, in format
    s = self.formatMessage(record)
  File "/usr/lib/python3.10/logging/__init__.py", line 650, in formatMessage
    return self._style.format(record)
  File "/usr/lib/python3.10/logging/__init__.py", line 442, in format
    raise ValueError('Formatting field not found in record: %s' % e)
ValueError: Formatting field not found in record: 'endpt'
Call stack:
  File "<string>", line 1, in <module>
  File "/usr/lib/python3.10/multiprocessing/spawn.py", line 116, in spawn_main
    exitcode = _main(fd, parent_sentinel)
  File "/usr/lib/python3.10/multiprocessing/spawn.py", line 129, in _main
    return self._bootstrap(parent_sentinel)
  File "/usr/lib/python3.10/multiprocessing/process.py", line 314, in _bootstrap
    self.run()
  File "/usr/lib/python3.10/multiprocessing/process.py", line 108, in run
    self._target(*self._args, **self._kwargs)
  File "/usr/lib/python3/dist-packages/uvicorn/subprocess.py", line 76, in subprocess_started
    target(sockets=sockets)
  File "/usr/lib/python3/dist-packages/uvicorn/server.py", line 68, in run
    return asyncio.run(self.serve(sockets=sockets))
  File "/usr/lib/python3.10/asyncio/runners.py", line 44, in run
    return loop.run_until_complete(main)
  File "/usr/lib/python3.10/asyncio/base_events.py", line 636, in run_until_complete
    self.run_forever()
  File "/usr/lib/python3.10/asyncio/base_events.py", line 603, in run_forever
    self._run_once()
  File "/usr/lib/python3.10/asyncio/base_events.py", line 1909, in _run_once
    handle._run()
  File "/usr/lib/python3.10/asyncio/events.py", line 80, in _run
    self._context.run(self._callback, *self._args)
  File "/usr/lib/python3/dist-packages/uvicorn/server.py", line 94, in serve
    logger.info(message, process_id, extra={"color_message": color_message})
Message: 'Finished server process [%d]'
Arguments: (18332,)
2024-04-30 17:53:27,344 - asyncio - DEBUG - Using selector: EpollSelector
Process SpawnProcess-27:
Traceback (most recent call last):
  File "/usr/lib/python3.10/multiprocessing/process.py", line 314, in _bootstrap
    self.run()
  File "/usr/lib/python3.10/multiprocessing/process.py", line 108, in run
    self._target(*self._args, **self._kwargs)
  File "/usr/lib/python3/dist-packages/uvicorn/subprocess.py", line 76, in subprocess_started
    target(sockets=sockets)
  File "/usr/lib/python3/dist-packages/uvicorn/server.py", line 68, in run
    return asyncio.run(self.serve(sockets=sockets))
  File "/usr/lib/python3.10/asyncio/runners.py", line 44, in run
    return loop.run_until_complete(main)
  File "/usr/lib/python3.10/asyncio/base_events.py", line 649, in run_until_complete
    return future.result()
  File "/usr/lib/python3/dist-packages/uvicorn/server.py", line 76, in serve
    config.load()
  File "/usr/lib/python3/dist-packages/uvicorn/config.py", line 448, in load
    self.loaded_app = import_from_string(self.app)
  File "/usr/lib/python3/dist-packages/uvicorn/importer.py", line 24, in import_from_string
    raise exc from None
  File "/usr/lib/python3/dist-packages/uvicorn/importer.py", line 21, in import_from_string
    module = importlib.import_module(module_str)
  File "/usr/lib/python3.10/importlib/__init__.py", line 126, in import_module
    return _bootstrap._gcd_import(name[level:], package, level)
  File "<frozen importlib._bootstrap>", line 1050, in _gcd_import
  File "<frozen importlib._bootstrap>", line 1027, in _find_and_load
  File "<frozen importlib._bootstrap>", line 1006, in _find_and_load_unlocked
  File "<frozen importlib._bootstrap>", line 688, in _load_unlocked
  File "<frozen importlib._bootstrap_external>", line 883, in exec_module
  File "<frozen importlib._bootstrap>", line 241, in _call_with_frames_removed
  File "/mnt/e/cura/cura_backend/./main.py", line 3, in <module>
    from fastapi import FsstAPI, HTTPException, Depends, Query
ImportError: cannot import name 'FsstAPI' from 'fastapi' (/home/rudra/.local/lib/python3.10/site-packages/fastapi/__init__.py)
--- Logging error ---
Traceback (most recent call last):
  File "/usr/lib/python3.10/logging/__init__.py", line 440, in format
    return self._format(record)
  File "/usr/lib/python3.10/logging/__init__.py", line 436, in _format
    return self._fmt % values
KeyError: 'funcname'

During handling of the above exception, another exception occurred:

Traceback (most recent call last):
  File "/usr/lib/python3.10/logging/__init__.py", line 1100, in emit
    msg = self.format(record)
  File "/usr/lib/python3.10/logging/__init__.py", line 943, in format
    return fmt.format(record)
  File "/usr/lib/python3.10/logging/__init__.py", line 681, in format
    s = self.formatMessage(record)
  File "/usr/lib/python3.10/logging/__init__.py", line 650, in formatMessage
    return self._style.format(record)
  File "/usr/lib/python3.10/logging/__init__.py", line 442, in format
    raise ValueError('Formatting field not found in record: %s' % e)
ValueError: Formatting field not found in record: 'funcname'
Call stack:
  File "/usr/bin/uvicorn", line 33, in <module>
    sys.exit(load_entry_point('uvicorn==0.15.0', 'console_scripts', 'uvicorn')())
  File "/usr/lib/python3/dist-packages/click/core.py", line 1128, in __call__
    return self.main(*args, **kwargs)
  File "/usr/lib/python3/dist-packages/click/core.py", line 1053, in main
    rv = self.invoke(ctx)
  File "/usr/lib/python3/dist-packages/click/core.py", line 1395, in invoke
    return ctx.invoke(self.callback, **ctx.params)
  File "/usr/lib/python3/dist-packages/click/core.py", line 754, in invoke
    return __callback(*args, **kwargs)
  File "/usr/lib/python3/dist-packages/uvicorn/main.py", line 425, in main
    run(app, **kwargs)
  File "/usr/lib/python3/dist-packages/uvicorn/main.py", line 442, in run
    ChangeReload(config, target=server.run, sockets=[sock]).run()
  File "/usr/lib/python3/dist-packages/uvicorn/supervisors/basereload.py", line 45, in run
    if self.should_restart():
  File "/usr/lib/python3/dist-packages/uvicorn/supervisors/statreload.py", line 41, in should_restart
    logger.warning(message, display_path)
Message: "StatReload detected file change in '%s'. Reloading..."
Arguments: ('main.py',)
2024-04-30 17:53:32,960 - asyncio - DEBUG - Using selector: EpollSelector
2024-04-30 17:53:33,546 - main - INFO - program_started
2024-04-30 17:53:33,546 - uvicorn.error - INFO - Started server process [18442]
2024-04-30 17:53:33,547 - uvicorn.error - INFO - Waiting for application startup.
2024-04-30 17:53:33,547 - uvicorn.error - INFO - Application startup complete.
--- Logging error ---
Traceback (most recent call last):
  File "/usr/lib/python3.10/logging/__init__.py", line 440, in format
    return self._format(record)
  File "/usr/lib/python3.10/logging/__init__.py", line 436, in _format
    return self._fmt % values
KeyError: 'funcname'

During handling of the above exception, another exception occurred:

Traceback (most recent call last):
  File "/usr/lib/python3.10/logging/__init__.py", line 1100, in emit
    msg = self.format(record)
  File "/usr/lib/python3.10/logging/__init__.py", line 943, in format
    return fmt.format(record)
  File "/usr/lib/python3.10/logging/__init__.py", line 681, in format
    s = self.formatMessage(record)
  File "/usr/lib/python3.10/logging/__init__.py", line 650, in formatMessage
    return self._style.format(record)
  File "/usr/lib/python3.10/logging/__init__.py", line 442, in format
    raise ValueError('Formatting field not found in record: %s' % e)
ValueError: Formatting field not found in record: 'funcname'
Call stack:
  File "/usr/bin/uvicorn", line 33, in <module>
    sys.exit(load_entry_point('uvicorn==0.15.0', 'console_scripts', 'uvicorn')())
  File "/usr/lib/python3/dist-packages/click/core.py", line 1128, in __call__
    return self.main(*args, **kwargs)
  File "/usr/lib/python3/dist-packages/click/core.py", line 1053, in main
    rv = self.invoke(ctx)
  File "/usr/lib/python3/dist-packages/click/core.py", line 1395, in invoke
    return ctx.invoke(self.callback, **ctx.params)
  File "/usr/lib/python3/dist-packages/click/core.py", line 754, in invoke
    return __callback(*args, **kwargs)
  File "/usr/lib/python3/dist-packages/uvicorn/main.py", line 425, in main
    run(app, **kwargs)
  File "/usr/lib/python3/dist-packages/uvicorn/main.py", line 442, in run
    ChangeReload(config, target=server.run, sockets=[sock]).run()
  File "/usr/lib/python3/dist-packages/uvicorn/supervisors/basereload.py", line 45, in run
    if self.should_restart():
  File "/usr/lib/python3/dist-packages/uvicorn/supervisors/statreload.py", line 41, in should_restart
    logger.warning(message, display_path)
Message: "StatReload detected file change in '%s'. Reloading..."
Arguments: ('main.py',)
2024-04-30 17:53:42,474 - uvicorn.error - INFO - Shutting down
2024-04-30 17:53:42,575 - uvicorn.error - INFO - Waiting for application shutdown.
2024-04-30 17:53:42,575 - uvicorn.error - INFO - Application shutdown complete.
2024-04-30 17:53:42,575 - uvicorn.error - INFO - Finished server process [18442]
2024-04-30 17:53:42,750 - asyncio - DEBUG - Using selector: EpollSelector
2024-04-30 17:53:43,364 - main - INFO - program_started
2024-04-30 17:53:43,365 - uvicorn.error - INFO - Started server process [18482]
2024-04-30 17:53:43,365 - uvicorn.error - INFO - Waiting for application startup.
2024-04-30 17:53:43,365 - uvicorn.error - INFO - Application startup complete.
--- Logging error ---
Traceback (most recent call last):
  File "/usr/lib/python3.10/logging/__init__.py", line 440, in format
    return self._format(record)
  File "/usr/lib/python3.10/logging/__init__.py", line 436, in _format
    return self._fmt % values
KeyError: 'funcname'

During handling of the above exception, another exception occurred:

Traceback (most recent call last):
  File "/usr/lib/python3.10/logging/__init__.py", line 1100, in emit
    msg = self.format(record)
  File "/usr/lib/python3.10/logging/__init__.py", line 943, in format
    return fmt.format(record)
  File "/usr/lib/python3.10/logging/__init__.py", line 681, in format
    s = self.formatMessage(record)
  File "/usr/lib/python3.10/logging/__init__.py", line 650, in formatMessage
    return self._style.format(record)
  File "/usr/lib/python3.10/logging/__init__.py", line 442, in format
    raise ValueError('Formatting field not found in record: %s' % e)
ValueError: Formatting field not found in record: 'funcname'
Call stack:
  File "/usr/bin/uvicorn", line 33, in <module>
    sys.exit(load_entry_point('uvicorn==0.15.0', 'console_scripts', 'uvicorn')())
  File "/usr/lib/python3/dist-packages/click/core.py", line 1128, in __call__
    return self.main(*args, **kwargs)
  File "/usr/lib/python3/dist-packages/click/core.py", line 1053, in main
    rv = self.invoke(ctx)
  File "/usr/lib/python3/dist-packages/click/core.py", line 1395, in invoke
    return ctx.invoke(self.callback, **ctx.params)
  File "/usr/lib/python3/dist-packages/click/core.py", line 754, in invoke
    return __callback(*args, **kwargs)
  File "/usr/lib/python3/dist-packages/uvicorn/main.py", line 425, in main
    run(app, **kwargs)
  File "/usr/lib/python3/dist-packages/uvicorn/main.py", line 442, in run
    ChangeReload(config, target=server.run, sockets=[sock]).run()
  File "/usr/lib/python3/dist-packages/uvicorn/supervisors/basereload.py", line 45, in run
    if self.should_restart():
  File "/usr/lib/python3/dist-packages/uvicorn/supervisors/statreload.py", line 41, in should_restart
    logger.warning(message, display_path)
Message: "StatReload detected file change in '%s'. Reloading..."
Arguments: ('main.py',)
2024-04-30 17:53:54,598 - uvicorn.error - INFO - Shutting down
2024-04-30 17:53:54,699 - uvicorn.error - INFO - Waiting for application shutdown.
2024-04-30 17:53:54,699 - uvicorn.error - INFO - Application shutdown complete.
2024-04-30 17:53:54,700 - uvicorn.error - INFO - Finished server process [18482]
2024-04-30 17:53:54,865 - asyncio - DEBUG - Using selector: EpollSelector
2024-04-30 17:53:55,475 - main - INFO - program_started
2024-04-30 17:53:55,476 - uvicorn.error - INFO - Started server process [18530]
2024-04-30 17:53:55,476 - uvicorn.error - INFO - Waiting for application startup.
2024-04-30 17:53:55,476 - uvicorn.error - INFO - Application startup complete.
--- Logging error ---
Traceback (most recent call last):
  File "/usr/lib/python3.10/logging/__init__.py", line 440, in format
    return self._format(record)
  File "/usr/lib/python3.10/logging/__init__.py", line 436, in _format
    return self._fmt % values
KeyError: 'funcname'

During handling of the above exception, another exception occurred:

Traceback (most recent call last):
  File "/usr/lib/python3.10/logging/__init__.py", line 1100, in emit
    msg = self.format(record)
  File "/usr/lib/python3.10/logging/__init__.py", line 943, in format
    return fmt.format(record)
  File "/usr/lib/python3.10/logging/__init__.py", line 681, in format
    s = self.formatMessage(record)
  File "/usr/lib/python3.10/logging/__init__.py", line 650, in formatMessage
    return self._style.format(record)
  File "/usr/lib/python3.10/logging/__init__.py", line 442, in format
    raise ValueError('Formatting field not found in record: %s' % e)
ValueError: Formatting field not found in record: 'funcname'
Call stack:
  File "/usr/bin/uvicorn", line 33, in <module>
    sys.exit(load_entry_point('uvicorn==0.15.0', 'console_scripts', 'uvicorn')())
  File "/usr/lib/python3/dist-packages/click/core.py", line 1128, in __call__
    return self.main(*args, **kwargs)
  File "/usr/lib/python3/dist-packages/click/core.py", line 1053, in main
    rv = self.invoke(ctx)
  File "/usr/lib/python3/dist-packages/click/core.py", line 1395, in invoke
    return ctx.invoke(self.callback, **ctx.params)
  File "/usr/lib/python3/dist-packages/click/core.py", line 754, in invoke
    return __callback(*args, **kwargs)
  File "/usr/lib/python3/dist-packages/uvicorn/main.py", line 425, in main
    run(app, **kwargs)
  File "/usr/lib/python3/dist-packages/uvicorn/main.py", line 442, in run
    ChangeReload(config, target=server.run, sockets=[sock]).run()
  File "/usr/lib/python3/dist-packages/uvicorn/supervisors/basereload.py", line 45, in run
    if self.should_restart():
  File "/usr/lib/python3/dist-packages/uvicorn/supervisors/statreload.py", line 41, in should_restart
    logger.warning(message, display_path)
Message: "StatReload detected file change in '%s'. Reloading..."
Arguments: ('main.py',)
2024-04-30 17:57:36,703 - uvicorn.error - INFO - Shutting down
2024-04-30 17:57:36,804 - uvicorn.error - INFO - Waiting for application shutdown.
2024-04-30 17:57:36,804 - uvicorn.error - INFO - Application shutdown complete.
2024-04-30 17:57:36,804 - uvicorn.error - INFO - Finished server process [18530]
2024-04-30 17:57:37,008 - asyncio - DEBUG - Using selector: EpollSelector
2024-04-30 17:57:37,599 - main - INFO - program_started
2024-04-30 17:57:37,599 - uvicorn.error - INFO - Started server process [19414]
2024-04-30 17:57:37,600 - uvicorn.error - INFO - Waiting for application startup.
2024-04-30 17:57:37,600 - uvicorn.error - INFO - Application startup complete.
--- Logging error ---
Traceback (most recent call last):
  File "/usr/lib/python3.10/logging/__init__.py", line 440, in format
    return self._format(record)
  File "/usr/lib/python3.10/logging/__init__.py", line 436, in _format
    return self._fmt % values
KeyError: 'funcname'

During handling of the above exception, another exception occurred:

Traceback (most recent call last):
  File "/usr/lib/python3.10/logging/__init__.py", line 1100, in emit
    msg = self.format(record)
  File "/usr/lib/python3.10/logging/__init__.py", line 943, in format
    return fmt.format(record)
  File "/usr/lib/python3.10/logging/__init__.py", line 681, in format
    s = self.formatMessage(record)
  File "/usr/lib/python3.10/logging/__init__.py", line 650, in formatMessage
    return self._style.format(record)
  File "/usr/lib/python3.10/logging/__init__.py", line 442, in format
    raise ValueError('Formatting field not found in record: %s' % e)
ValueError: Formatting field not found in record: 'funcname'
Call stack:
  File "/usr/bin/uvicorn", line 33, in <module>
    sys.exit(load_entry_point('uvicorn==0.15.0', 'console_scripts', 'uvicorn')())
  File "/usr/lib/python3/dist-packages/click/core.py", line 1128, in __call__
    return self.main(*args, **kwargs)
  File "/usr/lib/python3/dist-packages/click/core.py", line 1053, in main
    rv = self.invoke(ctx)
  File "/usr/lib/python3/dist-packages/click/core.py", line 1395, in invoke
    return ctx.invoke(self.callback, **ctx.params)
  File "/usr/lib/python3/dist-packages/click/core.py", line 754, in invoke
    return __callback(*args, **kwargs)
  File "/usr/lib/python3/dist-packages/uvicorn/main.py", line 425, in main
    run(app, **kwargs)
  File "/usr/lib/python3/dist-packages/uvicorn/main.py", line 442, in run
    ChangeReload(config, target=server.run, sockets=[sock]).run()
  File "/usr/lib/python3/dist-packages/uvicorn/supervisors/basereload.py", line 45, in run
    if self.should_restart():
  File "/usr/lib/python3/dist-packages/uvicorn/supervisors/statreload.py", line 41, in should_restart
    logger.warning(message, display_path)
Message: "StatReload detected file change in '%s'. Reloading..."
Arguments: ('main.py',)
2024-04-30 17:57:50,840 - uvicorn.error - INFO - Shutting down
2024-04-30 17:57:50,940 - uvicorn.error - INFO - Waiting for application shutdown.
2024-04-30 17:57:50,941 - uvicorn.error - INFO - Application shutdown complete.
2024-04-30 17:57:50,941 - uvicorn.error - INFO - Finished server process [19414]
2024-04-30 17:57:51,136 - asyncio - DEBUG - Using selector: EpollSelector
2024-04-30 17:57:51,793 - main - INFO - program_started
2024-04-30 17:57:51,794 - uvicorn.error - INFO - Started server process [19471]
2024-04-30 17:57:51,795 - uvicorn.error - INFO - Waiting for application startup.
2024-04-30 17:57:51,795 - uvicorn.error - INFO - Application startup complete.
--- Logging error ---
Traceback (most recent call last):
  File "/usr/lib/python3.10/logging/__init__.py", line 440, in format
    return self._format(record)
  File "/usr/lib/python3.10/logging/__init__.py", line 436, in _format
    return self._fmt % values
KeyError: 'funcname'

During handling of the above exception, another exception occurred:

Traceback (most recent call last):
  File "/usr/lib/python3.10/logging/__init__.py", line 1100, in emit
    msg = self.format(record)
  File "/usr/lib/python3.10/logging/__init__.py", line 943, in format
    return fmt.format(record)
  File "/usr/lib/python3.10/logging/__init__.py", line 681, in format
    s = self.formatMessage(record)
  File "/usr/lib/python3.10/logging/__init__.py", line 650, in formatMessage
    return self._style.format(record)
  File "/usr/lib/python3.10/logging/__init__.py", line 442, in format
    raise ValueError('Formatting field not found in record: %s' % e)
ValueError: Formatting field not found in record: 'funcname'
Call stack:
  File "/usr/bin/uvicorn", line 33, in <module>
    sys.exit(load_entry_point('uvicorn==0.15.0', 'console_scripts', 'uvicorn')())
  File "/usr/lib/python3/dist-packages/click/core.py", line 1128, in __call__
    return self.main(*args, **kwargs)
  File "/usr/lib/python3/dist-packages/click/core.py", line 1053, in main
    rv = self.invoke(ctx)
  File "/usr/lib/python3/dist-packages/click/core.py", line 1395, in invoke
    return ctx.invoke(self.callback, **ctx.params)
  File "/usr/lib/python3/dist-packages/click/core.py", line 754, in invoke
    return __callback(*args, **kwargs)
  File "/usr/lib/python3/dist-packages/uvicorn/main.py", line 425, in main
    run(app, **kwargs)
  File "/usr/lib/python3/dist-packages/uvicorn/main.py", line 442, in run
    ChangeReload(config, target=server.run, sockets=[sock]).run()
  File "/usr/lib/python3/dist-packages/uvicorn/supervisors/basereload.py", line 45, in run
    if self.should_restart():
  File "/usr/lib/python3/dist-packages/uvicorn/supervisors/statreload.py", line 41, in should_restart
    logger.warning(message, display_path)
Message: "StatReload detected file change in '%s'. Reloading..."
Arguments: ('main.py',)
2024-04-30 17:58:19,075 - uvicorn.error - INFO - Shutting down
2024-04-30 17:58:19,176 - uvicorn.error - INFO - Waiting for application shutdown.
2024-04-30 17:58:19,177 - uvicorn.error - INFO - Application shutdown complete.
2024-04-30 17:58:19,177 - uvicorn.error - INFO - Finished server process [19471]
2024-04-30 17:58:19,361 - asyncio - DEBUG - Using selector: EpollSelector
2024-04-30 17:58:19,998 - main - INFO - program_started
2024-04-30 17:58:19,998 - uvicorn.error - INFO - Started server process [19584]
2024-04-30 17:58:19,999 - uvicorn.error - INFO - Waiting for application startup.
2024-04-30 17:58:19,999 - uvicorn.error - INFO - Application startup complete.
--- Logging error ---
Traceback (most recent call last):
  File "/usr/lib/python3.10/logging/__init__.py", line 440, in format
    return self._format(record)
  File "/usr/lib/python3.10/logging/__init__.py", line 436, in _format
    return self._fmt % values
KeyError: 'funcname'

During handling of the above exception, another exception occurred:

Traceback (most recent call last):
  File "/usr/lib/python3.10/logging/__init__.py", line 1100, in emit
    msg = self.format(record)
  File "/usr/lib/python3.10/logging/__init__.py", line 943, in format
    return fmt.format(record)
  File "/usr/lib/python3.10/logging/__init__.py", line 681, in format
    s = self.formatMessage(record)
  File "/usr/lib/python3.10/logging/__init__.py", line 650, in formatMessage
    return self._style.format(record)
  File "/usr/lib/python3.10/logging/__init__.py", line 442, in format
    raise ValueError('Formatting field not found in record: %s' % e)
ValueError: Formatting field not found in record: 'funcname'
Call stack:
  File "/usr/bin/uvicorn", line 33, in <module>
    sys.exit(load_entry_point('uvicorn==0.15.0', 'console_scripts', 'uvicorn')())
  File "/usr/lib/python3/dist-packages/click/core.py", line 1128, in __call__
    return self.main(*args, **kwargs)
  File "/usr/lib/python3/dist-packages/click/core.py", line 1053, in main
    rv = self.invoke(ctx)
  File "/usr/lib/python3/dist-packages/click/core.py", line 1395, in invoke
    return ctx.invoke(self.callback, **ctx.params)
  File "/usr/lib/python3/dist-packages/click/core.py", line 754, in invoke
    return __callback(*args, **kwargs)
  File "/usr/lib/python3/dist-packages/uvicorn/main.py", line 425, in main
    run(app, **kwargs)
  File "/usr/lib/python3/dist-packages/uvicorn/main.py", line 442, in run
    ChangeReload(config, target=server.run, sockets=[sock]).run()
  File "/usr/lib/python3/dist-packages/uvicorn/supervisors/basereload.py", line 45, in run
    if self.should_restart():
  File "/usr/lib/python3/dist-packages/uvicorn/supervisors/statreload.py", line 41, in should_restart
    logger.warning(message, display_path)
Message: "StatReload detected file change in '%s'. Reloading..."
Arguments: ('main.py',)
2024-04-30 17:59:02,822 - uvicorn.error - INFO - Shutting down
2024-04-30 17:59:02,924 - uvicorn.error - INFO - Waiting for application shutdown.
2024-04-30 17:59:02,924 - uvicorn.error - INFO - Application shutdown complete.
2024-04-30 17:59:02,925 - uvicorn.error - INFO - Finished server process [19584]
2024-04-30 17:59:03,097 - asyncio - DEBUG - Using selector: EpollSelector
2024-04-30 17:59:03,730 - main - INFO - program_started
2024-04-30 17:59:03,731 - uvicorn.error - INFO - Started server process [19757]
2024-04-30 17:59:03,731 - uvicorn.error - INFO - Waiting for application startup.
2024-04-30 17:59:03,732 - uvicorn.error - INFO - Application startup complete.
--- Logging error ---
Traceback (most recent call last):
  File "/usr/lib/python3.10/logging/__init__.py", line 440, in format
    return self._format(record)
  File "/usr/lib/python3.10/logging/__init__.py", line 436, in _format
    return self._fmt % values
KeyError: 'funcname'

During handling of the above exception, another exception occurred:

Traceback (most recent call last):
  File "/usr/lib/python3.10/logging/__init__.py", line 1100, in emit
    msg = self.format(record)
  File "/usr/lib/python3.10/logging/__init__.py", line 943, in format
    return fmt.format(record)
  File "/usr/lib/python3.10/logging/__init__.py", line 681, in format
    s = self.formatMessage(record)
  File "/usr/lib/python3.10/logging/__init__.py", line 650, in formatMessage
    return self._style.format(record)
  File "/usr/lib/python3.10/logging/__init__.py", line 442, in format
    raise ValueError('Formatting field not found in record: %s' % e)
ValueError: Formatting field not found in record: 'funcname'
Call stack:
  File "/usr/bin/uvicorn", line 33, in <module>
    sys.exit(load_entry_point('uvicorn==0.15.0', 'console_scripts', 'uvicorn')())
  File "/usr/lib/python3/dist-packages/click/core.py", line 1128, in __call__
    return self.main(*args, **kwargs)
  File "/usr/lib/python3/dist-packages/click/core.py", line 1053, in main
    rv = self.invoke(ctx)
  File "/usr/lib/python3/dist-packages/click/core.py", line 1395, in invoke
    return ctx.invoke(self.callback, **ctx.params)
  File "/usr/lib/python3/dist-packages/click/core.py", line 754, in invoke
    return __callback(*args, **kwargs)
  File "/usr/lib/python3/dist-packages/uvicorn/main.py", line 425, in main
    run(app, **kwargs)
  File "/usr/lib/python3/dist-packages/uvicorn/main.py", line 442, in run
    ChangeReload(config, target=server.run, sockets=[sock]).run()
  File "/usr/lib/python3/dist-packages/uvicorn/supervisors/basereload.py", line 45, in run
    if self.should_restart():
  File "/usr/lib/python3/dist-packages/uvicorn/supervisors/statreload.py", line 41, in should_restart
    logger.warning(message, display_path)
Message: "StatReload detected file change in '%s'. Reloading..."
Arguments: ('main.py',)
2024-04-30 17:59:55,280 - uvicorn.error - INFO - Shutting down
2024-04-30 17:59:55,381 - uvicorn.error - INFO - Waiting for application shutdown.
2024-04-30 17:59:55,381 - uvicorn.error - INFO - Application shutdown complete.
2024-04-30 17:59:55,382 - uvicorn.error - INFO - Finished server process [19757]
2024-04-30 17:59:55,596 - asyncio - DEBUG - Using selector: EpollSelector
2024-04-30 17:59:56,205 - main - INFO - program_started
2024-04-30 17:59:56,206 - uvicorn.error - INFO - Started server process [19966]
2024-04-30 17:59:56,206 - uvicorn.error - INFO - Waiting for application startup.
2024-04-30 17:59:56,207 - uvicorn.error - INFO - Application startup complete.
--- Logging error ---
Traceback (most recent call last):
  File "/usr/lib/python3.10/logging/__init__.py", line 440, in format
    return self._format(record)
  File "/usr/lib/python3.10/logging/__init__.py", line 436, in _format
    return self._fmt % values
KeyError: 'funcname'

During handling of the above exception, another exception occurred:

Traceback (most recent call last):
  File "/usr/lib/python3.10/logging/__init__.py", line 1100, in emit
    msg = self.format(record)
  File "/usr/lib/python3.10/logging/__init__.py", line 943, in format
    return fmt.format(record)
  File "/usr/lib/python3.10/logging/__init__.py", line 681, in format
    s = self.formatMessage(record)
  File "/usr/lib/python3.10/logging/__init__.py", line 650, in formatMessage
    return self._style.format(record)
  File "/usr/lib/python3.10/logging/__init__.py", line 442, in format
    raise ValueError('Formatting field not found in record: %s' % e)
ValueError: Formatting field not found in record: 'funcname'
Call stack:
  File "/usr/bin/uvicorn", line 33, in <module>
    sys.exit(load_entry_point('uvicorn==0.15.0', 'console_scripts', 'uvicorn')())
  File "/usr/lib/python3/dist-packages/click/core.py", line 1128, in __call__
    return self.main(*args, **kwargs)
  File "/usr/lib/python3/dist-packages/click/core.py", line 1053, in main
    rv = self.invoke(ctx)
  File "/usr/lib/python3/dist-packages/click/core.py", line 1395, in invoke
    return ctx.invoke(self.callback, **ctx.params)
  File "/usr/lib/python3/dist-packages/click/core.py", line 754, in invoke
    return __callback(*args, **kwargs)
  File "/usr/lib/python3/dist-packages/uvicorn/main.py", line 425, in main
    run(app, **kwargs)
  File "/usr/lib/python3/dist-packages/uvicorn/main.py", line 442, in run
    ChangeReload(config, target=server.run, sockets=[sock]).run()
  File "/usr/lib/python3/dist-packages/uvicorn/supervisors/basereload.py", line 45, in run
    if self.should_restart():
  File "/usr/lib/python3/dist-packages/uvicorn/supervisors/statreload.py", line 41, in should_restart
    logger.warning(message, display_path)
Message: "StatReload detected file change in '%s'. Reloading..."
Arguments: ('main.py',)
2024-04-30 18:00:05,133 - uvicorn.error - INFO - Shutting down
2024-04-30 18:00:05,234 - uvicorn.error - INFO - Waiting for application shutdown.
2024-04-30 18:00:05,235 - uvicorn.error - INFO - Application shutdown complete.
2024-04-30 18:00:05,235 - uvicorn.error - INFO - Finished server process [19966]
2024-04-30 18:00:05,413 - asyncio - DEBUG - Using selector: EpollSelector
2024-04-30 18:00:06,093 - main - INFO - program_started
2024-04-30 18:00:06,094 - uvicorn.error - INFO - Started server process [20008]
2024-04-30 18:00:06,094 - uvicorn.error - INFO - Waiting for application startup.
2024-04-30 18:00:06,094 - uvicorn.error - INFO - Application startup complete.
2024-04-30 18:01:44,475 - uvicorn.error - INFO - Shutting down
2024-04-30 18:01:44,576 - uvicorn.error - INFO - Waiting for application shutdown.
2024-04-30 18:01:44,577 - uvicorn.error - INFO - Application shutdown complete.
2024-04-30 18:01:44,577 - uvicorn.error - INFO - Finished server process [20008]
--- Logging error ---
Traceback (most recent call last):
  File "/usr/lib/python3.10/logging/__init__.py", line 440, in format
    return self._format(record)
  File "/usr/lib/python3.10/logging/__init__.py", line 436, in _format
    return self._fmt % values
KeyError: 'funcname'

During handling of the above exception, another exception occurred:

Traceback (most recent call last):
  File "/usr/lib/python3.10/logging/__init__.py", line 1100, in emit
    msg = self.format(record)
  File "/usr/lib/python3.10/logging/__init__.py", line 943, in format
    return fmt.format(record)
  File "/usr/lib/python3.10/logging/__init__.py", line 681, in format
    s = self.formatMessage(record)
  File "/usr/lib/python3.10/logging/__init__.py", line 650, in formatMessage
    return self._style.format(record)
  File "/usr/lib/python3.10/logging/__init__.py", line 442, in format
    raise ValueError('Formatting field not found in record: %s' % e)
ValueError: Formatting field not found in record: 'funcname'
Call stack:
  File "/usr/bin/uvicorn", line 33, in <module>
    sys.exit(load_entry_point('uvicorn==0.15.0', 'console_scripts', 'uvicorn')())
  File "/usr/lib/python3/dist-packages/click/core.py", line 1128, in __call__
    return self.main(*args, **kwargs)
  File "/usr/lib/python3/dist-packages/click/core.py", line 1053, in main
    rv = self.invoke(ctx)
  File "/usr/lib/python3/dist-packages/click/core.py", line 1395, in invoke
    return ctx.invoke(self.callback, **ctx.params)
  File "/usr/lib/python3/dist-packages/click/core.py", line 754, in invoke
    return __callback(*args, **kwargs)
  File "/usr/lib/python3/dist-packages/uvicorn/main.py", line 425, in main
    run(app, **kwargs)
  File "/usr/lib/python3/dist-packages/uvicorn/main.py", line 442, in run
    ChangeReload(config, target=server.run, sockets=[sock]).run()
  File "/usr/lib/python3/dist-packages/uvicorn/supervisors/basereload.py", line 48, in run
    self.shutdown()
  File "/usr/lib/python3/dist-packages/uvicorn/supervisors/basereload.py", line 83, in shutdown
    logger.info(message, extra={"color_message": color_message})
Message: 'Stopping reloader process [4299]'
Arguments: ()
