--- Logging error ---
Traceback (most recent call last):
  File "/usr/lib/python3.10/logging/__init__.py", line 440, in format
    return self._format(record)
  File "/usr/lib/python3.10/logging/__init__.py", line 436, in _format
    return self._fmt % values
KeyError: 'funcname'

During handling of the above exception, another exception occurred:

Traceback (most recent call last):
  File "/usr/lib/python3.10/logging/__init__.py", line 1100, in emit
    msg = self.format(record)
  File "/usr/lib/python3.10/logging/__init__.py", line 943, in format
    return fmt.format(record)
  File "/usr/lib/python3.10/logging/__init__.py", line 681, in format
    s = self.formatMessage(record)
  File "/usr/lib/python3.10/logging/__init__.py", line 650, in formatMessage
    return self._style.format(record)
  File "/usr/lib/python3.10/logging/__init__.py", line 442, in format
    raise ValueError('Formatting field not found in record: %s' % e)
ValueError: Formatting field not found in record: 'funcname'
Call stack:
  File "/usr/bin/uvicorn", line 33, in <module>
    sys.exit(load_entry_point('uvicorn==0.15.0', 'console_scripts', 'uvicorn')())
  File "/usr/lib/python3/dist-packages/click/core.py", line 1128, in __call__
    return self.main(*args, **kwargs)
  File "/usr/lib/python3/dist-packages/click/core.py", line 1053, in main
    rv = self.invoke(ctx)
  File "/usr/lib/python3/dist-packages/click/core.py", line 1395, in invoke
    return ctx.invoke(self.callback, **ctx.params)
  File "/usr/lib/python3/dist-packages/click/core.py", line 754, in invoke
    return __callback(*args, **kwargs)
  File "/usr/lib/python3/dist-packages/uvicorn/main.py", line 425, in main
    run(app, **kwargs)
  File "/usr/lib/python3/dist-packages/uvicorn/main.py", line 442, in run
    ChangeReload(config, target=server.run, sockets=[sock]).run()
  File "/usr/lib/python3/dist-packages/uvicorn/supervisors/basereload.py", line 45, in run
    if self.should_restart():
  File "/usr/lib/python3/dist-packages/uvicorn/supervisors/statreload.py", line 41, in should_restart
    logger.warning(message, display_path)
Message: "StatReload detected file change in '%s'. Reloading..."
Arguments: ('main.py',)
2024-04-30 17:38:23,638 - uvicorn.error - INFO - Shutting down
2024-04-30 17:38:23,739 - uvicorn.error - INFO - Waiting for application shutdown.
2024-04-30 17:38:23,739 - uvicorn.error - INFO - Application shutdown complete.
2024-04-30 17:38:23,740 - uvicorn.error - INFO - Finished server process [14554]
2024-04-30 17:38:23,940 - asyncio - DEBUG - Using selector: EpollSelector
2024-04-30 17:38:24,503 - main - INFO - program_started
2024-04-30 17:38:24,504 - uvicorn.error - INFO - Started server process [14814]
2024-04-30 17:38:24,504 - uvicorn.error - INFO - Waiting for application startup.
2024-04-30 17:38:24,504 - uvicorn.error - INFO - Application startup complete.
2024-04-30 17:38:29,679 - root - INFO - get_payments: received payload <{'user_id': 1234, 'rows': ['id', 'paymentto', 'paymentby', 'amount', 'paidon', 'paymentmode', 'paymentstatus', 'description', 'banktransactionid', 'paymentfor', 'dated', 'createdby', 'isdeleted', 'entityid', 'officeid', 'tds', 'professiontax', 'month', 'deduction'], 'filters': [], 'sort_by': [], 'order': 'asc', 'pg_no': 1, 'pg_size': 15, 'search_key': 'anvay'}>
2024-04-30 17:38:29,708 - root - INFO - QUERY IS : <b'SELECT roleid FROM usertable WHERE id = 1234'>
2024-04-30 17:38:29,722 - root - INFO - QUERY IS : <b'SELECT firstname,lastname,id FROM usertable order by firstname'>
2024-04-30 17:38:29,736 - root - INFO - QUERY IS : <b'SELECT DISTINCT id,name from mode_of_payment order by name'>
2024-04-30 17:38:29,747 - root - INFO - QUERY IS : <b'SELECT DISTINCT id,name from entity order by name'>
2024-04-30 17:38:29,759 - root - INFO - QUERY IS : <b'SELECT DISTINCT id,name from payment_for order by name'>
2024-04-30 17:38:29,768 - root - INFO - QUERY IS : <b'SELECT DISTINCT id,status from z_paymentrequeststatus order by status'>
2024-04-30 17:38:29,769 - root - INFO - filtAndPagination_v2: Prepared final query [SELECT id,paymentto,paymentby,amount,paidon,paymentmode,paymentstatus,description,banktransactionid,paymentfor,dated,createdby,isdeleted,entityid,officeid,tds,professiontax,month,deduction FROM get_payments_view]
2024-04-30 17:38:30,228 - root - INFO - Cursor message is SELECT 2013
2024-04-30 17:38:30,575 - root - INFO - filterAndPaginate_v2: Given filter yeilds <2013> entries
2024-04-30 17:38:30,583 - root - INFO - filterAndPaginate_v2: Given search key <anvay> yeilds <988> entries
2024-04-30 17:38:30,586 - uvicorn.access - send - INFO - 127.0.0.1:60182 - "POST /getPayments HTTP/1.1" 200
2024-04-30 17:39:10,978 - root - INFO - get_payments: received payload <{'user_id': 1234, 'rows': ['id', 'paymentto', 'paymentby', 'amount', 'paidon', 'paymentmode', 'paymentstatus', 'description', 'banktransactionid', 'paymentfor', 'dated', 'createdby', 'isdeleted', 'entityid', 'officeid', 'tds', 'professiontax', 'month', 'deduction'], 'filters': [], 'sort_by': [], 'order': 'asc', 'pg_no': 1, 'pg_size': 15, 'search_key': 'anvay'}>
2024-04-30 17:39:10,998 - root - INFO - QUERY IS : <b'SELECT roleid FROM usertable WHERE id = 1234'>
2024-04-30 17:39:11,015 - root - INFO - QUERY IS : <b'SELECT firstname,lastname,id FROM usertable order by firstname'>
2024-04-30 17:39:11,027 - root - INFO - QUERY IS : <b'SELECT DISTINCT id,name from mode_of_payment order by name'>
2024-04-30 17:39:11,041 - root - INFO - QUERY IS : <b'SELECT DISTINCT id,name from entity order by name'>
2024-04-30 17:39:11,054 - root - INFO - QUERY IS : <b'SELECT DISTINCT id,name from payment_for order by name'>
2024-04-30 17:39:11,066 - root - INFO - QUERY IS : <b'SELECT DISTINCT id,status from z_paymentrequeststatus order by status'>
2024-04-30 17:39:11,066 - root - INFO - filtAndPagination_v2: Prepared final query [SELECT id,paymentto,paymentby,amount,paidon,paymentmode,paymentstatus,description,banktransactionid,paymentfor,dated,createdby,isdeleted,entityid,officeid,tds,professiontax,month,deduction FROM get_payments_view]
2024-04-30 17:39:11,534 - root - INFO - Cursor message is SELECT 2013
2024-04-30 17:39:12,089 - root - INFO - filterAndPaginate_v2: Given filter yeilds <2013> entries
2024-04-30 17:39:12,096 - root - INFO - filterAndPaginate_v2: Given search key <anvay> yeilds <988> entries
2024-04-30 17:39:12,101 - uvicorn.access - send - INFO - 127.0.0.1:51928 - "POST /getPayments HTTP/1.1" 200
--- Logging error ---
Traceback (most recent call last):
  File "/usr/lib/python3.10/logging/__init__.py", line 440, in format
    return self._format(record)
  File "/usr/lib/python3.10/logging/__init__.py", line 436, in _format
    return self._fmt % values
KeyError: 'funcname'

During handling of the above exception, another exception occurred:

Traceback (most recent call last):
  File "/usr/lib/python3.10/logging/__init__.py", line 1100, in emit
    msg = self.format(record)
  File "/usr/lib/python3.10/logging/__init__.py", line 943, in format
    return fmt.format(record)
  File "/usr/lib/python3.10/logging/__init__.py", line 681, in format
    s = self.formatMessage(record)
  File "/usr/lib/python3.10/logging/__init__.py", line 650, in formatMessage
    return self._style.format(record)
  File "/usr/lib/python3.10/logging/__init__.py", line 442, in format
    raise ValueError('Formatting field not found in record: %s' % e)
ValueError: Formatting field not found in record: 'funcname'
Call stack:
  File "/usr/bin/uvicorn", line 33, in <module>
    sys.exit(load_entry_point('uvicorn==0.15.0', 'console_scripts', 'uvicorn')())
  File "/usr/lib/python3/dist-packages/click/core.py", line 1128, in __call__
    return self.main(*args, **kwargs)
  File "/usr/lib/python3/dist-packages/click/core.py", line 1053, in main
    rv = self.invoke(ctx)
  File "/usr/lib/python3/dist-packages/click/core.py", line 1395, in invoke
    return ctx.invoke(self.callback, **ctx.params)
  File "/usr/lib/python3/dist-packages/click/core.py", line 754, in invoke
    return __callback(*args, **kwargs)
  File "/usr/lib/python3/dist-packages/uvicorn/main.py", line 425, in main
    run(app, **kwargs)
  File "/usr/lib/python3/dist-packages/uvicorn/main.py", line 442, in run
    ChangeReload(config, target=server.run, sockets=[sock]).run()
  File "/usr/lib/python3/dist-packages/uvicorn/supervisors/basereload.py", line 45, in run
    if self.should_restart():
  File "/usr/lib/python3/dist-packages/uvicorn/supervisors/statreload.py", line 41, in should_restart
    logger.warning(message, display_path)
Message: "StatReload detected file change in '%s'. Reloading..."
Arguments: ('main.py',)
2024-04-30 17:39:19,523 - uvicorn.error - INFO - Shutting down
2024-04-30 17:39:19,624 - uvicorn.error - INFO - Waiting for application shutdown.
2024-04-30 17:39:19,624 - uvicorn.error - INFO - Application shutdown complete.
2024-04-30 17:39:19,624 - uvicorn.error - INFO - Finished server process [14814]
2024-04-30 17:39:19,809 - asyncio - __init__ - DEBUG - Using selector: EpollSelector
2024-04-30 17:39:20,396 - main - <module> - INFO - program_started
2024-04-30 17:39:20,396 - uvicorn.error - serve - INFO - Started server process [15043]
2024-04-30 17:39:20,397 - uvicorn.error - startup - INFO - Waiting for application startup.
2024-04-30 17:39:20,397 - uvicorn.error - startup - INFO - Application startup complete.
2024-04-30 17:39:25,856 - root - get_payments - INFO - get_payments: received payload <{'user_id': 1234, 'rows': ['id', 'paymentto', 'paymentby', 'amount', 'paidon', 'paymentmode', 'paymentstatus', 'description', 'banktransactionid', 'paymentfor', 'dated', 'createdby', 'isdeleted', 'entityid', 'officeid', 'tds', 'professiontax', 'month', 'deduction'], 'filters': [], 'sort_by': [], 'order': 'asc', 'pg_no': 1, 'pg_size': 15, 'search_key': 'anvay'}>
2024-04-30 17:39:25,890 - root - logMessage - INFO - QUERY IS : <b'SELECT roleid FROM usertable WHERE id = 1234'>
2024-04-30 17:39:25,912 - root - logMessage - INFO - QUERY IS : <b'SELECT firstname,lastname,id FROM usertable order by firstname'>
2024-04-30 17:39:25,929 - root - logMessage - INFO - QUERY IS : <b'SELECT DISTINCT id,name from mode_of_payment order by name'>
2024-04-30 17:39:25,947 - root - logMessage - INFO - QUERY IS : <b'SELECT DISTINCT id,name from entity order by name'>
2024-04-30 17:39:25,973 - root - logMessage - INFO - QUERY IS : <b'SELECT DISTINCT id,name from payment_for order by name'>
2024-04-30 17:39:25,990 - root - logMessage - INFO - QUERY IS : <b'SELECT DISTINCT id,status from z_paymentrequeststatus order by status'>
2024-04-30 17:39:25,991 - root - filterAndPaginate_v2 - INFO - filtAndPagination_v2: Prepared final query [SELECT id,paymentto,paymentby,amount,paidon,paymentmode,paymentstatus,description,banktransactionid,paymentfor,dated,createdby,isdeleted,entityid,officeid,tds,professiontax,month,deduction FROM get_payments_view]
2024-04-30 17:39:26,429 - root - filterAndPaginate_v2 - INFO - Cursor message is SELECT 2013
2024-04-30 17:39:26,756 - root - filterAndPaginate_v2 - INFO - filterAndPaginate_v2: Given filter yeilds <2013> entries
2024-04-30 17:39:26,763 - root - filterAndPaginate_v2 - INFO - filterAndPaginate_v2: Given search key <anvay> yeilds <988> entries
2024-04-30 17:39:26,766 - uvicorn.access - send - INFO - 127.0.0.1:50198 - "POST /getPayments HTTP/1.1" 200
2024-04-30 17:39:41,046 - root - get_payments - INFO - get_payments: received payload <{'user_id': 1234, 'rows': ['id', 'paymentto', 'paymentby', 'amount', 'paidon', 'paymentmode', 'paymentstatus', 'description', 'banktransactionid', 'paymentfor', 'dated', 'createdby', 'isdeleted', 'entityid', 'officeid', 'tds', 'professiontax', 'month', 'deduction'], 'filters': [], 'sort_by': [], 'order': 'asc', 'pg_no': 1, 'pg_size': 15, 'search_key': 'anvay'}>
2024-04-30 17:39:41,069 - root - logMessage - INFO - QUERY IS : <b'SELECT roleid FROM usertable WHERE id = 1234'>
2024-04-30 17:39:41,086 - root - logMessage - INFO - QUERY IS : <b'SELECT firstname,lastname,id FROM usertable order by firstname'>
2024-04-30 17:39:41,099 - root - logMessage - INFO - QUERY IS : <b'SELECT DISTINCT id,name from mode_of_payment order by name'>
2024-04-30 17:39:41,114 - root - logMessage - INFO - QUERY IS : <b'SELECT DISTINCT id,name from entity order by name'>
2024-04-30 17:39:41,126 - root - logMessage - INFO - QUERY IS : <b'SELECT DISTINCT id,name from payment_for order by name'>
2024-04-30 17:39:41,139 - root - logMessage - INFO - QUERY IS : <b'SELECT DISTINCT id,status from z_paymentrequeststatus order by status'>
2024-04-30 17:39:41,139 - root - filterAndPaginate_v2 - INFO - filtAndPagination_v2: Prepared final query [SELECT id,paymentto,paymentby,amount,paidon,paymentmode,paymentstatus,description,banktransactionid,paymentfor,dated,createdby,isdeleted,entityid,officeid,tds,professiontax,month,deduction FROM get_payments_view]
2024-04-30 17:39:41,659 - root - filterAndPaginate_v2 - INFO - Cursor message is SELECT 2013
2024-04-30 17:39:42,062 - root - filterAndPaginate_v2 - INFO - filterAndPaginate_v2: Given filter yeilds <2013> entries
2024-04-30 17:39:42,070 - root - filterAndPaginate_v2 - INFO - filterAndPaginate_v2: Given search key <anvay> yeilds <988> entries
2024-04-30 17:39:42,072 - uvicorn.access - send - INFO - 127.0.0.1:60554 - "POST /getPayments HTTP/1.1" 200
--- Logging error ---
Traceback (most recent call last):
  File "/usr/lib/python3.10/logging/__init__.py", line 440, in format
    return self._format(record)
  File "/usr/lib/python3.10/logging/__init__.py", line 436, in _format
    return self._fmt % values
KeyError: 'funcname'

During handling of the above exception, another exception occurred:

Traceback (most recent call last):
  File "/usr/lib/python3.10/logging/__init__.py", line 1100, in emit
    msg = self.format(record)
  File "/usr/lib/python3.10/logging/__init__.py", line 943, in format
    return fmt.format(record)
  File "/usr/lib/python3.10/logging/__init__.py", line 681, in format
    s = self.formatMessage(record)
  File "/usr/lib/python3.10/logging/__init__.py", line 650, in formatMessage
    return self._style.format(record)
  File "/usr/lib/python3.10/logging/__init__.py", line 442, in format
    raise ValueError('Formatting field not found in record: %s' % e)
ValueError: Formatting field not found in record: 'funcname'
Call stack:
  File "/usr/bin/uvicorn", line 33, in <module>
    sys.exit(load_entry_point('uvicorn==0.15.0', 'console_scripts', 'uvicorn')())
  File "/usr/lib/python3/dist-packages/click/core.py", line 1128, in __call__
    return self.main(*args, **kwargs)
  File "/usr/lib/python3/dist-packages/click/core.py", line 1053, in main
    rv = self.invoke(ctx)
  File "/usr/lib/python3/dist-packages/click/core.py", line 1395, in invoke
    return ctx.invoke(self.callback, **ctx.params)
  File "/usr/lib/python3/dist-packages/click/core.py", line 754, in invoke
    return __callback(*args, **kwargs)
  File "/usr/lib/python3/dist-packages/uvicorn/main.py", line 425, in main
    run(app, **kwargs)
  File "/usr/lib/python3/dist-packages/uvicorn/main.py", line 442, in run
    ChangeReload(config, target=server.run, sockets=[sock]).run()
  File "/usr/lib/python3/dist-packages/uvicorn/supervisors/basereload.py", line 45, in run
    if self.should_restart():
  File "/usr/lib/python3/dist-packages/uvicorn/supervisors/statreload.py", line 41, in should_restart
    logger.warning(message, display_path)
Message: "StatReload detected file change in '%s'. Reloading..."
Arguments: ('main.py',)
2024-04-30 17:39:50,598 - uvicorn.error - shutdown - INFO - Shutting down
2024-04-30 17:39:50,698 - uvicorn.error - shutdown - INFO - Waiting for application shutdown.
2024-04-30 17:39:50,699 - uvicorn.error - shutdown - INFO - Application shutdown complete.
2024-04-30 17:39:50,699 - uvicorn.error - serve - INFO - Finished server process [15043]
--- Logging error ---
Traceback (most recent call last):
  File "/usr/lib/python3.10/logging/__init__.py", line 440, in format
    return self._format(record)
  File "/usr/lib/python3.10/logging/__init__.py", line 436, in _format
    return self._fmt % values
KeyError: 'endpt'

During handling of the above exception, another exception occurred:

Traceback (most recent call last):
  File "/usr/lib/python3.10/logging/__init__.py", line 1100, in emit
    msg = self.format(record)
  File "/usr/lib/python3.10/logging/__init__.py", line 943, in format
    return fmt.format(record)
  File "/usr/lib/python3.10/logging/__init__.py", line 681, in format
    s = self.formatMessage(record)
  File "/usr/lib/python3.10/logging/__init__.py", line 650, in formatMessage
    return self._style.format(record)
  File "/usr/lib/python3.10/logging/__init__.py", line 442, in format
    raise ValueError('Formatting field not found in record: %s' % e)
ValueError: Formatting field not found in record: 'endpt'
Call stack:
  File "<string>", line 1, in <module>
  File "/usr/lib/python3.10/multiprocessing/spawn.py", line 116, in spawn_main
    exitcode = _main(fd, parent_sentinel)
  File "/usr/lib/python3.10/multiprocessing/spawn.py", line 129, in _main
    return self._bootstrap(parent_sentinel)
  File "/usr/lib/python3.10/multiprocessing/process.py", line 314, in _bootstrap
    self.run()
  File "/usr/lib/python3.10/multiprocessing/process.py", line 108, in run
    self._target(*self._args, **self._kwargs)
  File "/usr/lib/python3/dist-packages/uvicorn/subprocess.py", line 76, in subprocess_started
    target(sockets=sockets)
  File "/usr/lib/python3/dist-packages/uvicorn/server.py", line 68, in run
    return asyncio.run(self.serve(sockets=sockets))
  File "/usr/lib/python3.10/asyncio/runners.py", line 39, in run
    loop = events.new_event_loop()
  File "/usr/lib/python3.10/asyncio/events.py", line 783, in new_event_loop
    return get_event_loop_policy().new_event_loop()
  File "/usr/lib/python3.10/asyncio/events.py", line 673, in new_event_loop
    return self._loop_factory()
  File "/usr/lib/python3.10/asyncio/unix_events.py", line 64, in __init__
    super().__init__(selector)
  File "/usr/lib/python3.10/asyncio/selector_events.py", line 54, in __init__
    logger.debug('Using selector: %s', selector.__class__.__name__)
Message: 'Using selector: %s'
Arguments: ('EpollSelector',)
--- Logging error ---
Traceback (most recent call last):
  File "/usr/lib/python3.10/logging/__init__.py", line 440, in format
    return self._format(record)
  File "/usr/lib/python3.10/logging/__init__.py", line 436, in _format
    return self._fmt % values
KeyError: 'endpt'

During handling of the above exception, another exception occurred:

Traceback (most recent call last):
  File "/usr/lib/python3.10/logging/__init__.py", line 1100, in emit
    msg = self.format(record)
  File "/usr/lib/python3.10/logging/__init__.py", line 943, in format
    return fmt.format(record)
  File "/usr/lib/python3.10/logging/__init__.py", line 681, in format
    s = self.formatMessage(record)
  File "/usr/lib/python3.10/logging/__init__.py", line 650, in formatMessage
    return self._style.format(record)
  File "/usr/lib/python3.10/logging/__init__.py", line 442, in format
    raise ValueError('Formatting field not found in record: %s' % e)
ValueError: Formatting field not found in record: 'endpt'
Call stack:
  File "<string>", line 1, in <module>
  File "/usr/lib/python3.10/multiprocessing/spawn.py", line 116, in spawn_main
    exitcode = _main(fd, parent_sentinel)
  File "/usr/lib/python3.10/multiprocessing/spawn.py", line 129, in _main
    return self._bootstrap(parent_sentinel)
  File "/usr/lib/python3.10/multiprocessing/process.py", line 314, in _bootstrap
    self.run()
  File "/usr/lib/python3.10/multiprocessing/process.py", line 108, in run
    self._target(*self._args, **self._kwargs)
  File "/usr/lib/python3/dist-packages/uvicorn/subprocess.py", line 76, in subprocess_started
    target(sockets=sockets)
  File "/usr/lib/python3/dist-packages/uvicorn/server.py", line 68, in run
    return asyncio.run(self.serve(sockets=sockets))
  File "/usr/lib/python3.10/asyncio/runners.py", line 44, in run
    return loop.run_until_complete(main)
  File "/usr/lib/python3.10/asyncio/base_events.py", line 636, in run_until_complete
    self.run_forever()
  File "/usr/lib/python3.10/asyncio/base_events.py", line 603, in run_forever
    self._run_once()
  File "/usr/lib/python3.10/asyncio/base_events.py", line 1909, in _run_once
    handle._run()
  File "/usr/lib/python3.10/asyncio/events.py", line 80, in _run
    self._context.run(self._callback, *self._args)
  File "/usr/lib/python3/dist-packages/uvicorn/server.py", line 76, in serve
    config.load()
  File "/usr/lib/python3/dist-packages/uvicorn/config.py", line 448, in load
    self.loaded_app = import_from_string(self.app)
  File "/usr/lib/python3/dist-packages/uvicorn/importer.py", line 21, in import_from_string
    module = importlib.import_module(module_str)
  File "/usr/lib/python3.10/importlib/__init__.py", line 126, in import_module
    return _bootstrap._gcd_import(name[level:], package, level)
  File "<frozen importlib._bootstrap>", line 1050, in _gcd_import
  File "<frozen importlib._bootstrap>", line 1027, in _find_and_load
  File "<frozen importlib._bootstrap>", line 1006, in _find_and_load_unlocked
  File "<frozen importlib._bootstrap>", line 688, in _load_unlocked
  File "<frozen importlib._bootstrap_external>", line 883, in exec_module
  File "<frozen importlib._bootstrap>", line 241, in _call_with_frames_removed
  File "/mnt/e/cura/cura_backend/./main.py", line 4132, in <module>
    logger.info("program_started")
Message: 'program_started'
Arguments: ()
--- Logging error ---
Traceback (most recent call last):
  File "/usr/lib/python3.10/logging/__init__.py", line 440, in format
    return self._format(record)
  File "/usr/lib/python3.10/logging/__init__.py", line 436, in _format
    return self._fmt % values
KeyError: 'endpt'

During handling of the above exception, another exception occurred:

Traceback (most recent call last):
  File "/usr/lib/python3.10/logging/__init__.py", line 1100, in emit
    msg = self.format(record)
  File "/usr/lib/python3.10/logging/__init__.py", line 943, in format
    return fmt.format(record)
  File "/usr/lib/python3.10/logging/__init__.py", line 681, in format
    s = self.formatMessage(record)
  File "/usr/lib/python3.10/logging/__init__.py", line 650, in formatMessage
    return self._style.format(record)
  File "/usr/lib/python3.10/logging/__init__.py", line 442, in format
    raise ValueError('Formatting field not found in record: %s' % e)
ValueError: Formatting field not found in record: 'endpt'
Call stack:
  File "<string>", line 1, in <module>
  File "/usr/lib/python3.10/multiprocessing/spawn.py", line 116, in spawn_main
    exitcode = _main(fd, parent_sentinel)
  File "/usr/lib/python3.10/multiprocessing/spawn.py", line 129, in _main
    return self._bootstrap(parent_sentinel)
  File "/usr/lib/python3.10/multiprocessing/process.py", line 314, in _bootstrap
    self.run()
  File "/usr/lib/python3.10/multiprocessing/process.py", line 108, in run
    self._target(*self._args, **self._kwargs)
  File "/usr/lib/python3/dist-packages/uvicorn/subprocess.py", line 76, in subprocess_started
    target(sockets=sockets)
  File "/usr/lib/python3/dist-packages/uvicorn/server.py", line 68, in run
    return asyncio.run(self.serve(sockets=sockets))
  File "/usr/lib/python3.10/asyncio/runners.py", line 44, in run
    return loop.run_until_complete(main)
  File "/usr/lib/python3.10/asyncio/base_events.py", line 636, in run_until_complete
    self.run_forever()
  File "/usr/lib/python3.10/asyncio/base_events.py", line 603, in run_forever
    self._run_once()
  File "/usr/lib/python3.10/asyncio/base_events.py", line 1909, in _run_once
    handle._run()
  File "/usr/lib/python3.10/asyncio/events.py", line 80, in _run
    self._context.run(self._callback, *self._args)
  File "/usr/lib/python3/dist-packages/uvicorn/server.py", line 84, in serve
    logger.info(message, process_id, extra={"color_message": color_message})
Message: 'Started server process [%d]'
Arguments: (15174,)
--- Logging error ---
Traceback (most recent call last):
  File "/usr/lib/python3.10/logging/__init__.py", line 440, in format
    return self._format(record)
  File "/usr/lib/python3.10/logging/__init__.py", line 436, in _format
    return self._fmt % values
KeyError: 'endpt'

During handling of the above exception, another exception occurred:

Traceback (most recent call last):
  File "/usr/lib/python3.10/logging/__init__.py", line 1100, in emit
    msg = self.format(record)
  File "/usr/lib/python3.10/logging/__init__.py", line 943, in format
    return fmt.format(record)
  File "/usr/lib/python3.10/logging/__init__.py", line 681, in format
    s = self.formatMessage(record)
  File "/usr/lib/python3.10/logging/__init__.py", line 650, in formatMessage
    return self._style.format(record)
  File "/usr/lib/python3.10/logging/__init__.py", line 442, in format
    raise ValueError('Formatting field not found in record: %s' % e)
ValueError: Formatting field not found in record: 'endpt'
Call stack:
  File "<string>", line 1, in <module>
  File "/usr/lib/python3.10/multiprocessing/spawn.py", line 116, in spawn_main
    exitcode = _main(fd, parent_sentinel)
  File "/usr/lib/python3.10/multiprocessing/spawn.py", line 129, in _main
    return self._bootstrap(parent_sentinel)
  File "/usr/lib/python3.10/multiprocessing/process.py", line 314, in _bootstrap
    self.run()
  File "/usr/lib/python3.10/multiprocessing/process.py", line 108, in run
    self._target(*self._args, **self._kwargs)
  File "/usr/lib/python3/dist-packages/uvicorn/subprocess.py", line 76, in subprocess_started
    target(sockets=sockets)
  File "/usr/lib/python3/dist-packages/uvicorn/server.py", line 68, in run
    return asyncio.run(self.serve(sockets=sockets))
  File "/usr/lib/python3.10/asyncio/runners.py", line 44, in run
    return loop.run_until_complete(main)
  File "/usr/lib/python3.10/asyncio/base_events.py", line 636, in run_until_complete
    self.run_forever()
  File "/usr/lib/python3.10/asyncio/base_events.py", line 603, in run_forever
    self._run_once()
  File "/usr/lib/python3.10/asyncio/base_events.py", line 1909, in _run_once
    handle._run()
  File "/usr/lib/python3.10/asyncio/events.py", line 80, in _run
    self._context.run(self._callback, *self._args)
  File "/usr/lib/python3/dist-packages/uvicorn/server.py", line 86, in serve
    await self.startup(sockets=sockets)
  File "/usr/lib/python3/dist-packages/uvicorn/server.py", line 97, in startup
    await self.lifespan.startup()
  File "/usr/lib/python3/dist-packages/uvicorn/lifespan/on.py", line 45, in startup
    self.logger.info("Waiting for application startup.")
Message: 'Waiting for application startup.'
Arguments: ()
--- Logging error ---
Traceback (most recent call last):
  File "/usr/lib/python3.10/logging/__init__.py", line 440, in format
    return self._format(record)
  File "/usr/lib/python3.10/logging/__init__.py", line 436, in _format
    return self._fmt % values
KeyError: 'endpt'

During handling of the above exception, another exception occurred:

Traceback (most recent call last):
  File "/usr/lib/python3.10/logging/__init__.py", line 1100, in emit
    msg = self.format(record)
  File "/usr/lib/python3.10/logging/__init__.py", line 943, in format
    return fmt.format(record)
  File "/usr/lib/python3.10/logging/__init__.py", line 681, in format
    s = self.formatMessage(record)
  File "/usr/lib/python3.10/logging/__init__.py", line 650, in formatMessage
    return self._style.format(record)
  File "/usr/lib/python3.10/logging/__init__.py", line 442, in format
    raise ValueError('Formatting field not found in record: %s' % e)
ValueError: Formatting field not found in record: 'endpt'
Call stack:
  File "<string>", line 1, in <module>
  File "/usr/lib/python3.10/multiprocessing/spawn.py", line 116, in spawn_main
    exitcode = _main(fd, parent_sentinel)
  File "/usr/lib/python3.10/multiprocessing/spawn.py", line 129, in _main
    return self._bootstrap(parent_sentinel)
  File "/usr/lib/python3.10/multiprocessing/process.py", line 314, in _bootstrap
    self.run()
  File "/usr/lib/python3.10/multiprocessing/process.py", line 108, in run
    self._target(*self._args, **self._kwargs)
  File "/usr/lib/python3/dist-packages/uvicorn/subprocess.py", line 76, in subprocess_started
    target(sockets=sockets)
  File "/usr/lib/python3/dist-packages/uvicorn/server.py", line 68, in run
    return asyncio.run(self.serve(sockets=sockets))
  File "/usr/lib/python3.10/asyncio/runners.py", line 44, in run
    return loop.run_until_complete(main)
  File "/usr/lib/python3.10/asyncio/base_events.py", line 636, in run_until_complete
    self.run_forever()
  File "/usr/lib/python3.10/asyncio/base_events.py", line 603, in run_forever
    self._run_once()
  File "/usr/lib/python3.10/asyncio/base_events.py", line 1909, in _run_once
    handle._run()
  File "/usr/lib/python3.10/asyncio/events.py", line 80, in _run
    self._context.run(self._callback, *self._args)
  File "/usr/lib/python3/dist-packages/uvicorn/server.py", line 86, in serve
    await self.startup(sockets=sockets)
  File "/usr/lib/python3/dist-packages/uvicorn/server.py", line 97, in startup
    await self.lifespan.startup()
  File "/usr/lib/python3/dist-packages/uvicorn/lifespan/on.py", line 59, in startup
    self.logger.info("Application startup complete.")
Message: 'Application startup complete.'
Arguments: ()
--- Logging error ---
Traceback (most recent call last):
  File "/usr/lib/python3.10/logging/__init__.py", line 440, in format
    return self._format(record)
  File "/usr/lib/python3.10/logging/__init__.py", line 436, in _format
    return self._fmt % values
KeyError: 'funcname'

During handling of the above exception, another exception occurred:

Traceback (most recent call last):
  File "/usr/lib/python3.10/logging/__init__.py", line 1100, in emit
    msg = self.format(record)
  File "/usr/lib/python3.10/logging/__init__.py", line 943, in format
    return fmt.format(record)
  File "/usr/lib/python3.10/logging/__init__.py", line 681, in format
    s = self.formatMessage(record)
  File "/usr/lib/python3.10/logging/__init__.py", line 650, in formatMessage
    return self._style.format(record)
  File "/usr/lib/python3.10/logging/__init__.py", line 442, in format
    raise ValueError('Formatting field not found in record: %s' % e)
ValueError: Formatting field not found in record: 'funcname'
Call stack:
  File "/usr/bin/uvicorn", line 33, in <module>
    sys.exit(load_entry_point('uvicorn==0.15.0', 'console_scripts', 'uvicorn')())
  File "/usr/lib/python3/dist-packages/click/core.py", line 1128, in __call__
    return self.main(*args, **kwargs)
  File "/usr/lib/python3/dist-packages/click/core.py", line 1053, in main
    rv = self.invoke(ctx)
  File "/usr/lib/python3/dist-packages/click/core.py", line 1395, in invoke
    return ctx.invoke(self.callback, **ctx.params)
  File "/usr/lib/python3/dist-packages/click/core.py", line 754, in invoke
    return __callback(*args, **kwargs)
  File "/usr/lib/python3/dist-packages/uvicorn/main.py", line 425, in main
    run(app, **kwargs)
  File "/usr/lib/python3/dist-packages/uvicorn/main.py", line 442, in run
    ChangeReload(config, target=server.run, sockets=[sock]).run()
  File "/usr/lib/python3/dist-packages/uvicorn/supervisors/basereload.py", line 45, in run
    if self.should_restart():
  File "/usr/lib/python3/dist-packages/uvicorn/supervisors/statreload.py", line 41, in should_restart
    logger.warning(message, display_path)
Message: "StatReload detected file change in '%s'. Reloading..."
Arguments: ('main.py',)
--- Logging error ---
Traceback (most recent call last):
  File "/usr/lib/python3.10/logging/__init__.py", line 440, in format
    return self._format(record)
  File "/usr/lib/python3.10/logging/__init__.py", line 436, in _format
    return self._fmt % values
KeyError: 'endpt'

During handling of the above exception, another exception occurred:

Traceback (most recent call last):
  File "/usr/lib/python3.10/logging/__init__.py", line 1100, in emit
    msg = self.format(record)
  File "/usr/lib/python3.10/logging/__init__.py", line 943, in format
    return fmt.format(record)
  File "/usr/lib/python3.10/logging/__init__.py", line 681, in format
    s = self.formatMessage(record)
  File "/usr/lib/python3.10/logging/__init__.py", line 650, in formatMessage
    return self._style.format(record)
  File "/usr/lib/python3.10/logging/__init__.py", line 442, in format
    raise ValueError('Formatting field not found in record: %s' % e)
ValueError: Formatting field not found in record: 'endpt'
Call stack:
  File "<string>", line 1, in <module>
  File "/usr/lib/python3.10/multiprocessing/spawn.py", line 116, in spawn_main
    exitcode = _main(fd, parent_sentinel)
  File "/usr/lib/python3.10/multiprocessing/spawn.py", line 129, in _main
    return self._bootstrap(parent_sentinel)
  File "/usr/lib/python3.10/multiprocessing/process.py", line 314, in _bootstrap
    self.run()
  File "/usr/lib/python3.10/multiprocessing/process.py", line 108, in run
    self._target(*self._args, **self._kwargs)
  File "/usr/lib/python3/dist-packages/uvicorn/subprocess.py", line 76, in subprocess_started
    target(sockets=sockets)
  File "/usr/lib/python3/dist-packages/uvicorn/server.py", line 68, in run
    return asyncio.run(self.serve(sockets=sockets))
  File "/usr/lib/python3.10/asyncio/runners.py", line 44, in run
    return loop.run_until_complete(main)
  File "/usr/lib/python3.10/asyncio/base_events.py", line 636, in run_until_complete
    self.run_forever()
  File "/usr/lib/python3.10/asyncio/base_events.py", line 603, in run_forever
    self._run_once()
  File "/usr/lib/python3.10/asyncio/base_events.py", line 1909, in _run_once
    handle._run()
  File "/usr/lib/python3.10/asyncio/events.py", line 80, in _run
    self._context.run(self._callback, *self._args)
  File "/usr/lib/python3/dist-packages/uvicorn/server.py", line 90, in serve
    await self.shutdown(sockets=sockets)
  File "/usr/lib/python3/dist-packages/uvicorn/server.py", line 263, in shutdown
    logger.info("Shutting down")
Message: 'Shutting down'
Arguments: ()
--- Logging error ---
Traceback (most recent call last):
  File "/usr/lib/python3.10/logging/__init__.py", line 440, in format
    return self._format(record)
  File "/usr/lib/python3.10/logging/__init__.py", line 436, in _format
    return self._fmt % values
KeyError: 'endpt'

During handling of the above exception, another exception occurred:

Traceback (most recent call last):
  File "/usr/lib/python3.10/logging/__init__.py", line 1100, in emit
    msg = self.format(record)
  File "/usr/lib/python3.10/logging/__init__.py", line 943, in format
    return fmt.format(record)
  File "/usr/lib/python3.10/logging/__init__.py", line 681, in format
    s = self.formatMessage(record)
  File "/usr/lib/python3.10/logging/__init__.py", line 650, in formatMessage
    return self._style.format(record)
  File "/usr/lib/python3.10/logging/__init__.py", line 442, in format
    raise ValueError('Formatting field not found in record: %s' % e)
ValueError: Formatting field not found in record: 'endpt'
Call stack:
  File "<string>", line 1, in <module>
  File "/usr/lib/python3.10/multiprocessing/spawn.py", line 116, in spawn_main
    exitcode = _main(fd, parent_sentinel)
  File "/usr/lib/python3.10/multiprocessing/spawn.py", line 129, in _main
    return self._bootstrap(parent_sentinel)
  File "/usr/lib/python3.10/multiprocessing/process.py", line 314, in _bootstrap
    self.run()
  File "/usr/lib/python3.10/multiprocessing/process.py", line 108, in run
    self._target(*self._args, **self._kwargs)
  File "/usr/lib/python3/dist-packages/uvicorn/subprocess.py", line 76, in subprocess_started
    target(sockets=sockets)
  File "/usr/lib/python3/dist-packages/uvicorn/server.py", line 68, in run
    return asyncio.run(self.serve(sockets=sockets))
  File "/usr/lib/python3.10/asyncio/runners.py", line 44, in run
    return loop.run_until_complete(main)
  File "/usr/lib/python3.10/asyncio/base_events.py", line 636, in run_until_complete
    self.run_forever()
  File "/usr/lib/python3.10/asyncio/base_events.py", line 603, in run_forever
    self._run_once()
  File "/usr/lib/python3.10/asyncio/base_events.py", line 1909, in _run_once
    handle._run()
  File "/usr/lib/python3.10/asyncio/events.py", line 80, in _run
    self._context.run(self._callback, *self._args)
  File "/usr/lib/python3/dist-packages/uvicorn/server.py", line 90, in serve
    await self.shutdown(sockets=sockets)
  File "/usr/lib/python3/dist-packages/uvicorn/server.py", line 294, in shutdown
    await self.lifespan.shutdown()
  File "/usr/lib/python3/dist-packages/uvicorn/lifespan/on.py", line 64, in shutdown
    self.logger.info("Waiting for application shutdown.")
Message: 'Waiting for application shutdown.'
Arguments: ()
--- Logging error ---
Traceback (most recent call last):
  File "/usr/lib/python3.10/logging/__init__.py", line 440, in format
    return self._format(record)
  File "/usr/lib/python3.10/logging/__init__.py", line 436, in _format
    return self._fmt % values
KeyError: 'endpt'

During handling of the above exception, another exception occurred:

Traceback (most recent call last):
  File "/usr/lib/python3.10/logging/__init__.py", line 1100, in emit
    msg = self.format(record)
  File "/usr/lib/python3.10/logging/__init__.py", line 943, in format
    return fmt.format(record)
  File "/usr/lib/python3.10/logging/__init__.py", line 681, in format
    s = self.formatMessage(record)
  File "/usr/lib/python3.10/logging/__init__.py", line 650, in formatMessage
    return self._style.format(record)
  File "/usr/lib/python3.10/logging/__init__.py", line 442, in format
    raise ValueError('Formatting field not found in record: %s' % e)
ValueError: Formatting field not found in record: 'endpt'
Call stack:
  File "<string>", line 1, in <module>
  File "/usr/lib/python3.10/multiprocessing/spawn.py", line 116, in spawn_main
    exitcode = _main(fd, parent_sentinel)
  File "/usr/lib/python3.10/multiprocessing/spawn.py", line 129, in _main
    return self._bootstrap(parent_sentinel)
  File "/usr/lib/python3.10/multiprocessing/process.py", line 314, in _bootstrap
    self.run()
  File "/usr/lib/python3.10/multiprocessing/process.py", line 108, in run
    self._target(*self._args, **self._kwargs)
  File "/usr/lib/python3/dist-packages/uvicorn/subprocess.py", line 76, in subprocess_started
    target(sockets=sockets)
  File "/usr/lib/python3/dist-packages/uvicorn/server.py", line 68, in run
    return asyncio.run(self.serve(sockets=sockets))
  File "/usr/lib/python3.10/asyncio/runners.py", line 44, in run
    return loop.run_until_complete(main)
  File "/usr/lib/python3.10/asyncio/base_events.py", line 636, in run_until_complete
    self.run_forever()
  File "/usr/lib/python3.10/asyncio/base_events.py", line 603, in run_forever
    self._run_once()
  File "/usr/lib/python3.10/asyncio/base_events.py", line 1909, in _run_once
    handle._run()
  File "/usr/lib/python3.10/asyncio/events.py", line 80, in _run
    self._context.run(self._callback, *self._args)
  File "/usr/lib/python3/dist-packages/uvicorn/server.py", line 90, in serve
    await self.shutdown(sockets=sockets)
  File "/usr/lib/python3/dist-packages/uvicorn/server.py", line 294, in shutdown
    await self.lifespan.shutdown()
  File "/usr/lib/python3/dist-packages/uvicorn/lifespan/on.py", line 75, in shutdown
    self.logger.info("Application shutdown complete.")
Message: 'Application shutdown complete.'
Arguments: ()
--- Logging error ---
Traceback (most recent call last):
  File "/usr/lib/python3.10/logging/__init__.py", line 440, in format
    return self._format(record)
  File "/usr/lib/python3.10/logging/__init__.py", line 436, in _format
    return self._fmt % values
KeyError: 'endpt'

During handling of the above exception, another exception occurred:

Traceback (most recent call last):
  File "/usr/lib/python3.10/logging/__init__.py", line 1100, in emit
    msg = self.format(record)
  File "/usr/lib/python3.10/logging/__init__.py", line 943, in format
    return fmt.format(record)
  File "/usr/lib/python3.10/logging/__init__.py", line 681, in format
    s = self.formatMessage(record)
  File "/usr/lib/python3.10/logging/__init__.py", line 650, in formatMessage
    return self._style.format(record)
  File "/usr/lib/python3.10/logging/__init__.py", line 442, in format
    raise ValueError('Formatting field not found in record: %s' % e)
ValueError: Formatting field not found in record: 'endpt'
Call stack:
  File "<string>", line 1, in <module>
  File "/usr/lib/python3.10/multiprocessing/spawn.py", line 116, in spawn_main
    exitcode = _main(fd, parent_sentinel)
  File "/usr/lib/python3.10/multiprocessing/spawn.py", line 129, in _main
    return self._bootstrap(parent_sentinel)
  File "/usr/lib/python3.10/multiprocessing/process.py", line 314, in _bootstrap
    self.run()
  File "/usr/lib/python3.10/multiprocessing/process.py", line 108, in run
    self._target(*self._args, **self._kwargs)
  File "/usr/lib/python3/dist-packages/uvicorn/subprocess.py", line 76, in subprocess_started
    target(sockets=sockets)
  File "/usr/lib/python3/dist-packages/uvicorn/server.py", line 68, in run
    return asyncio.run(self.serve(sockets=sockets))
  File "/usr/lib/python3.10/asyncio/runners.py", line 44, in run
    return loop.run_until_complete(main)
  File "/usr/lib/python3.10/asyncio/base_events.py", line 636, in run_until_complete
    self.run_forever()
  File "/usr/lib/python3.10/asyncio/base_events.py", line 603, in run_forever
    self._run_once()
  File "/usr/lib/python3.10/asyncio/base_events.py", line 1909, in _run_once
    handle._run()
  File "/usr/lib/python3.10/asyncio/events.py", line 80, in _run
    self._context.run(self._callback, *self._args)
  File "/usr/lib/python3/dist-packages/uvicorn/server.py", line 94, in serve
    logger.info(message, process_id, extra={"color_message": color_message})
Message: 'Finished server process [%d]'
Arguments: (15174,)
--- Logging error ---
Traceback (most recent call last):
  File "/usr/lib/python3.10/logging/__init__.py", line 440, in format
    return self._format(record)
  File "/usr/lib/python3.10/logging/__init__.py", line 436, in _format
    return self._fmt % values
KeyError: 'endpt'

During handling of the above exception, another exception occurred:

Traceback (most recent call last):
  File "/usr/lib/python3.10/logging/__init__.py", line 1100, in emit
    msg = self.format(record)
  File "/usr/lib/python3.10/logging/__init__.py", line 943, in format
    return fmt.format(record)
  File "/usr/lib/python3.10/logging/__init__.py", line 681, in format
    s = self.formatMessage(record)
  File "/usr/lib/python3.10/logging/__init__.py", line 650, in formatMessage
    return self._style.format(record)
  File "/usr/lib/python3.10/logging/__init__.py", line 442, in format
    raise ValueError('Formatting field not found in record: %s' % e)
ValueError: Formatting field not found in record: 'endpt'
Call stack:
  File "<string>", line 1, in <module>
  File "/usr/lib/python3.10/multiprocessing/spawn.py", line 116, in spawn_main
    exitcode = _main(fd, parent_sentinel)
  File "/usr/lib/python3.10/multiprocessing/spawn.py", line 129, in _main
    return self._bootstrap(parent_sentinel)
  File "/usr/lib/python3.10/multiprocessing/process.py", line 314, in _bootstrap
    self.run()
  File "/usr/lib/python3.10/multiprocessing/process.py", line 108, in run
    self._target(*self._args, **self._kwargs)
  File "/usr/lib/python3/dist-packages/uvicorn/subprocess.py", line 76, in subprocess_started
    target(sockets=sockets)
  File "/usr/lib/python3/dist-packages/uvicorn/server.py", line 68, in run
    return asyncio.run(self.serve(sockets=sockets))
  File "/usr/lib/python3.10/asyncio/runners.py", line 39, in run
    loop = events.new_event_loop()
  File "/usr/lib/python3.10/asyncio/events.py", line 783, in new_event_loop
    return get_event_loop_policy().new_event_loop()
  File "/usr/lib/python3.10/asyncio/events.py", line 673, in new_event_loop
    return self._loop_factory()
  File "/usr/lib/python3.10/asyncio/unix_events.py", line 64, in __init__
    super().__init__(selector)
  File "/usr/lib/python3.10/asyncio/selector_events.py", line 54, in __init__
    logger.debug('Using selector: %s', selector.__class__.__name__)
Message: 'Using selector: %s'
Arguments: ('EpollSelector',)
Process SpawnProcess-24:
Traceback (most recent call last):
  File "/usr/lib/python3.10/multiprocessing/process.py", line 314, in _bootstrap
    self.run()
  File "/usr/lib/python3.10/multiprocessing/process.py", line 108, in run
    self._target(*self._args, **self._kwargs)
  File "/usr/lib/python3/dist-packages/uvicorn/subprocess.py", line 76, in subprocess_started
    target(sockets=sockets)
  File "/usr/lib/python3/dist-packages/uvicorn/server.py", line 68, in run
    return asyncio.run(self.serve(sockets=sockets))
  File "/usr/lib/python3.10/asyncio/runners.py", line 44, in run
    return loop.run_until_complete(main)
  File "/usr/lib/python3.10/asyncio/base_events.py", line 649, in run_until_complete
    return future.result()
  File "/usr/lib/python3/dist-packages/uvicorn/server.py", line 76, in serve
    config.load()
  File "/usr/lib/python3/dist-packages/uvicorn/config.py", line 448, in load
    self.loaded_app = import_from_string(self.app)
  File "/usr/lib/python3/dist-packages/uvicorn/importer.py", line 21, in import_from_string
    module = importlib.import_module(module_str)
  File "/usr/lib/python3.10/importlib/__init__.py", line 126, in import_module
    return _bootstrap._gcd_import(name[level:], package, level)
  File "<frozen importlib._bootstrap>", line 1050, in _gcd_import
  File "<frozen importlib._bootstrap>", line 1027, in _find_and_load
  File "<frozen importlib._bootstrap>", line 1006, in _find_and_load_unlocked
  File "<frozen importlib._bootstrap>", line 688, in _load_unlocked
  File "<frozen importlib._bootstrap_external>", line 879, in exec_module
  File "<frozen importlib._bootstrap_external>", line 1017, in get_code
  File "<frozen importlib._bootstrap_external>", line 947, in source_to_code
  File "<frozen importlib._bootstrap>", line 241, in _call_with_frames_removed
  File "/mnt/e/cura/cura_backend/./main.py", line 758
    ))
    ^
SyntaxError: unmatched ')'
--- Logging error ---
Traceback (most recent call last):
  File "/usr/lib/python3.10/logging/__init__.py", line 440, in format
    return self._format(record)
  File "/usr/lib/python3.10/logging/__init__.py", line 436, in _format
    return self._fmt % values
KeyError: 'funcname'

During handling of the above exception, another exception occurred:

Traceback (most recent call last):
  File "/usr/lib/python3.10/logging/__init__.py", line 1100, in emit
    msg = self.format(record)
  File "/usr/lib/python3.10/logging/__init__.py", line 943, in format
    return fmt.format(record)
  File "/usr/lib/python3.10/logging/__init__.py", line 681, in format
    s = self.formatMessage(record)
  File "/usr/lib/python3.10/logging/__init__.py", line 650, in formatMessage
    return self._style.format(record)
  File "/usr/lib/python3.10/logging/__init__.py", line 442, in format
    raise ValueError('Formatting field not found in record: %s' % e)
ValueError: Formatting field not found in record: 'funcname'
Call stack:
  File "/usr/bin/uvicorn", line 33, in <module>
    sys.exit(load_entry_point('uvicorn==0.15.0', 'console_scripts', 'uvicorn')())
  File "/usr/lib/python3/dist-packages/click/core.py", line 1128, in __call__
    return self.main(*args, **kwargs)
  File "/usr/lib/python3/dist-packages/click/core.py", line 1053, in main
    rv = self.invoke(ctx)
  File "/usr/lib/python3/dist-packages/click/core.py", line 1395, in invoke
    return ctx.invoke(self.callback, **ctx.params)
  File "/usr/lib/python3/dist-packages/click/core.py", line 754, in invoke
    return __callback(*args, **kwargs)
  File "/usr/lib/python3/dist-packages/uvicorn/main.py", line 425, in main
    run(app, **kwargs)
  File "/usr/lib/python3/dist-packages/uvicorn/main.py", line 442, in run
    ChangeReload(config, target=server.run, sockets=[sock]).run()
  File "/usr/lib/python3/dist-packages/uvicorn/supervisors/basereload.py", line 45, in run
    if self.should_restart():
  File "/usr/lib/python3/dist-packages/uvicorn/supervisors/statreload.py", line 41, in should_restart
    logger.warning(message, display_path)
Message: "StatReload detected file change in '%s'. Reloading..."
Arguments: ('main.py',)
--- Logging error ---
Traceback (most recent call last):
  File "/usr/lib/python3.10/logging/__init__.py", line 440, in format
    return self._format(record)
  File "/usr/lib/python3.10/logging/__init__.py", line 436, in _format
    return self._fmt % values
KeyError: 'endpt'

During handling of the above exception, another exception occurred:

Traceback (most recent call last):
  File "/usr/lib/python3.10/logging/__init__.py", line 1100, in emit
    msg = self.format(record)
  File "/usr/lib/python3.10/logging/__init__.py", line 943, in format
    return fmt.format(record)
  File "/usr/lib/python3.10/logging/__init__.py", line 681, in format
    s = self.formatMessage(record)
  File "/usr/lib/python3.10/logging/__init__.py", line 650, in formatMessage
    return self._style.format(record)
  File "/usr/lib/python3.10/logging/__init__.py", line 442, in format
    raise ValueError('Formatting field not found in record: %s' % e)
ValueError: Formatting field not found in record: 'endpt'
Call stack:
  File "<string>", line 1, in <module>
  File "/usr/lib/python3.10/multiprocessing/spawn.py", line 116, in spawn_main
    exitcode = _main(fd, parent_sentinel)
  File "/usr/lib/python3.10/multiprocessing/spawn.py", line 129, in _main
    return self._bootstrap(parent_sentinel)
  File "/usr/lib/python3.10/multiprocessing/process.py", line 314, in _bootstrap
    self.run()
  File "/usr/lib/python3.10/multiprocessing/process.py", line 108, in run
    self._target(*self._args, **self._kwargs)
  File "/usr/lib/python3/dist-packages/uvicorn/subprocess.py", line 76, in subprocess_started
    target(sockets=sockets)
  File "/usr/lib/python3/dist-packages/uvicorn/server.py", line 68, in run
    return asyncio.run(self.serve(sockets=sockets))
  File "/usr/lib/python3.10/asyncio/runners.py", line 39, in run
    loop = events.new_event_loop()
  File "/usr/lib/python3.10/asyncio/events.py", line 783, in new_event_loop
    return get_event_loop_policy().new_event_loop()
  File "/usr/lib/python3.10/asyncio/events.py", line 673, in new_event_loop
    return self._loop_factory()
  File "/usr/lib/python3.10/asyncio/unix_events.py", line 64, in __init__
    super().__init__(selector)
  File "/usr/lib/python3.10/asyncio/selector_events.py", line 54, in __init__
    logger.debug('Using selector: %s', selector.__class__.__name__)
Message: 'Using selector: %s'
Arguments: ('EpollSelector',)
Process SpawnProcess-25:
Traceback (most recent call last):
  File "/usr/lib/python3.10/multiprocessing/process.py", line 314, in _bootstrap
    self.run()
  File "/usr/lib/python3.10/multiprocessing/process.py", line 108, in run
    self._target(*self._args, **self._kwargs)
  File "/usr/lib/python3/dist-packages/uvicorn/subprocess.py", line 76, in subprocess_started
    target(sockets=sockets)
  File "/usr/lib/python3/dist-packages/uvicorn/server.py", line 68, in run
    return asyncio.run(self.serve(sockets=sockets))
  File "/usr/lib/python3.10/asyncio/runners.py", line 44, in run
    return loop.run_until_complete(main)
  File "/usr/lib/python3.10/asyncio/base_events.py", line 649, in run_until_complete
    return future.result()
  File "/usr/lib/python3/dist-packages/uvicorn/server.py", line 76, in serve
    config.load()
  File "/usr/lib/python3/dist-packages/uvicorn/config.py", line 448, in load
    self.loaded_app = import_from_string(self.app)
  File "/usr/lib/python3/dist-packages/uvicorn/importer.py", line 21, in import_from_string
    module = importlib.import_module(module_str)
  File "/usr/lib/python3.10/importlib/__init__.py", line 126, in import_module
    return _bootstrap._gcd_import(name[level:], package, level)
  File "<frozen importlib._bootstrap>", line 1050, in _gcd_import
  File "<frozen importlib._bootstrap>", line 1027, in _find_and_load
  File "<frozen importlib._bootstrap>", line 1006, in _find_and_load_unlocked
  File "<frozen importlib._bootstrap>", line 688, in _load_unlocked
  File "<frozen importlib._bootstrap_external>", line 879, in exec_module
  File "<frozen importlib._bootstrap_external>", line 1017, in get_code
  File "<frozen importlib._bootstrap_external>", line 947, in source_to_code
  File "<frozen importlib._bootstrap>", line 241, in _call_with_frames_removed
  File "/mnt/e/cura/cura_backend/./main.py", line 16
    return f'QUERY IS : <{cursor.mogrify(query,arr)}>')
                                                      ^
SyntaxError: unmatched ')'
--- Logging error ---
Traceback (most recent call last):
  File "/usr/lib/python3.10/logging/__init__.py", line 440, in format
    return self._format(record)
  File "/usr/lib/python3.10/logging/__init__.py", line 436, in _format
    return self._fmt % values
KeyError: 'funcname'

During handling of the above exception, another exception occurred:

Traceback (most recent call last):
  File "/usr/lib/python3.10/logging/__init__.py", line 1100, in emit
    msg = self.format(record)
  File "/usr/lib/python3.10/logging/__init__.py", line 943, in format
    return fmt.format(record)
  File "/usr/lib/python3.10/logging/__init__.py", line 681, in format
    s = self.formatMessage(record)
  File "/usr/lib/python3.10/logging/__init__.py", line 650, in formatMessage
    return self._style.format(record)
  File "/usr/lib/python3.10/logging/__init__.py", line 442, in format
    raise ValueError('Formatting field not found in record: %s' % e)
ValueError: Formatting field not found in record: 'funcname'
Call stack:
  File "/usr/bin/uvicorn", line 33, in <module>
    sys.exit(load_entry_point('uvicorn==0.15.0', 'console_scripts', 'uvicorn')())
  File "/usr/lib/python3/dist-packages/click/core.py", line 1128, in __call__
    return self.main(*args, **kwargs)
  File "/usr/lib/python3/dist-packages/click/core.py", line 1053, in main
    rv = self.invoke(ctx)
  File "/usr/lib/python3/dist-packages/click/core.py", line 1395, in invoke
    return ctx.invoke(self.callback, **ctx.params)
  File "/usr/lib/python3/dist-packages/click/core.py", line 754, in invoke
    return __callback(*args, **kwargs)
  File "/usr/lib/python3/dist-packages/uvicorn/main.py", line 425, in main
    run(app, **kwargs)
  File "/usr/lib/python3/dist-packages/uvicorn/main.py", line 442, in run
    ChangeReload(config, target=server.run, sockets=[sock]).run()
  File "/usr/lib/python3/dist-packages/uvicorn/supervisors/basereload.py", line 45, in run
    if self.should_restart():
  File "/usr/lib/python3/dist-packages/uvicorn/supervisors/statreload.py", line 41, in should_restart
    logger.warning(message, display_path)
Message: "StatReload detected file change in '%s'. Reloading..."
Arguments: ('main.py',)
--- Logging error ---
Traceback (most recent call last):
  File "/usr/lib/python3.10/logging/__init__.py", line 440, in format
    return self._format(record)
  File "/usr/lib/python3.10/logging/__init__.py", line 436, in _format
    return self._fmt % values
KeyError: 'endpt'

During handling of the above exception, another exception occurred:

Traceback (most recent call last):
  File "/usr/lib/python3.10/logging/__init__.py", line 1100, in emit
    msg = self.format(record)
  File "/usr/lib/python3.10/logging/__init__.py", line 943, in format
    return fmt.format(record)
  File "/usr/lib/python3.10/logging/__init__.py", line 681, in format
    s = self.formatMessage(record)
  File "/usr/lib/python3.10/logging/__init__.py", line 650, in formatMessage
    return self._style.format(record)
  File "/usr/lib/python3.10/logging/__init__.py", line 442, in format
    raise ValueError('Formatting field not found in record: %s' % e)
ValueError: Formatting field not found in record: 'endpt'
Call stack:
  File "<string>", line 1, in <module>
  File "/usr/lib/python3.10/multiprocessing/spawn.py", line 116, in spawn_main
    exitcode = _main(fd, parent_sentinel)
  File "/usr/lib/python3.10/multiprocessing/spawn.py", line 129, in _main
    return self._bootstrap(parent_sentinel)
  File "/usr/lib/python3.10/multiprocessing/process.py", line 314, in _bootstrap
    self.run()
  File "/usr/lib/python3.10/multiprocessing/process.py", line 108, in run
    self._target(*self._args, **self._kwargs)
  File "/usr/lib/python3/dist-packages/uvicorn/subprocess.py", line 76, in subprocess_started
    target(sockets=sockets)
  File "/usr/lib/python3/dist-packages/uvicorn/server.py", line 68, in run
    return asyncio.run(self.serve(sockets=sockets))
  File "/usr/lib/python3.10/asyncio/runners.py", line 39, in run
    loop = events.new_event_loop()
  File "/usr/lib/python3.10/asyncio/events.py", line 783, in new_event_loop
    return get_event_loop_policy().new_event_loop()
  File "/usr/lib/python3.10/asyncio/events.py", line 673, in new_event_loop
    return self._loop_factory()
  File "/usr/lib/python3.10/asyncio/unix_events.py", line 64, in __init__
    super().__init__(selector)
  File "/usr/lib/python3.10/asyncio/selector_events.py", line 54, in __init__
    logger.debug('Using selector: %s', selector.__class__.__name__)
Message: 'Using selector: %s'
Arguments: ('EpollSelector',)
--- Logging error ---
Traceback (most recent call last):
  File "/usr/lib/python3.10/logging/__init__.py", line 440, in format
    return self._format(record)
  File "/usr/lib/python3.10/logging/__init__.py", line 436, in _format
    return self._fmt % values
KeyError: 'endpt'

During handling of the above exception, another exception occurred:

Traceback (most recent call last):
  File "/usr/lib/python3.10/logging/__init__.py", line 1100, in emit
    msg = self.format(record)
  File "/usr/lib/python3.10/logging/__init__.py", line 943, in format
    return fmt.format(record)
  File "/usr/lib/python3.10/logging/__init__.py", line 681, in format
    s = self.formatMessage(record)
  File "/usr/lib/python3.10/logging/__init__.py", line 650, in formatMessage
    return self._style.format(record)
  File "/usr/lib/python3.10/logging/__init__.py", line 442, in format
    raise ValueError('Formatting field not found in record: %s' % e)
ValueError: Formatting field not found in record: 'endpt'
Call stack:
  File "<string>", line 1, in <module>
  File "/usr/lib/python3.10/multiprocessing/spawn.py", line 116, in spawn_main
    exitcode = _main(fd, parent_sentinel)
  File "/usr/lib/python3.10/multiprocessing/spawn.py", line 129, in _main
    return self._bootstrap(parent_sentinel)
  File "/usr/lib/python3.10/multiprocessing/process.py", line 314, in _bootstrap
    self.run()
  File "/usr/lib/python3.10/multiprocessing/process.py", line 108, in run
    self._target(*self._args, **self._kwargs)
  File "/usr/lib/python3/dist-packages/uvicorn/subprocess.py", line 76, in subprocess_started
    target(sockets=sockets)
  File "/usr/lib/python3/dist-packages/uvicorn/server.py", line 68, in run
    return asyncio.run(self.serve(sockets=sockets))
  File "/usr/lib/python3.10/asyncio/runners.py", line 44, in run
    return loop.run_until_complete(main)
  File "/usr/lib/python3.10/asyncio/base_events.py", line 636, in run_until_complete
    self.run_forever()
  File "/usr/lib/python3.10/asyncio/base_events.py", line 603, in run_forever
    self._run_once()
  File "/usr/lib/python3.10/asyncio/base_events.py", line 1909, in _run_once
    handle._run()
  File "/usr/lib/python3.10/asyncio/events.py", line 80, in _run
    self._context.run(self._callback, *self._args)
  File "/usr/lib/python3/dist-packages/uvicorn/server.py", line 76, in serve
    config.load()
  File "/usr/lib/python3/dist-packages/uvicorn/config.py", line 448, in load
    self.loaded_app = import_from_string(self.app)
  File "/usr/lib/python3/dist-packages/uvicorn/importer.py", line 21, in import_from_string
    module = importlib.import_module(module_str)
  File "/usr/lib/python3.10/importlib/__init__.py", line 126, in import_module
    return _bootstrap._gcd_import(name[level:], package, level)
  File "<frozen importlib._bootstrap>", line 1050, in _gcd_import
  File "<frozen importlib._bootstrap>", line 1027, in _find_and_load
  File "<frozen importlib._bootstrap>", line 1006, in _find_and_load_unlocked
  File "<frozen importlib._bootstrap>", line 688, in _load_unlocked
  File "<frozen importlib._bootstrap_external>", line 883, in exec_module
  File "<frozen importlib._bootstrap>", line 241, in _call_with_frames_removed
  File "/mnt/e/cura/cura_backend/./main.py", line 4132, in <module>
    logger.info("program_started")
Message: 'program_started'
Arguments: ()
--- Logging error ---
Traceback (most recent call last):
  File "/usr/lib/python3.10/logging/__init__.py", line 440, in format
    return self._format(record)
  File "/usr/lib/python3.10/logging/__init__.py", line 436, in _format
    return self._fmt % values
KeyError: 'endpt'

During handling of the above exception, another exception occurred:

Traceback (most recent call last):
  File "/usr/lib/python3.10/logging/__init__.py", line 1100, in emit
    msg = self.format(record)
  File "/usr/lib/python3.10/logging/__init__.py", line 943, in format
    return fmt.format(record)
  File "/usr/lib/python3.10/logging/__init__.py", line 681, in format
    s = self.formatMessage(record)
  File "/usr/lib/python3.10/logging/__init__.py", line 650, in formatMessage
    return self._style.format(record)
  File "/usr/lib/python3.10/logging/__init__.py", line 442, in format
    raise ValueError('Formatting field not found in record: %s' % e)
ValueError: Formatting field not found in record: 'endpt'
Call stack:
  File "<string>", line 1, in <module>
  File "/usr/lib/python3.10/multiprocessing/spawn.py", line 116, in spawn_main
    exitcode = _main(fd, parent_sentinel)
  File "/usr/lib/python3.10/multiprocessing/spawn.py", line 129, in _main
    return self._bootstrap(parent_sentinel)
  File "/usr/lib/python3.10/multiprocessing/process.py", line 314, in _bootstrap
    self.run()
  File "/usr/lib/python3.10/multiprocessing/process.py", line 108, in run
    self._target(*self._args, **self._kwargs)
  File "/usr/lib/python3/dist-packages/uvicorn/subprocess.py", line 76, in subprocess_started
    target(sockets=sockets)
  File "/usr/lib/python3/dist-packages/uvicorn/server.py", line 68, in run
    return asyncio.run(self.serve(sockets=sockets))
  File "/usr/lib/python3.10/asyncio/runners.py", line 44, in run
    return loop.run_until_complete(main)
  File "/usr/lib/python3.10/asyncio/base_events.py", line 636, in run_until_complete
    self.run_forever()
  File "/usr/lib/python3.10/asyncio/base_events.py", line 603, in run_forever
    self._run_once()
  File "/usr/lib/python3.10/asyncio/base_events.py", line 1909, in _run_once
    handle._run()
  File "/usr/lib/python3.10/asyncio/events.py", line 80, in _run
    self._context.run(self._callback, *self._args)
  File "/usr/lib/python3/dist-packages/uvicorn/server.py", line 84, in serve
    logger.info(message, process_id, extra={"color_message": color_message})
Message: 'Started server process [%d]'
Arguments: (18332,)
--- Logging error ---
Traceback (most recent call last):
  File "/usr/lib/python3.10/logging/__init__.py", line 440, in format
    return self._format(record)
  File "/usr/lib/python3.10/logging/__init__.py", line 436, in _format
    return self._fmt % values
KeyError: 'endpt'

During handling of the above exception, another exception occurred:

Traceback (most recent call last):
  File "/usr/lib/python3.10/logging/__init__.py", line 1100, in emit
    msg = self.format(record)
  File "/usr/lib/python3.10/logging/__init__.py", line 943, in format
    return fmt.format(record)
  File "/usr/lib/python3.10/logging/__init__.py", line 681, in format
    s = self.formatMessage(record)
  File "/usr/lib/python3.10/logging/__init__.py", line 650, in formatMessage
    return self._style.format(record)
  File "/usr/lib/python3.10/logging/__init__.py", line 442, in format
    raise ValueError('Formatting field not found in record: %s' % e)
ValueError: Formatting field not found in record: 'endpt'
Call stack:
  File "<string>", line 1, in <module>
  File "/usr/lib/python3.10/multiprocessing/spawn.py", line 116, in spawn_main
    exitcode = _main(fd, parent_sentinel)
  File "/usr/lib/python3.10/multiprocessing/spawn.py", line 129, in _main
    return self._bootstrap(parent_sentinel)
  File "/usr/lib/python3.10/multiprocessing/process.py", line 314, in _bootstrap
    self.run()
  File "/usr/lib/python3.10/multiprocessing/process.py", line 108, in run
    self._target(*self._args, **self._kwargs)
  File "/usr/lib/python3/dist-packages/uvicorn/subprocess.py", line 76, in subprocess_started
    target(sockets=sockets)
  File "/usr/lib/python3/dist-packages/uvicorn/server.py", line 68, in run
    return asyncio.run(self.serve(sockets=sockets))
  File "/usr/lib/python3.10/asyncio/runners.py", line 44, in run
    return loop.run_until_complete(main)
  File "/usr/lib/python3.10/asyncio/base_events.py", line 636, in run_until_complete
    self.run_forever()
  File "/usr/lib/python3.10/asyncio/base_events.py", line 603, in run_forever
    self._run_once()
  File "/usr/lib/python3.10/asyncio/base_events.py", line 1909, in _run_once
    handle._run()
  File "/usr/lib/python3.10/asyncio/events.py", line 80, in _run
    self._context.run(self._callback, *self._args)
  File "/usr/lib/python3/dist-packages/uvicorn/server.py", line 86, in serve
    await self.startup(sockets=sockets)
  File "/usr/lib/python3/dist-packages/uvicorn/server.py", line 97, in startup
    await self.lifespan.startup()
  File "/usr/lib/python3/dist-packages/uvicorn/lifespan/on.py", line 45, in startup
    self.logger.info("Waiting for application startup.")
Message: 'Waiting for application startup.'
Arguments: ()
--- Logging error ---
Traceback (most recent call last):
  File "/usr/lib/python3.10/logging/__init__.py", line 440, in format
    return self._format(record)
  File "/usr/lib/python3.10/logging/__init__.py", line 436, in _format
    return self._fmt % values
KeyError: 'endpt'

During handling of the above exception, another exception occurred:

Traceback (most recent call last):
  File "/usr/lib/python3.10/logging/__init__.py", line 1100, in emit
    msg = self.format(record)
  File "/usr/lib/python3.10/logging/__init__.py", line 943, in format
    return fmt.format(record)
  File "/usr/lib/python3.10/logging/__init__.py", line 681, in format
    s = self.formatMessage(record)
  File "/usr/lib/python3.10/logging/__init__.py", line 650, in formatMessage
    return self._style.format(record)
  File "/usr/lib/python3.10/logging/__init__.py", line 442, in format
    raise ValueError('Formatting field not found in record: %s' % e)
ValueError: Formatting field not found in record: 'endpt'
Call stack:
  File "<string>", line 1, in <module>
  File "/usr/lib/python3.10/multiprocessing/spawn.py", line 116, in spawn_main
    exitcode = _main(fd, parent_sentinel)
  File "/usr/lib/python3.10/multiprocessing/spawn.py", line 129, in _main
    return self._bootstrap(parent_sentinel)
  File "/usr/lib/python3.10/multiprocessing/process.py", line 314, in _bootstrap
    self.run()
  File "/usr/lib/python3.10/multiprocessing/process.py", line 108, in run
    self._target(*self._args, **self._kwargs)
  File "/usr/lib/python3/dist-packages/uvicorn/subprocess.py", line 76, in subprocess_started
    target(sockets=sockets)
  File "/usr/lib/python3/dist-packages/uvicorn/server.py", line 68, in run
    return asyncio.run(self.serve(sockets=sockets))
  File "/usr/lib/python3.10/asyncio/runners.py", line 44, in run
    return loop.run_until_complete(main)
  File "/usr/lib/python3.10/asyncio/base_events.py", line 636, in run_until_complete
    self.run_forever()
  File "/usr/lib/python3.10/asyncio/base_events.py", line 603, in run_forever
    self._run_once()
  File "/usr/lib/python3.10/asyncio/base_events.py", line 1909, in _run_once
    handle._run()
  File "/usr/lib/python3.10/asyncio/events.py", line 80, in _run
    self._context.run(self._callback, *self._args)
  File "/usr/lib/python3/dist-packages/uvicorn/server.py", line 86, in serve
    await self.startup(sockets=sockets)
  File "/usr/lib/python3/dist-packages/uvicorn/server.py", line 97, in startup
    await self.lifespan.startup()
  File "/usr/lib/python3/dist-packages/uvicorn/lifespan/on.py", line 59, in startup
    self.logger.info("Application startup complete.")
Message: 'Application startup complete.'
Arguments: ()
--- Logging error ---
Traceback (most recent call last):
  File "/usr/lib/python3.10/logging/__init__.py", line 440, in format
    return self._format(record)
  File "/usr/lib/python3.10/logging/__init__.py", line 436, in _format
    return self._fmt % values
KeyError: 'endpt'

During handling of the above exception, another exception occurred:

Traceback (most recent call last):
  File "/usr/lib/python3.10/logging/__init__.py", line 1100, in emit
    msg = self.format(record)
  File "/usr/lib/python3.10/logging/__init__.py", line 943, in format
    return fmt.format(record)
  File "/usr/lib/python3.10/logging/__init__.py", line 681, in format
    s = self.formatMessage(record)
  File "/usr/lib/python3.10/logging/__init__.py", line 650, in formatMessage
    return self._style.format(record)
  File "/usr/lib/python3.10/logging/__init__.py", line 442, in format
    raise ValueError('Formatting field not found in record: %s' % e)
ValueError: Formatting field not found in record: 'endpt'
Call stack:
  File "<string>", line 1, in <module>
  File "/usr/lib/python3.10/multiprocessing/spawn.py", line 116, in spawn_main
    exitcode = _main(fd, parent_sentinel)
  File "/usr/lib/python3.10/multiprocessing/spawn.py", line 129, in _main
    return self._bootstrap(parent_sentinel)
  File "/usr/lib/python3.10/multiprocessing/process.py", line 314, in _bootstrap
    self.run()
  File "/usr/lib/python3.10/multiprocessing/process.py", line 108, in run
    self._target(*self._args, **self._kwargs)
  File "/usr/lib/python3/dist-packages/uvicorn/subprocess.py", line 76, in subprocess_started
    target(sockets=sockets)
  File "/usr/lib/python3/dist-packages/uvicorn/server.py", line 68, in run
    return asyncio.run(self.serve(sockets=sockets))
  File "/usr/lib/python3.10/asyncio/runners.py", line 44, in run
    return loop.run_until_complete(main)
  File "/usr/lib/python3.10/asyncio/base_events.py", line 636, in run_until_complete
    self.run_forever()
  File "/usr/lib/python3.10/asyncio/base_events.py", line 603, in run_forever
    self._run_once()
  File "/usr/lib/python3.10/asyncio/base_events.py", line 1909, in _run_once
    handle._run()
  File "/usr/lib/python3.10/asyncio/events.py", line 80, in _run
    self._context.run(self._callback, *self._args)
  File "/usr/lib/python3/dist-packages/uvicorn/protocols/http/h11_impl.py", line 373, in run_asgi
    result = await app(self.scope, self.receive, self.send)
  File "/usr/lib/python3/dist-packages/uvicorn/middleware/proxy_headers.py", line 75, in __call__
    return await self.app(scope, receive, send)
  File "/home/rudra/.local/lib/python3.10/site-packages/fastapi/applications.py", line 1054, in __call__
    await super().__call__(scope, receive, send)
  File "/home/rudra/.local/lib/python3.10/site-packages/starlette/applications.py", line 123, in __call__
    await self.middleware_stack(scope, receive, send)
  File "/home/rudra/.local/lib/python3.10/site-packages/starlette/middleware/errors.py", line 164, in __call__
    await self.app(scope, receive, _send)
  File "/home/rudra/.local/lib/python3.10/site-packages/starlette/middleware/cors.py", line 93, in __call__
    await self.simple_response(scope, receive, send, request_headers=headers)
  File "/home/rudra/.local/lib/python3.10/site-packages/starlette/middleware/cors.py", line 148, in simple_response
    await self.app(scope, receive, send)
  File "/home/rudra/.local/lib/python3.10/site-packages/starlette/middleware/exceptions.py", line 65, in __call__
    await wrap_app_handling_exceptions(self.app, conn)(scope, receive, send)
  File "/home/rudra/.local/lib/python3.10/site-packages/starlette/_exception_handler.py", line 53, in wrapped_app
    await app(scope, receive, sender)
  File "/home/rudra/.local/lib/python3.10/site-packages/starlette/routing.py", line 756, in __call__
    await self.middleware_stack(scope, receive, send)
  File "/home/rudra/.local/lib/python3.10/site-packages/starlette/routing.py", line 776, in app
    await route.handle(scope, receive, send)
  File "/home/rudra/.local/lib/python3.10/site-packages/starlette/routing.py", line 297, in handle
    await self.app(scope, receive, send)
  File "/home/rudra/.local/lib/python3.10/site-packages/starlette/routing.py", line 77, in app
    await wrap_app_handling_exceptions(app, request)(scope, receive, send)
  File "/home/rudra/.local/lib/python3.10/site-packages/starlette/_exception_handler.py", line 53, in wrapped_app
    await app(scope, receive, sender)
  File "/home/rudra/.local/lib/python3.10/site-packages/starlette/routing.py", line 72, in app
    response = await func(request)
  File "/home/rudra/.local/lib/python3.10/site-packages/fastapi/routing.py", line 278, in app
    raw_response = await run_endpoint_function(
  File "/home/rudra/.local/lib/python3.10/site-packages/fastapi/routing.py", line 191, in run_endpoint_function
    return await dependant.call(**values)
  File "/mnt/e/cura/cura_backend/./main.py", line 1866, in get_users_admin
    logging.info(f'get_users_admin:payload received is {payload}')
Message: "get_users_admin:payload received is {'user_id': 1234}"
Arguments: ()
2024-04-30 17:53:07,275 - uvicorn.access - send - INFO - 127.0.0.1:60370 - "POST /getUsersAdmin HTTP/1.1" 200
--- Logging error ---
Traceback (most recent call last):
  File "/usr/lib/python3.10/logging/__init__.py", line 440, in format
    return self._format(record)
  File "/usr/lib/python3.10/logging/__init__.py", line 436, in _format
    return self._fmt % values
KeyError: 'funcname'

During handling of the above exception, another exception occurred:

Traceback (most recent call last):
  File "/usr/lib/python3.10/logging/__init__.py", line 1100, in emit
    msg = self.format(record)
  File "/usr/lib/python3.10/logging/__init__.py", line 943, in format
    return fmt.format(record)
  File "/usr/lib/python3.10/logging/__init__.py", line 681, in format
    s = self.formatMessage(record)
  File "/usr/lib/python3.10/logging/__init__.py", line 650, in formatMessage
    return self._style.format(record)
  File "/usr/lib/python3.10/logging/__init__.py", line 442, in format
    raise ValueError('Formatting field not found in record: %s' % e)
ValueError: Formatting field not found in record: 'funcname'
Call stack:
  File "/usr/bin/uvicorn", line 33, in <module>
    sys.exit(load_entry_point('uvicorn==0.15.0', 'console_scripts', 'uvicorn')())
  File "/usr/lib/python3/dist-packages/click/core.py", line 1128, in __call__
    return self.main(*args, **kwargs)
  File "/usr/lib/python3/dist-packages/click/core.py", line 1053, in main
    rv = self.invoke(ctx)
  File "/usr/lib/python3/dist-packages/click/core.py", line 1395, in invoke
    return ctx.invoke(self.callback, **ctx.params)
  File "/usr/lib/python3/dist-packages/click/core.py", line 754, in invoke
    return __callback(*args, **kwargs)
  File "/usr/lib/python3/dist-packages/uvicorn/main.py", line 425, in main
    run(app, **kwargs)
  File "/usr/lib/python3/dist-packages/uvicorn/main.py", line 442, in run
    ChangeReload(config, target=server.run, sockets=[sock]).run()
  File "/usr/lib/python3/dist-packages/uvicorn/supervisors/basereload.py", line 45, in run
    if self.should_restart():
  File "/usr/lib/python3/dist-packages/uvicorn/supervisors/statreload.py", line 41, in should_restart
    logger.warning(message, display_path)
Message: "StatReload detected file change in '%s'. Reloading..."
Arguments: ('main.py',)
--- Logging error ---
Traceback (most recent call last):
  File "/usr/lib/python3.10/logging/__init__.py", line 440, in format
    return self._format(record)
  File "/usr/lib/python3.10/logging/__init__.py", line 436, in _format
    return self._fmt % values
KeyError: 'endpt'

During handling of the above exception, another exception occurred:

Traceback (most recent call last):
  File "/usr/lib/python3.10/logging/__init__.py", line 1100, in emit
    msg = self.format(record)
  File "/usr/lib/python3.10/logging/__init__.py", line 943, in format
    return fmt.format(record)
  File "/usr/lib/python3.10/logging/__init__.py", line 681, in format
    s = self.formatMessage(record)
  File "/usr/lib/python3.10/logging/__init__.py", line 650, in formatMessage
    return self._style.format(record)
  File "/usr/lib/python3.10/logging/__init__.py", line 442, in format
    raise ValueError('Formatting field not found in record: %s' % e)
ValueError: Formatting field not found in record: 'endpt'
Call stack:
  File "<string>", line 1, in <module>
  File "/usr/lib/python3.10/multiprocessing/spawn.py", line 116, in spawn_main
    exitcode = _main(fd, parent_sentinel)
  File "/usr/lib/python3.10/multiprocessing/spawn.py", line 129, in _main
    return self._bootstrap(parent_sentinel)
  File "/usr/lib/python3.10/multiprocessing/process.py", line 314, in _bootstrap
    self.run()
  File "/usr/lib/python3.10/multiprocessing/process.py", line 108, in run
    self._target(*self._args, **self._kwargs)
  File "/usr/lib/python3/dist-packages/uvicorn/subprocess.py", line 76, in subprocess_started
    target(sockets=sockets)
  File "/usr/lib/python3/dist-packages/uvicorn/server.py", line 68, in run
    return asyncio.run(self.serve(sockets=sockets))
  File "/usr/lib/python3.10/asyncio/runners.py", line 44, in run
    return loop.run_until_complete(main)
  File "/usr/lib/python3.10/asyncio/base_events.py", line 636, in run_until_complete
    self.run_forever()
  File "/usr/lib/python3.10/asyncio/base_events.py", line 603, in run_forever
    self._run_once()
  File "/usr/lib/python3.10/asyncio/base_events.py", line 1909, in _run_once
    handle._run()
  File "/usr/lib/python3.10/asyncio/events.py", line 80, in _run
    self._context.run(self._callback, *self._args)
  File "/usr/lib/python3/dist-packages/uvicorn/server.py", line 90, in serve
    await self.shutdown(sockets=sockets)
  File "/usr/lib/python3/dist-packages/uvicorn/server.py", line 263, in shutdown
    logger.info("Shutting down")
Message: 'Shutting down'
Arguments: ()
--- Logging error ---
Traceback (most recent call last):
  File "/usr/lib/python3.10/logging/__init__.py", line 440, in format
    return self._format(record)
  File "/usr/lib/python3.10/logging/__init__.py", line 436, in _format
    return self._fmt % values
KeyError: 'endpt'

During handling of the above exception, another exception occurred:

Traceback (most recent call last):
  File "/usr/lib/python3.10/logging/__init__.py", line 1100, in emit
    msg = self.format(record)
  File "/usr/lib/python3.10/logging/__init__.py", line 943, in format
    return fmt.format(record)
  File "/usr/lib/python3.10/logging/__init__.py", line 681, in format
    s = self.formatMessage(record)
  File "/usr/lib/python3.10/logging/__init__.py", line 650, in formatMessage
    return self._style.format(record)
  File "/usr/lib/python3.10/logging/__init__.py", line 442, in format
    raise ValueError('Formatting field not found in record: %s' % e)
ValueError: Formatting field not found in record: 'endpt'
Call stack:
  File "<string>", line 1, in <module>
  File "/usr/lib/python3.10/multiprocessing/spawn.py", line 116, in spawn_main
    exitcode = _main(fd, parent_sentinel)
  File "/usr/lib/python3.10/multiprocessing/spawn.py", line 129, in _main
    return self._bootstrap(parent_sentinel)
  File "/usr/lib/python3.10/multiprocessing/process.py", line 314, in _bootstrap
    self.run()
  File "/usr/lib/python3.10/multiprocessing/process.py", line 108, in run
    self._target(*self._args, **self._kwargs)
  File "/usr/lib/python3/dist-packages/uvicorn/subprocess.py", line 76, in subprocess_started
    target(sockets=sockets)
  File "/usr/lib/python3/dist-packages/uvicorn/server.py", line 68, in run
    return asyncio.run(self.serve(sockets=sockets))
  File "/usr/lib/python3.10/asyncio/runners.py", line 44, in run
    return loop.run_until_complete(main)
  File "/usr/lib/python3.10/asyncio/base_events.py", line 636, in run_until_complete
    self.run_forever()
  File "/usr/lib/python3.10/asyncio/base_events.py", line 603, in run_forever
    self._run_once()
  File "/usr/lib/python3.10/asyncio/base_events.py", line 1909, in _run_once
    handle._run()
  File "/usr/lib/python3.10/asyncio/events.py", line 80, in _run
    self._context.run(self._callback, *self._args)
  File "/usr/lib/python3/dist-packages/uvicorn/server.py", line 90, in serve
    await self.shutdown(sockets=sockets)
  File "/usr/lib/python3/dist-packages/uvicorn/server.py", line 294, in shutdown
    await self.lifespan.shutdown()
  File "/usr/lib/python3/dist-packages/uvicorn/lifespan/on.py", line 64, in shutdown
    self.logger.info("Waiting for application shutdown.")
Message: 'Waiting for application shutdown.'
Arguments: ()
--- Logging error ---
Traceback (most recent call last):
  File "/usr/lib/python3.10/logging/__init__.py", line 440, in format
    return self._format(record)
  File "/usr/lib/python3.10/logging/__init__.py", line 436, in _format
    return self._fmt % values
KeyError: 'endpt'

During handling of the above exception, another exception occurred:

Traceback (most recent call last):
  File "/usr/lib/python3.10/logging/__init__.py", line 1100, in emit
    msg = self.format(record)
  File "/usr/lib/python3.10/logging/__init__.py", line 943, in format
    return fmt.format(record)
  File "/usr/lib/python3.10/logging/__init__.py", line 681, in format
    s = self.formatMessage(record)
  File "/usr/lib/python3.10/logging/__init__.py", line 650, in formatMessage
    return self._style.format(record)
  File "/usr/lib/python3.10/logging/__init__.py", line 442, in format
    raise ValueError('Formatting field not found in record: %s' % e)
ValueError: Formatting field not found in record: 'endpt'
Call stack:
  File "<string>", line 1, in <module>
  File "/usr/lib/python3.10/multiprocessing/spawn.py", line 116, in spawn_main
    exitcode = _main(fd, parent_sentinel)
  File "/usr/lib/python3.10/multiprocessing/spawn.py", line 129, in _main
    return self._bootstrap(parent_sentinel)
  File "/usr/lib/python3.10/multiprocessing/process.py", line 314, in _bootstrap
    self.run()
  File "/usr/lib/python3.10/multiprocessing/process.py", line 108, in run
    self._target(*self._args, **self._kwargs)
  File "/usr/lib/python3/dist-packages/uvicorn/subprocess.py", line 76, in subprocess_started
    target(sockets=sockets)
  File "/usr/lib/python3/dist-packages/uvicorn/server.py", line 68, in run
    return asyncio.run(self.serve(sockets=sockets))
  File "/usr/lib/python3.10/asyncio/runners.py", line 44, in run
    return loop.run_until_complete(main)
  File "/usr/lib/python3.10/asyncio/base_events.py", line 636, in run_until_complete
    self.run_forever()
  File "/usr/lib/python3.10/asyncio/base_events.py", line 603, in run_forever
    self._run_once()
  File "/usr/lib/python3.10/asyncio/base_events.py", line 1909, in _run_once
    handle._run()
  File "/usr/lib/python3.10/asyncio/events.py", line 80, in _run
    self._context.run(self._callback, *self._args)
  File "/usr/lib/python3/dist-packages/uvicorn/server.py", line 90, in serve
    await self.shutdown(sockets=sockets)
  File "/usr/lib/python3/dist-packages/uvicorn/server.py", line 294, in shutdown
    await self.lifespan.shutdown()
  File "/usr/lib/python3/dist-packages/uvicorn/lifespan/on.py", line 75, in shutdown
    self.logger.info("Application shutdown complete.")
Message: 'Application shutdown complete.'
Arguments: ()
--- Logging error ---
Traceback (most recent call last):
  File "/usr/lib/python3.10/logging/__init__.py", line 440, in format
    return self._format(record)
  File "/usr/lib/python3.10/logging/__init__.py", line 436, in _format
    return self._fmt % values
KeyError: 'endpt'

During handling of the above exception, another exception occurred:

Traceback (most recent call last):
  File "/usr/lib/python3.10/logging/__init__.py", line 1100, in emit
    msg = self.format(record)
  File "/usr/lib/python3.10/logging/__init__.py", line 943, in format
    return fmt.format(record)
  File "/usr/lib/python3.10/logging/__init__.py", line 681, in format
    s = self.formatMessage(record)
  File "/usr/lib/python3.10/logging/__init__.py", line 650, in formatMessage
    return self._style.format(record)
  File "/usr/lib/python3.10/logging/__init__.py", line 442, in format
    raise ValueError('Formatting field not found in record: %s' % e)
ValueError: Formatting field not found in record: 'endpt'
Call stack:
  File "<string>", line 1, in <module>
  File "/usr/lib/python3.10/multiprocessing/spawn.py", line 116, in spawn_main
    exitcode = _main(fd, parent_sentinel)
  File "/usr/lib/python3.10/multiprocessing/spawn.py", line 129, in _main
    return self._bootstrap(parent_sentinel)
  File "/usr/lib/python3.10/multiprocessing/process.py", line 314, in _bootstrap
    self.run()
  File "/usr/lib/python3.10/multiprocessing/process.py", line 108, in run
    self._target(*self._args, **self._kwargs)
  File "/usr/lib/python3/dist-packages/uvicorn/subprocess.py", line 76, in subprocess_started
    target(sockets=sockets)
  File "/usr/lib/python3/dist-packages/uvicorn/server.py", line 68, in run
    return asyncio.run(self.serve(sockets=sockets))
  File "/usr/lib/python3.10/asyncio/runners.py", line 44, in run
    return loop.run_until_complete(main)
  File "/usr/lib/python3.10/asyncio/base_events.py", line 636, in run_until_complete
    self.run_forever()
  File "/usr/lib/python3.10/asyncio/base_events.py", line 603, in run_forever
    self._run_once()
  File "/usr/lib/python3.10/asyncio/base_events.py", line 1909, in _run_once
    handle._run()
  File "/usr/lib/python3.10/asyncio/events.py", line 80, in _run
    self._context.run(self._callback, *self._args)
  File "/usr/lib/python3/dist-packages/uvicorn/server.py", line 94, in serve
    logger.info(message, process_id, extra={"color_message": color_message})
Message: 'Finished server process [%d]'
Arguments: (18332,)
2024-04-30 17:53:27,344 - asyncio - DEBUG - Using selector: EpollSelector
Process SpawnProcess-27:
Traceback (most recent call last):
  File "/usr/lib/python3.10/multiprocessing/process.py", line 314, in _bootstrap
    self.run()
  File "/usr/lib/python3.10/multiprocessing/process.py", line 108, in run
    self._target(*self._args, **self._kwargs)
  File "/usr/lib/python3/dist-packages/uvicorn/subprocess.py", line 76, in subprocess_started
    target(sockets=sockets)
  File "/usr/lib/python3/dist-packages/uvicorn/server.py", line 68, in run
    return asyncio.run(self.serve(sockets=sockets))
  File "/usr/lib/python3.10/asyncio/runners.py", line 44, in run
    return loop.run_until_complete(main)
  File "/usr/lib/python3.10/asyncio/base_events.py", line 649, in run_until_complete
    return future.result()
  File "/usr/lib/python3/dist-packages/uvicorn/server.py", line 76, in serve
    config.load()
  File "/usr/lib/python3/dist-packages/uvicorn/config.py", line 448, in load
    self.loaded_app = import_from_string(self.app)
  File "/usr/lib/python3/dist-packages/uvicorn/importer.py", line 24, in import_from_string
    raise exc from None
  File "/usr/lib/python3/dist-packages/uvicorn/importer.py", line 21, in import_from_string
    module = importlib.import_module(module_str)
  File "/usr/lib/python3.10/importlib/__init__.py", line 126, in import_module
    return _bootstrap._gcd_import(name[level:], package, level)
  File "<frozen importlib._bootstrap>", line 1050, in _gcd_import
  File "<frozen importlib._bootstrap>", line 1027, in _find_and_load
  File "<frozen importlib._bootstrap>", line 1006, in _find_and_load_unlocked
  File "<frozen importlib._bootstrap>", line 688, in _load_unlocked
  File "<frozen importlib._bootstrap_external>", line 883, in exec_module
  File "<frozen importlib._bootstrap>", line 241, in _call_with_frames_removed
  File "/mnt/e/cura/cura_backend/./main.py", line 3, in <module>
    from fastapi import FsstAPI, HTTPException, Depends, Query
ImportError: cannot import name 'FsstAPI' from 'fastapi' (/home/rudra/.local/lib/python3.10/site-packages/fastapi/__init__.py)
--- Logging error ---
Traceback (most recent call last):
  File "/usr/lib/python3.10/logging/__init__.py", line 440, in format
    return self._format(record)
  File "/usr/lib/python3.10/logging/__init__.py", line 436, in _format
    return self._fmt % values
KeyError: 'funcname'

During handling of the above exception, another exception occurred:

Traceback (most recent call last):
  File "/usr/lib/python3.10/logging/__init__.py", line 1100, in emit
    msg = self.format(record)
  File "/usr/lib/python3.10/logging/__init__.py", line 943, in format
    return fmt.format(record)
  File "/usr/lib/python3.10/logging/__init__.py", line 681, in format
    s = self.formatMessage(record)
  File "/usr/lib/python3.10/logging/__init__.py", line 650, in formatMessage
    return self._style.format(record)
  File "/usr/lib/python3.10/logging/__init__.py", line 442, in format
    raise ValueError('Formatting field not found in record: %s' % e)
ValueError: Formatting field not found in record: 'funcname'
Call stack:
  File "/usr/bin/uvicorn", line 33, in <module>
    sys.exit(load_entry_point('uvicorn==0.15.0', 'console_scripts', 'uvicorn')())
  File "/usr/lib/python3/dist-packages/click/core.py", line 1128, in __call__
    return self.main(*args, **kwargs)
  File "/usr/lib/python3/dist-packages/click/core.py", line 1053, in main
    rv = self.invoke(ctx)
  File "/usr/lib/python3/dist-packages/click/core.py", line 1395, in invoke
    return ctx.invoke(self.callback, **ctx.params)
  File "/usr/lib/python3/dist-packages/click/core.py", line 754, in invoke
    return __callback(*args, **kwargs)
  File "/usr/lib/python3/dist-packages/uvicorn/main.py", line 425, in main
    run(app, **kwargs)
  File "/usr/lib/python3/dist-packages/uvicorn/main.py", line 442, in run
    ChangeReload(config, target=server.run, sockets=[sock]).run()
  File "/usr/lib/python3/dist-packages/uvicorn/supervisors/basereload.py", line 45, in run
    if self.should_restart():
  File "/usr/lib/python3/dist-packages/uvicorn/supervisors/statreload.py", line 41, in should_restart
    logger.warning(message, display_path)
Message: "StatReload detected file change in '%s'. Reloading..."
Arguments: ('main.py',)
2024-04-30 17:53:32,960 - asyncio - DEBUG - Using selector: EpollSelector
2024-04-30 17:53:33,546 - main - INFO - program_started
2024-04-30 17:53:33,546 - uvicorn.error - INFO - Started server process [18442]
2024-04-30 17:53:33,547 - uvicorn.error - INFO - Waiting for application startup.
2024-04-30 17:53:33,547 - uvicorn.error - INFO - Application startup complete.
--- Logging error ---
Traceback (most recent call last):
  File "/usr/lib/python3.10/logging/__init__.py", line 440, in format
    return self._format(record)
  File "/usr/lib/python3.10/logging/__init__.py", line 436, in _format
    return self._fmt % values
KeyError: 'funcname'

During handling of the above exception, another exception occurred:

Traceback (most recent call last):
  File "/usr/lib/python3.10/logging/__init__.py", line 1100, in emit
    msg = self.format(record)
  File "/usr/lib/python3.10/logging/__init__.py", line 943, in format
    return fmt.format(record)
  File "/usr/lib/python3.10/logging/__init__.py", line 681, in format
    s = self.formatMessage(record)
  File "/usr/lib/python3.10/logging/__init__.py", line 650, in formatMessage
    return self._style.format(record)
  File "/usr/lib/python3.10/logging/__init__.py", line 442, in format
    raise ValueError('Formatting field not found in record: %s' % e)
ValueError: Formatting field not found in record: 'funcname'
Call stack:
  File "/usr/bin/uvicorn", line 33, in <module>
    sys.exit(load_entry_point('uvicorn==0.15.0', 'console_scripts', 'uvicorn')())
  File "/usr/lib/python3/dist-packages/click/core.py", line 1128, in __call__
    return self.main(*args, **kwargs)
  File "/usr/lib/python3/dist-packages/click/core.py", line 1053, in main
    rv = self.invoke(ctx)
  File "/usr/lib/python3/dist-packages/click/core.py", line 1395, in invoke
    return ctx.invoke(self.callback, **ctx.params)
  File "/usr/lib/python3/dist-packages/click/core.py", line 754, in invoke
    return __callback(*args, **kwargs)
  File "/usr/lib/python3/dist-packages/uvicorn/main.py", line 425, in main
    run(app, **kwargs)
  File "/usr/lib/python3/dist-packages/uvicorn/main.py", line 442, in run
    ChangeReload(config, target=server.run, sockets=[sock]).run()
  File "/usr/lib/python3/dist-packages/uvicorn/supervisors/basereload.py", line 45, in run
    if self.should_restart():
  File "/usr/lib/python3/dist-packages/uvicorn/supervisors/statreload.py", line 41, in should_restart
    logger.warning(message, display_path)
Message: "StatReload detected file change in '%s'. Reloading..."
Arguments: ('main.py',)
2024-04-30 17:53:42,474 - uvicorn.error - INFO - Shutting down
2024-04-30 17:53:42,575 - uvicorn.error - INFO - Waiting for application shutdown.
2024-04-30 17:53:42,575 - uvicorn.error - INFO - Application shutdown complete.
2024-04-30 17:53:42,575 - uvicorn.error - INFO - Finished server process [18442]
2024-04-30 17:53:42,750 - asyncio - DEBUG - Using selector: EpollSelector
2024-04-30 17:53:43,364 - main - INFO - program_started
2024-04-30 17:53:43,365 - uvicorn.error - INFO - Started server process [18482]
2024-04-30 17:53:43,365 - uvicorn.error - INFO - Waiting for application startup.
2024-04-30 17:53:43,365 - uvicorn.error - INFO - Application startup complete.
--- Logging error ---
Traceback (most recent call last):
  File "/usr/lib/python3.10/logging/__init__.py", line 440, in format
    return self._format(record)
  File "/usr/lib/python3.10/logging/__init__.py", line 436, in _format
    return self._fmt % values
KeyError: 'funcname'

During handling of the above exception, another exception occurred:

Traceback (most recent call last):
  File "/usr/lib/python3.10/logging/__init__.py", line 1100, in emit
    msg = self.format(record)
  File "/usr/lib/python3.10/logging/__init__.py", line 943, in format
    return fmt.format(record)
  File "/usr/lib/python3.10/logging/__init__.py", line 681, in format
    s = self.formatMessage(record)
  File "/usr/lib/python3.10/logging/__init__.py", line 650, in formatMessage
    return self._style.format(record)
  File "/usr/lib/python3.10/logging/__init__.py", line 442, in format
    raise ValueError('Formatting field not found in record: %s' % e)
ValueError: Formatting field not found in record: 'funcname'
Call stack:
  File "/usr/bin/uvicorn", line 33, in <module>
    sys.exit(load_entry_point('uvicorn==0.15.0', 'console_scripts', 'uvicorn')())
  File "/usr/lib/python3/dist-packages/click/core.py", line 1128, in __call__
    return self.main(*args, **kwargs)
  File "/usr/lib/python3/dist-packages/click/core.py", line 1053, in main
    rv = self.invoke(ctx)
  File "/usr/lib/python3/dist-packages/click/core.py", line 1395, in invoke
    return ctx.invoke(self.callback, **ctx.params)
  File "/usr/lib/python3/dist-packages/click/core.py", line 754, in invoke
    return __callback(*args, **kwargs)
  File "/usr/lib/python3/dist-packages/uvicorn/main.py", line 425, in main
    run(app, **kwargs)
  File "/usr/lib/python3/dist-packages/uvicorn/main.py", line 442, in run
    ChangeReload(config, target=server.run, sockets=[sock]).run()
  File "/usr/lib/python3/dist-packages/uvicorn/supervisors/basereload.py", line 45, in run
    if self.should_restart():
  File "/usr/lib/python3/dist-packages/uvicorn/supervisors/statreload.py", line 41, in should_restart
    logger.warning(message, display_path)
Message: "StatReload detected file change in '%s'. Reloading..."
Arguments: ('main.py',)
2024-04-30 17:53:54,598 - uvicorn.error - INFO - Shutting down
2024-04-30 17:53:54,699 - uvicorn.error - INFO - Waiting for application shutdown.
2024-04-30 17:53:54,699 - uvicorn.error - INFO - Application shutdown complete.
2024-04-30 17:53:54,700 - uvicorn.error - INFO - Finished server process [18482]
2024-04-30 17:53:54,865 - asyncio - DEBUG - Using selector: EpollSelector
2024-04-30 17:53:55,475 - main - INFO - program_started
2024-04-30 17:53:55,476 - uvicorn.error - INFO - Started server process [18530]
2024-04-30 17:53:55,476 - uvicorn.error - INFO - Waiting for application startup.
2024-04-30 17:53:55,476 - uvicorn.error - INFO - Application startup complete.
--- Logging error ---
Traceback (most recent call last):
  File "/usr/lib/python3.10/logging/__init__.py", line 440, in format
    return self._format(record)
  File "/usr/lib/python3.10/logging/__init__.py", line 436, in _format
    return self._fmt % values
KeyError: 'funcname'

During handling of the above exception, another exception occurred:

Traceback (most recent call last):
  File "/usr/lib/python3.10/logging/__init__.py", line 1100, in emit
    msg = self.format(record)
  File "/usr/lib/python3.10/logging/__init__.py", line 943, in format
    return fmt.format(record)
  File "/usr/lib/python3.10/logging/__init__.py", line 681, in format
    s = self.formatMessage(record)
  File "/usr/lib/python3.10/logging/__init__.py", line 650, in formatMessage
    return self._style.format(record)
  File "/usr/lib/python3.10/logging/__init__.py", line 442, in format
    raise ValueError('Formatting field not found in record: %s' % e)
ValueError: Formatting field not found in record: 'funcname'
Call stack:
  File "/usr/bin/uvicorn", line 33, in <module>
    sys.exit(load_entry_point('uvicorn==0.15.0', 'console_scripts', 'uvicorn')())
  File "/usr/lib/python3/dist-packages/click/core.py", line 1128, in __call__
    return self.main(*args, **kwargs)
  File "/usr/lib/python3/dist-packages/click/core.py", line 1053, in main
    rv = self.invoke(ctx)
  File "/usr/lib/python3/dist-packages/click/core.py", line 1395, in invoke
    return ctx.invoke(self.callback, **ctx.params)
  File "/usr/lib/python3/dist-packages/click/core.py", line 754, in invoke
    return __callback(*args, **kwargs)
  File "/usr/lib/python3/dist-packages/uvicorn/main.py", line 425, in main
    run(app, **kwargs)
  File "/usr/lib/python3/dist-packages/uvicorn/main.py", line 442, in run
    ChangeReload(config, target=server.run, sockets=[sock]).run()
  File "/usr/lib/python3/dist-packages/uvicorn/supervisors/basereload.py", line 45, in run
    if self.should_restart():
  File "/usr/lib/python3/dist-packages/uvicorn/supervisors/statreload.py", line 41, in should_restart
    logger.warning(message, display_path)
Message: "StatReload detected file change in '%s'. Reloading..."
Arguments: ('main.py',)
2024-04-30 17:57:36,703 - uvicorn.error - INFO - Shutting down
2024-04-30 17:57:36,804 - uvicorn.error - INFO - Waiting for application shutdown.
2024-04-30 17:57:36,804 - uvicorn.error - INFO - Application shutdown complete.
2024-04-30 17:57:36,804 - uvicorn.error - INFO - Finished server process [18530]
2024-04-30 17:57:37,008 - asyncio - DEBUG - Using selector: EpollSelector
2024-04-30 17:57:37,599 - main - INFO - program_started
2024-04-30 17:57:37,599 - uvicorn.error - INFO - Started server process [19414]
2024-04-30 17:57:37,600 - uvicorn.error - INFO - Waiting for application startup.
2024-04-30 17:57:37,600 - uvicorn.error - INFO - Application startup complete.
--- Logging error ---
Traceback (most recent call last):
  File "/usr/lib/python3.10/logging/__init__.py", line 440, in format
    return self._format(record)
  File "/usr/lib/python3.10/logging/__init__.py", line 436, in _format
    return self._fmt % values
KeyError: 'funcname'

During handling of the above exception, another exception occurred:

Traceback (most recent call last):
  File "/usr/lib/python3.10/logging/__init__.py", line 1100, in emit
    msg = self.format(record)
  File "/usr/lib/python3.10/logging/__init__.py", line 943, in format
    return fmt.format(record)
  File "/usr/lib/python3.10/logging/__init__.py", line 681, in format
    s = self.formatMessage(record)
  File "/usr/lib/python3.10/logging/__init__.py", line 650, in formatMessage
    return self._style.format(record)
  File "/usr/lib/python3.10/logging/__init__.py", line 442, in format
    raise ValueError('Formatting field not found in record: %s' % e)
ValueError: Formatting field not found in record: 'funcname'
Call stack:
  File "/usr/bin/uvicorn", line 33, in <module>
    sys.exit(load_entry_point('uvicorn==0.15.0', 'console_scripts', 'uvicorn')())
  File "/usr/lib/python3/dist-packages/click/core.py", line 1128, in __call__
    return self.main(*args, **kwargs)
  File "/usr/lib/python3/dist-packages/click/core.py", line 1053, in main
    rv = self.invoke(ctx)
  File "/usr/lib/python3/dist-packages/click/core.py", line 1395, in invoke
    return ctx.invoke(self.callback, **ctx.params)
  File "/usr/lib/python3/dist-packages/click/core.py", line 754, in invoke
    return __callback(*args, **kwargs)
  File "/usr/lib/python3/dist-packages/uvicorn/main.py", line 425, in main
    run(app, **kwargs)
  File "/usr/lib/python3/dist-packages/uvicorn/main.py", line 442, in run
    ChangeReload(config, target=server.run, sockets=[sock]).run()
  File "/usr/lib/python3/dist-packages/uvicorn/supervisors/basereload.py", line 45, in run
    if self.should_restart():
  File "/usr/lib/python3/dist-packages/uvicorn/supervisors/statreload.py", line 41, in should_restart
    logger.warning(message, display_path)
Message: "StatReload detected file change in '%s'. Reloading..."
Arguments: ('main.py',)
2024-04-30 17:57:50,840 - uvicorn.error - INFO - Shutting down
2024-04-30 17:57:50,940 - uvicorn.error - INFO - Waiting for application shutdown.
2024-04-30 17:57:50,941 - uvicorn.error - INFO - Application shutdown complete.
2024-04-30 17:57:50,941 - uvicorn.error - INFO - Finished server process [19414]
2024-04-30 17:57:51,136 - asyncio - DEBUG - Using selector: EpollSelector
2024-04-30 17:57:51,793 - main - INFO - program_started
2024-04-30 17:57:51,794 - uvicorn.error - INFO - Started server process [19471]
2024-04-30 17:57:51,795 - uvicorn.error - INFO - Waiting for application startup.
2024-04-30 17:57:51,795 - uvicorn.error - INFO - Application startup complete.
--- Logging error ---
Traceback (most recent call last):
  File "/usr/lib/python3.10/logging/__init__.py", line 440, in format
    return self._format(record)
  File "/usr/lib/python3.10/logging/__init__.py", line 436, in _format
    return self._fmt % values
KeyError: 'funcname'

During handling of the above exception, another exception occurred:

Traceback (most recent call last):
  File "/usr/lib/python3.10/logging/__init__.py", line 1100, in emit
    msg = self.format(record)
  File "/usr/lib/python3.10/logging/__init__.py", line 943, in format
    return fmt.format(record)
  File "/usr/lib/python3.10/logging/__init__.py", line 681, in format
    s = self.formatMessage(record)
  File "/usr/lib/python3.10/logging/__init__.py", line 650, in formatMessage
    return self._style.format(record)
  File "/usr/lib/python3.10/logging/__init__.py", line 442, in format
    raise ValueError('Formatting field not found in record: %s' % e)
ValueError: Formatting field not found in record: 'funcname'
Call stack:
  File "/usr/bin/uvicorn", line 33, in <module>
    sys.exit(load_entry_point('uvicorn==0.15.0', 'console_scripts', 'uvicorn')())
  File "/usr/lib/python3/dist-packages/click/core.py", line 1128, in __call__
    return self.main(*args, **kwargs)
  File "/usr/lib/python3/dist-packages/click/core.py", line 1053, in main
    rv = self.invoke(ctx)
  File "/usr/lib/python3/dist-packages/click/core.py", line 1395, in invoke
    return ctx.invoke(self.callback, **ctx.params)
  File "/usr/lib/python3/dist-packages/click/core.py", line 754, in invoke
    return __callback(*args, **kwargs)
  File "/usr/lib/python3/dist-packages/uvicorn/main.py", line 425, in main
    run(app, **kwargs)
  File "/usr/lib/python3/dist-packages/uvicorn/main.py", line 442, in run
    ChangeReload(config, target=server.run, sockets=[sock]).run()
  File "/usr/lib/python3/dist-packages/uvicorn/supervisors/basereload.py", line 45, in run
    if self.should_restart():
  File "/usr/lib/python3/dist-packages/uvicorn/supervisors/statreload.py", line 41, in should_restart
    logger.warning(message, display_path)
Message: "StatReload detected file change in '%s'. Reloading..."
Arguments: ('main.py',)
2024-04-30 17:58:19,075 - uvicorn.error - INFO - Shutting down
2024-04-30 17:58:19,176 - uvicorn.error - INFO - Waiting for application shutdown.
2024-04-30 17:58:19,177 - uvicorn.error - INFO - Application shutdown complete.
2024-04-30 17:58:19,177 - uvicorn.error - INFO - Finished server process [19471]
2024-04-30 17:58:19,361 - asyncio - DEBUG - Using selector: EpollSelector
2024-04-30 17:58:19,998 - main - INFO - program_started
2024-04-30 17:58:19,998 - uvicorn.error - INFO - Started server process [19584]
2024-04-30 17:58:19,999 - uvicorn.error - INFO - Waiting for application startup.
2024-04-30 17:58:19,999 - uvicorn.error - INFO - Application startup complete.
--- Logging error ---
Traceback (most recent call last):
  File "/usr/lib/python3.10/logging/__init__.py", line 440, in format
    return self._format(record)
  File "/usr/lib/python3.10/logging/__init__.py", line 436, in _format
    return self._fmt % values
KeyError: 'funcname'

During handling of the above exception, another exception occurred:

Traceback (most recent call last):
  File "/usr/lib/python3.10/logging/__init__.py", line 1100, in emit
    msg = self.format(record)
  File "/usr/lib/python3.10/logging/__init__.py", line 943, in format
    return fmt.format(record)
  File "/usr/lib/python3.10/logging/__init__.py", line 681, in format
    s = self.formatMessage(record)
  File "/usr/lib/python3.10/logging/__init__.py", line 650, in formatMessage
    return self._style.format(record)
  File "/usr/lib/python3.10/logging/__init__.py", line 442, in format
    raise ValueError('Formatting field not found in record: %s' % e)
ValueError: Formatting field not found in record: 'funcname'
Call stack:
  File "/usr/bin/uvicorn", line 33, in <module>
    sys.exit(load_entry_point('uvicorn==0.15.0', 'console_scripts', 'uvicorn')())
  File "/usr/lib/python3/dist-packages/click/core.py", line 1128, in __call__
    return self.main(*args, **kwargs)
  File "/usr/lib/python3/dist-packages/click/core.py", line 1053, in main
    rv = self.invoke(ctx)
  File "/usr/lib/python3/dist-packages/click/core.py", line 1395, in invoke
    return ctx.invoke(self.callback, **ctx.params)
  File "/usr/lib/python3/dist-packages/click/core.py", line 754, in invoke
    return __callback(*args, **kwargs)
  File "/usr/lib/python3/dist-packages/uvicorn/main.py", line 425, in main
    run(app, **kwargs)
  File "/usr/lib/python3/dist-packages/uvicorn/main.py", line 442, in run
    ChangeReload(config, target=server.run, sockets=[sock]).run()
  File "/usr/lib/python3/dist-packages/uvicorn/supervisors/basereload.py", line 45, in run
    if self.should_restart():
  File "/usr/lib/python3/dist-packages/uvicorn/supervisors/statreload.py", line 41, in should_restart
    logger.warning(message, display_path)
Message: "StatReload detected file change in '%s'. Reloading..."
Arguments: ('main.py',)
2024-04-30 17:59:02,822 - uvicorn.error - INFO - Shutting down
2024-04-30 17:59:02,924 - uvicorn.error - INFO - Waiting for application shutdown.
2024-04-30 17:59:02,924 - uvicorn.error - INFO - Application shutdown complete.
2024-04-30 17:59:02,925 - uvicorn.error - INFO - Finished server process [19584]
2024-04-30 17:59:03,097 - asyncio - DEBUG - Using selector: EpollSelector
2024-04-30 17:59:03,730 - main - INFO - program_started
2024-04-30 17:59:03,731 - uvicorn.error - INFO - Started server process [19757]
2024-04-30 17:59:03,731 - uvicorn.error - INFO - Waiting for application startup.
2024-04-30 17:59:03,732 - uvicorn.error - INFO - Application startup complete.
--- Logging error ---
Traceback (most recent call last):
  File "/usr/lib/python3.10/logging/__init__.py", line 440, in format
    return self._format(record)
  File "/usr/lib/python3.10/logging/__init__.py", line 436, in _format
    return self._fmt % values
KeyError: 'funcname'

During handling of the above exception, another exception occurred:

Traceback (most recent call last):
  File "/usr/lib/python3.10/logging/__init__.py", line 1100, in emit
    msg = self.format(record)
  File "/usr/lib/python3.10/logging/__init__.py", line 943, in format
    return fmt.format(record)
  File "/usr/lib/python3.10/logging/__init__.py", line 681, in format
    s = self.formatMessage(record)
  File "/usr/lib/python3.10/logging/__init__.py", line 650, in formatMessage
    return self._style.format(record)
  File "/usr/lib/python3.10/logging/__init__.py", line 442, in format
    raise ValueError('Formatting field not found in record: %s' % e)
ValueError: Formatting field not found in record: 'funcname'
Call stack:
  File "/usr/bin/uvicorn", line 33, in <module>
    sys.exit(load_entry_point('uvicorn==0.15.0', 'console_scripts', 'uvicorn')())
  File "/usr/lib/python3/dist-packages/click/core.py", line 1128, in __call__
    return self.main(*args, **kwargs)
  File "/usr/lib/python3/dist-packages/click/core.py", line 1053, in main
    rv = self.invoke(ctx)
  File "/usr/lib/python3/dist-packages/click/core.py", line 1395, in invoke
    return ctx.invoke(self.callback, **ctx.params)
  File "/usr/lib/python3/dist-packages/click/core.py", line 754, in invoke
    return __callback(*args, **kwargs)
  File "/usr/lib/python3/dist-packages/uvicorn/main.py", line 425, in main
    run(app, **kwargs)
  File "/usr/lib/python3/dist-packages/uvicorn/main.py", line 442, in run
    ChangeReload(config, target=server.run, sockets=[sock]).run()
  File "/usr/lib/python3/dist-packages/uvicorn/supervisors/basereload.py", line 45, in run
    if self.should_restart():
  File "/usr/lib/python3/dist-packages/uvicorn/supervisors/statreload.py", line 41, in should_restart
    logger.warning(message, display_path)
Message: "StatReload detected file change in '%s'. Reloading..."
Arguments: ('main.py',)
2024-04-30 17:59:55,280 - uvicorn.error - INFO - Shutting down
2024-04-30 17:59:55,381 - uvicorn.error - INFO - Waiting for application shutdown.
2024-04-30 17:59:55,381 - uvicorn.error - INFO - Application shutdown complete.
2024-04-30 17:59:55,382 - uvicorn.error - INFO - Finished server process [19757]
2024-04-30 17:59:55,596 - asyncio - DEBUG - Using selector: EpollSelector
2024-04-30 17:59:56,205 - main - INFO - program_started
2024-04-30 17:59:56,206 - uvicorn.error - INFO - Started server process [19966]
2024-04-30 17:59:56,206 - uvicorn.error - INFO - Waiting for application startup.
2024-04-30 17:59:56,207 - uvicorn.error - INFO - Application startup complete.
--- Logging error ---
Traceback (most recent call last):
  File "/usr/lib/python3.10/logging/__init__.py", line 440, in format
    return self._format(record)
  File "/usr/lib/python3.10/logging/__init__.py", line 436, in _format
    return self._fmt % values
KeyError: 'funcname'

During handling of the above exception, another exception occurred:

Traceback (most recent call last):
  File "/usr/lib/python3.10/logging/__init__.py", line 1100, in emit
    msg = self.format(record)
  File "/usr/lib/python3.10/logging/__init__.py", line 943, in format
    return fmt.format(record)
  File "/usr/lib/python3.10/logging/__init__.py", line 681, in format
    s = self.formatMessage(record)
  File "/usr/lib/python3.10/logging/__init__.py", line 650, in formatMessage
    return self._style.format(record)
  File "/usr/lib/python3.10/logging/__init__.py", line 442, in format
    raise ValueError('Formatting field not found in record: %s' % e)
ValueError: Formatting field not found in record: 'funcname'
Call stack:
  File "/usr/bin/uvicorn", line 33, in <module>
    sys.exit(load_entry_point('uvicorn==0.15.0', 'console_scripts', 'uvicorn')())
  File "/usr/lib/python3/dist-packages/click/core.py", line 1128, in __call__
    return self.main(*args, **kwargs)
  File "/usr/lib/python3/dist-packages/click/core.py", line 1053, in main
    rv = self.invoke(ctx)
  File "/usr/lib/python3/dist-packages/click/core.py", line 1395, in invoke
    return ctx.invoke(self.callback, **ctx.params)
  File "/usr/lib/python3/dist-packages/click/core.py", line 754, in invoke
    return __callback(*args, **kwargs)
  File "/usr/lib/python3/dist-packages/uvicorn/main.py", line 425, in main
    run(app, **kwargs)
  File "/usr/lib/python3/dist-packages/uvicorn/main.py", line 442, in run
    ChangeReload(config, target=server.run, sockets=[sock]).run()
  File "/usr/lib/python3/dist-packages/uvicorn/supervisors/basereload.py", line 45, in run
    if self.should_restart():
  File "/usr/lib/python3/dist-packages/uvicorn/supervisors/statreload.py", line 41, in should_restart
    logger.warning(message, display_path)
Message: "StatReload detected file change in '%s'. Reloading..."
Arguments: ('main.py',)
2024-04-30 18:00:05,133 - uvicorn.error - INFO - Shutting down
2024-04-30 18:00:05,234 - uvicorn.error - INFO - Waiting for application shutdown.
2024-04-30 18:00:05,235 - uvicorn.error - INFO - Application shutdown complete.
2024-04-30 18:00:05,235 - uvicorn.error - INFO - Finished server process [19966]
2024-04-30 18:00:05,413 - asyncio - DEBUG - Using selector: EpollSelector
2024-04-30 18:00:06,093 - main - INFO - program_started
2024-04-30 18:00:06,094 - uvicorn.error - INFO - Started server process [20008]
2024-04-30 18:00:06,094 - uvicorn.error - INFO - Waiting for application startup.
2024-04-30 18:00:06,094 - uvicorn.error - INFO - Application startup complete.
2024-04-30 18:01:44,475 - uvicorn.error - INFO - Shutting down
2024-04-30 18:01:44,576 - uvicorn.error - INFO - Waiting for application shutdown.
2024-04-30 18:01:44,577 - uvicorn.error - INFO - Application shutdown complete.
2024-04-30 18:01:44,577 - uvicorn.error - INFO - Finished server process [20008]
--- Logging error ---
Traceback (most recent call last):
  File "/usr/lib/python3.10/logging/__init__.py", line 440, in format
    return self._format(record)
  File "/usr/lib/python3.10/logging/__init__.py", line 436, in _format
    return self._fmt % values
KeyError: 'funcname'

During handling of the above exception, another exception occurred:

Traceback (most recent call last):
  File "/usr/lib/python3.10/logging/__init__.py", line 1100, in emit
    msg = self.format(record)
  File "/usr/lib/python3.10/logging/__init__.py", line 943, in format
    return fmt.format(record)
  File "/usr/lib/python3.10/logging/__init__.py", line 681, in format
    s = self.formatMessage(record)
  File "/usr/lib/python3.10/logging/__init__.py", line 650, in formatMessage
    return self._style.format(record)
  File "/usr/lib/python3.10/logging/__init__.py", line 442, in format
    raise ValueError('Formatting field not found in record: %s' % e)
ValueError: Formatting field not found in record: 'funcname'
Call stack:
  File "/usr/bin/uvicorn", line 33, in <module>
    sys.exit(load_entry_point('uvicorn==0.15.0', 'console_scripts', 'uvicorn')())
  File "/usr/lib/python3/dist-packages/click/core.py", line 1128, in __call__
    return self.main(*args, **kwargs)
  File "/usr/lib/python3/dist-packages/click/core.py", line 1053, in main
    rv = self.invoke(ctx)
  File "/usr/lib/python3/dist-packages/click/core.py", line 1395, in invoke
    return ctx.invoke(self.callback, **ctx.params)
  File "/usr/lib/python3/dist-packages/click/core.py", line 754, in invoke
    return __callback(*args, **kwargs)
  File "/usr/lib/python3/dist-packages/uvicorn/main.py", line 425, in main
    run(app, **kwargs)
  File "/usr/lib/python3/dist-packages/uvicorn/main.py", line 442, in run
    ChangeReload(config, target=server.run, sockets=[sock]).run()
  File "/usr/lib/python3/dist-packages/uvicorn/supervisors/basereload.py", line 48, in run
    self.shutdown()
  File "/usr/lib/python3/dist-packages/uvicorn/supervisors/basereload.py", line 83, in shutdown
    logger.info(message, extra={"color_message": color_message})
Message: 'Stopping reloader process [4299]'
Arguments: ()
2024-04-30 18:02:04,705 - uvicorn.error - INFO - Will watch for changes in these directories: ['/mnt/e/cura/cura_backend']
2024-04-30 18:02:04,706 - uvicorn.error - INFO - Uvicorn running on http://127.0.0.1:8000 (Press CTRL+C to quit)
2024-04-30 18:02:04,706 - uvicorn.error - INFO - Started reloader process [20485] using statreload
2024-04-30 18:02:04,812 - asyncio - DEBUG - Using selector: EpollSelector
2024-04-30 18:02:05,408 - main - INFO - program_started
2024-04-30 18:02:05,408 - uvicorn.error - INFO - Started server process [20488]
2024-04-30 18:02:05,409 - uvicorn.error - INFO - Waiting for application startup.
2024-04-30 18:02:05,409 - uvicorn.error - INFO - Application startup complete.
2024-04-30 18:02:24,623 - uvicorn.error - WARNING - StatReload detected file change in 'main.py'. Reloading...
2024-04-30 18:02:24,667 - uvicorn.error - INFO - Shutting down
2024-04-30 18:02:24,767 - uvicorn.error - INFO - Waiting for application shutdown.
2024-04-30 18:02:24,768 - uvicorn.error - INFO - Application shutdown complete.
2024-04-30 18:02:24,768 - uvicorn.error - INFO - Finished server process [20488]
2024-04-30 18:02:24,990 - asyncio - DEBUG - Using selector: EpollSelector
2024-04-30 18:02:25,798 - main - INFO - program_started
2024-04-30 18:02:25,799 - uvicorn.error - INFO - Started server process [20569]
2024-04-30 18:02:25,799 - uvicorn.error - INFO - Waiting for application startup.
2024-04-30 18:02:25,800 - uvicorn.error - INFO - Application startup complete.
2024-04-30 18:03:38,818 - uvicorn.error - WARNING - StatReload detected file change in 'main.py'. Reloading...
2024-04-30 18:03:38,908 - uvicorn.error - INFO - Shutting down
2024-04-30 18:03:39,009 - uvicorn.error - INFO - Waiting for application shutdown.
2024-04-30 18:03:39,010 - uvicorn.error - INFO - Application shutdown complete.
2024-04-30 18:03:39,010 - uvicorn.error - INFO - Finished server process [20569]
2024-04-30 18:03:39,171 - asyncio - DEBUG - Using selector: EpollSelector
2024-04-30 18:03:39,762 - main - INFO - program_started
2024-04-30 18:03:39,763 - uvicorn.error - INFO - Started server process [20863]
2024-04-30 18:03:39,763 - uvicorn.error - INFO - Waiting for application startup.
2024-04-30 18:03:39,764 - uvicorn.error - INFO - Application startup complete.
2024-04-30 18:04:14,884 - root - INFO - get_users_admin:payload received is {'user_id': 1234}
2024-04-30 18:04:14,947 - uvicorn.access -send INFO - 127.0.0.1:33960 - "POST /getUsersAdmin HTTP/1.1" 200
2024-04-30 18:04:48,369 - uvicorn.error - WARNING - StatReload detected file change in 'main.py'. Reloading...
2024-04-30 18:04:48,464 - uvicorn.error - INFO - Shutting down
2024-04-30 18:04:48,565 - uvicorn.error - INFO - Waiting for application shutdown.
2024-04-30 18:04:48,565 - uvicorn.error - INFO - Application shutdown complete.
2024-04-30 18:04:48,566 - uvicorn.error - INFO - Finished server process [20863]
2024-04-30 18:04:48,737 - asyncio - DEBUG - Using selector: EpollSelector
2024-04-30 18:04:49,335 - main - INFO - program_started
2024-04-30 18:04:49,336 - uvicorn.error - INFO - Started server process [21144]
2024-04-30 18:04:49,336 - uvicorn.error - INFO - Waiting for application startup.
2024-04-30 18:04:49,336 - uvicorn.error - INFO - Application startup complete.
2024-04-30 18:04:51,919 - root - INFO - get_users_admin:payload received is {'user_id': 1234}
2024-04-30 18:04:51,956 - root - INFO - QUERY IS : <b'SELECT firstname,lastname,id FROM usertable order by firstname'>
2024-04-30 18:04:51,958 - uvicorn.access -send INFO - 127.0.0.1:60838 - "POST /getUsersAdmin HTTP/1.1" 200
2024-04-30 18:05:45,193 - uvicorn.error - WARNING - StatReload detected file change in 'main.py'. Reloading...
2024-04-30 18:05:45,208 - uvicorn.error - INFO - Shutting down
2024-04-30 18:05:45,309 - uvicorn.error - INFO - Waiting for application shutdown.
2024-04-30 18:05:45,309 - uvicorn.error - INFO - Application shutdown complete.
2024-04-30 18:05:45,310 - uvicorn.error - INFO - Finished server process [21144]
2024-04-30 18:05:45,478 - asyncio - DEBUG - Using selector: EpollSelector
2024-04-30 18:05:46,135 - main - INFO - program_started
2024-04-30 18:05:46,135 - uvicorn.error - INFO - Started server process [21376]
2024-04-30 18:05:46,136 - uvicorn.error - INFO - Waiting for application startup.
2024-04-30 18:05:46,136 - uvicorn.error - INFO - Application startup complete.
2024-04-30 18:05:48,579 - root - INFO - get_users_admin:payload received is {'user_id': 1234}
2024-04-30 18:05:48,615 - root - DEBUG - QUERY IS : <b'SELECT firstname,lastname,id FROM usertable order by firstname'>
2024-04-30 18:05:48,617 - uvicorn.access -send INFO - 127.0.0.1:43462 - "POST /getUsersAdmin HTTP/1.1" 200
2024-04-30 18:07:38,222 - uvicorn.error - WARNING - StatReload detected file change in 'main.py'. Reloading...
2024-04-30 18:07:38,263 - uvicorn.error - INFO - Shutting down
2024-04-30 18:07:38,364 - uvicorn.error - INFO - Waiting for application shutdown.
2024-04-30 18:07:38,364 - uvicorn.error - INFO - Application shutdown complete.
2024-04-30 18:07:38,365 - uvicorn.error - INFO - Finished server process [21376]
2024-04-30 18:07:38,527 - asyncio - DEBUG - Using selector: EpollSelector
2024-04-30 18:07:39,113 - main - INFO - program_started
2024-04-30 18:07:39,114 - uvicorn.error - INFO - Started server process [21829]
2024-04-30 18:07:39,114 - uvicorn.error - INFO - Waiting for application startup.
2024-04-30 18:07:39,114 - uvicorn.error - INFO - Application startup complete.
2024-04-30 18:08:29,097 - uvicorn.error - WARNING - StatReload detected file change in 'main.py'. Reloading...
2024-04-30 18:08:29,158 - uvicorn.error - INFO - Shutting down
2024-04-30 18:08:29,259 - uvicorn.error - INFO - Waiting for application shutdown.
2024-04-30 18:08:29,260 - uvicorn.error - INFO - Application shutdown complete.
2024-04-30 18:08:29,260 - uvicorn.error - INFO - Finished server process [21829]
2024-04-30 18:08:29,478 -DEFAULT- asyncio - DEBUG - Using selector: EpollSelector
2024-04-30 18:08:30,182 -DEFAULT- main - INFO - program_started
2024-04-30 18:08:30,182 -DEFAULT- uvicorn.error - INFO - Started server process [22032]
2024-04-30 18:08:30,183 -DEFAULT- uvicorn.error - INFO - Waiting for application startup.
2024-04-30 18:08:30,183 -DEFAULT- uvicorn.error - INFO - Application startup complete.
2024-04-30 18:08:33,536 -DEFAULT- root - INFO - get_users_admin:payload received is {'user_id': 1234}
2024-04-30 18:08:33,567 -DEFAULT- root - INFO - QUERY IS : <b'SELECT firstname,lastname,id FROM usertable order by firstname'>
2024-04-30 18:08:33,568 -ACCESS- uvicorn.access -send INFO - 127.0.0.1:36410 - "POST /getUsersAdmin HTTP/1.1" 200
2024-04-30 18:08:58,967 - uvicorn.error - WARNING - StatReload detected file change in 'main.py'. Reloading...
2024-04-30 18:08:59,067 -DEFAULT- uvicorn.error - INFO - Shutting down
2024-04-30 18:08:59,168 -DEFAULT- uvicorn.error - INFO - Waiting for application shutdown.
2024-04-30 18:08:59,168 -DEFAULT- uvicorn.error - INFO - Application shutdown complete.
2024-04-30 18:08:59,169 -DEFAULT- uvicorn.error - INFO - Finished server process [22032]
2024-04-30 18:08:59,348 -ACCESS- asyncio -__init__ DEBUG - Using selector: EpollSelector
2024-04-30 18:08:59,965 -ACCESS- main -<module> INFO - program_started
2024-04-30 18:08:59,965 -DEFAULT- uvicorn.error - INFO - Started server process [22155]
2024-04-30 18:08:59,966 -DEFAULT- uvicorn.error - INFO - Waiting for application startup.
2024-04-30 18:08:59,966 -DEFAULT- uvicorn.error - INFO - Application startup complete.
2024-04-30 18:09:18,559 -ACCESS- root -get_users_admin INFO - get_users_admin:payload received is {'user_id': 1234}
2024-04-30 18:09:18,598 -ACCESS- root -usernames INFO - QUERY IS : <b'SELECT firstname,lastname,id FROM usertable order by firstname'>
2024-04-30 18:09:18,601 -ACCESS- uvicorn.access -send INFO - 127.0.0.1:40652 - "POST /getUsersAdmin HTTP/1.1" 200
2024-04-30 18:09:43,269 - uvicorn.error - WARNING - StatReload detected file change in 'main.py'. Reloading...
2024-04-30 18:09:43,299 -DEFAULT- uvicorn.error - INFO - Shutting down
2024-04-30 18:09:43,400 -DEFAULT- uvicorn.error - INFO - Waiting for application shutdown.
2024-04-30 18:09:43,401 -DEFAULT- uvicorn.error - INFO - Application shutdown complete.
2024-04-30 18:09:43,401 -DEFAULT- uvicorn.error - INFO - Finished server process [22155]
2024-04-30 18:09:43,616 - asyncio -__init__ DEBUG - Using selector: EpollSelector
2024-04-30 18:09:44,301 - main -<module> INFO - program_started
2024-04-30 18:09:44,302 - uvicorn.error - INFO - Started server process [22335]
2024-04-30 18:09:44,303 - uvicorn.error - INFO - Waiting for application startup.
2024-04-30 18:09:44,303 - uvicorn.error - INFO - Application startup complete.
2024-04-30 18:09:49,848 - root -get_users_admin INFO - get_users_admin:payload received is {'user_id': 1234}
2024-04-30 18:09:49,880 - root -usernames INFO - QUERY IS : <b'SELECT firstname,lastname,id FROM usertable order by firstname'>
2024-04-30 18:09:49,882 - uvicorn.access -send INFO - 127.0.0.1:52130 - "POST /getUsersAdmin HTTP/1.1" 200
2024-04-30 18:10:04,059 - uvicorn.error - WARNING - StatReload detected file change in 'main.py'. Reloading...
2024-04-30 18:10:04,060 - uvicorn.error - INFO - Shutting down
2024-04-30 18:10:04,161 - uvicorn.error - INFO - Waiting for application shutdown.
2024-04-30 18:10:04,161 - uvicorn.error - INFO - Application shutdown complete.
2024-04-30 18:10:04,162 - uvicorn.error - INFO - Finished server process [22335]
2024-04-30 18:10:04,350 - asyncio - __init__ DEBUG - Using selector: EpollSelector
2024-04-30 18:10:04,963 - main - <module> INFO - program_started
2024-04-30 18:10:04,963 - uvicorn.error - INFO - Started server process [22424]
2024-04-30 18:10:04,964 - uvicorn.error - INFO - Waiting for application startup.
2024-04-30 18:10:04,964 - uvicorn.error - INFO - Application startup complete.
2024-04-30 18:10:06,405 - root - get_users_admin INFO - get_users_admin:payload received is {'user_id': 1234}
2024-04-30 18:10:06,447 - root - usernames INFO - QUERY IS : <b'SELECT firstname,lastname,id FROM usertable order by firstname'>
2024-04-30 18:10:06,449 - uvicorn.access - send INFO - 127.0.0.1:53984 - "POST /getUsersAdmin HTTP/1.1" 200
2024-04-30 18:10:28,610 - root - get_users_admin INFO - get_users_admin:payload received is {'user_id': 1234}
2024-04-30 18:10:28,671 - root - usernames INFO - QUERY IS : <b'SELECT firstname,lastname,id FROM usertable order by firstname'>
2024-04-30 18:10:28,674 - uvicorn.access - send INFO - 127.0.0.1:43088 - "POST /getUsersAdmin HTTP/1.1" 200
2024-04-30 18:10:39,502 - uvicorn.error - WARNING - StatReload detected file change in 'main.py'. Reloading...
2024-04-30 18:10:39,505 - uvicorn.error - INFO - Shutting down
2024-04-30 18:10:39,606 - uvicorn.error - INFO - Waiting for application shutdown.
2024-04-30 18:10:39,607 - uvicorn.error - INFO - Application shutdown complete.
2024-04-30 18:10:39,607 - uvicorn.error - INFO - Finished server process [22424]
2024-04-30 18:10:39,816 - asyncio - __init__ - DEBUG - Using selector: EpollSelector
2024-04-30 18:10:40,459 - main - <module> - INFO - program_started
2024-04-30 18:10:40,460 - uvicorn.error - INFO - Started server process [22572]
2024-04-30 18:10:40,460 - uvicorn.error - INFO - Waiting for application startup.
2024-04-30 18:10:40,460 - uvicorn.error - INFO - Application startup complete.
2024-04-30 18:10:48,258 - root - get_users_admin - INFO - get_users_admin:payload received is {'user_id': 1234}
2024-04-30 18:10:48,316 - root - usernames - INFO - QUERY IS : <b'SELECT firstname,lastname,id FROM usertable order by firstname'>
2024-04-30 18:10:48,318 - uvicorn.access - send - INFO - 127.0.0.1:33922 - "POST /getUsersAdmin HTTP/1.1" 200
2024-04-30 18:13:52,228 - uvicorn.error - WARNING - StatReload detected file change in 'main.py'. Reloading...
2024-04-30 18:13:52,234 - uvicorn.error - INFO - Shutting down
2024-04-30 18:13:52,334 - uvicorn.error - INFO - Waiting for application shutdown.
2024-04-30 18:13:52,335 - uvicorn.error - INFO - Application shutdown complete.
2024-04-30 18:13:52,335 - uvicorn.error - INFO - Finished server process [22572]
2024-04-30 18:13:52,506 - asyncio - __init__ - DEBUG - Using selector: EpollSelector
Process SpawnProcess-12:
Traceback (most recent call last):
  File "/usr/lib/python3.10/multiprocessing/process.py", line 314, in _bootstrap
    self.run()
  File "/usr/lib/python3.10/multiprocessing/process.py", line 108, in run
    self._target(*self._args, **self._kwargs)
  File "/usr/lib/python3/dist-packages/uvicorn/subprocess.py", line 76, in subprocess_started
    target(sockets=sockets)
  File "/usr/lib/python3/dist-packages/uvicorn/server.py", line 68, in run
    return asyncio.run(self.serve(sockets=sockets))
  File "/usr/lib/python3.10/asyncio/runners.py", line 44, in run
    return loop.run_until_complete(main)
  File "/usr/lib/python3.10/asyncio/base_events.py", line 649, in run_until_complete
    return future.result()
  File "/usr/lib/python3/dist-packages/uvicorn/server.py", line 76, in serve
    config.load()
  File "/usr/lib/python3/dist-packages/uvicorn/config.py", line 448, in load
    self.loaded_app = import_from_string(self.app)
  File "/usr/lib/python3/dist-packages/uvicorn/importer.py", line 21, in import_from_string
    module = importlib.import_module(module_str)
  File "/usr/lib/python3.10/importlib/__init__.py", line 126, in import_module
    return _bootstrap._gcd_import(name[level:], package, level)
  File "<frozen importlib._bootstrap>", line 1050, in _gcd_import
  File "<frozen importlib._bootstrap>", line 1027, in _find_and_load
  File "<frozen importlib._bootstrap>", line 1006, in _find_and_load_unlocked
  File "<frozen importlib._bootstrap>", line 688, in _load_unlocked
  File "<frozen importlib._bootstrap_external>", line 879, in exec_module
  File "<frozen importlib._bootstrap_external>", line 1017, in get_code
  File "<frozen importlib._bootstrap_external>", line 947, in source_to_code
  File "<frozen importlib._bootstrap>", line 241, in _call_with_frames_removed
  File "/mnt/e/cura/cura_backend/./main.py", line 470
    msg = logMessage(cursor,query,(payload['username'],))
                                                         ^
IndentationError: unindent does not match any outer indentation level
2024-04-30 18:14:51,011 - uvicorn.error - WARNING - StatReload detected file change in 'main.py'. Reloading...
2024-04-30 18:14:51,115 - asyncio - __init__ - DEBUG - Using selector: EpollSelector
2024-04-30 18:14:51,779 - main - <module> - INFO - program_started
2024-04-30 18:14:51,780 - uvicorn.error - INFO - Started server process [23572]
2024-04-30 18:14:51,780 - uvicorn.error - INFO - Waiting for application startup.
2024-04-30 18:14:51,781 - uvicorn.error - INFO - Application startup complete.
2024-04-30 18:16:54,651 - uvicorn.error - WARNING - StatReload detected file change in 'main.py'. Reloading...
2024-04-30 18:16:54,729 - uvicorn.error - INFO - Shutting down
2024-04-30 18:16:54,830 - uvicorn.error - INFO - Waiting for application shutdown.
2024-04-30 18:16:54,830 - uvicorn.error - INFO - Application shutdown complete.
2024-04-30 18:16:54,830 - uvicorn.error - INFO - Finished server process [23572]
2024-04-30 18:16:55,000 - asyncio - __init__ - DEBUG - Using selector: EpollSelector
2024-04-30 18:16:55,508 - main - <module> - INFO - program_started
2024-04-30 18:16:55,508 - uvicorn.error - INFO - Started server process [24067]
2024-04-30 18:16:55,509 - uvicorn.error - INFO - Waiting for application startup.
2024-04-30 18:16:55,509 - uvicorn.error - INFO - Application startup complete.
2024-04-30 18:20:24,545 - root - add_builder_info - INFO - add_builder_info: received payload <{'user_id': 1234, 'buildername': 'Rudra', 'phone1': '9999999999', 'phone2': '8888888888', 'email1': 'abc@def.com', 'addressline1': 'abc area, def house', 'addressline2': 'ghi locality', 'suburb': 'ijkl', 'city': 360, 'state': 'Maharashtra', 'country': 5, 'zip': '1234', 'website': 'www.abc.example.com', 'comments': 'comment1\ncomment2\ncomment3', 'dated': '10-03-2024 08:29:00', 'createdby': 1234, 'isdeleted': False}>
2024-04-30 18:20:24,620 - uvicorn.access - send - INFO - 127.0.0.1:36690 - "POST /addBuilderInfo HTTP/1.1" 200
2024-04-30 18:21:38,406 - uvicorn.access - send - INFO - 127.0.0.1:54946 - "POST /addCountry HTTP/1.1" 422
2024-04-30 18:21:46,957 - root - add_country - INFO - add_country: received payload <{'user_id': 1234, 'new_country': 'testabc'}>
2024-04-30 18:21:46,978 - uvicorn.access - send - INFO - 127.0.0.1:57416 - "POST /addCountry HTTP/1.1" 200
2024-04-30 18:22:09,316 - root - add_country - INFO - add_country: received payload <{'user_id': 1234, 'country_name': 'testabc'}>
2024-04-30 18:22:09,355 - root - ifNotExist - INFO - 0
2024-04-30 18:22:09,379 - uvicorn.access - send - INFO - 127.0.0.1:40292 - "POST /addCountry HTTP/1.1" 200
2024-04-30 18:23:24,708 - root - get_modes_admin - INFO - get_modes_admin: received payload <{'user_id': 1234}>
2024-04-30 18:23:24,746 - uvicorn.access - send - INFO - 127.0.0.1:41552 - "POST /getModesAdmin HTTP/1.1" 200
2024-04-30 18:24:26,753 - uvicorn.error - WARNING - StatReload detected file change in 'main.py'. Reloading...
2024-04-30 18:24:26,817 - uvicorn.error - INFO - Shutting down
2024-04-30 18:24:26,918 - uvicorn.error - INFO - Waiting for application shutdown.
2024-04-30 18:24:26,918 - uvicorn.error - INFO - Application shutdown complete.
2024-04-30 18:24:26,918 - uvicorn.error - INFO - Finished server process [24067]
2024-04-30 18:24:27,116 - asyncio - __init__ - DEBUG - Using selector: EpollSelector
2024-04-30 18:24:27,820 - main - <module> - INFO - program_started
2024-04-30 18:24:27,821 - uvicorn.error - INFO - Started server process [25878]
2024-04-30 18:24:27,822 - uvicorn.error - INFO - Waiting for application startup.
2024-04-30 18:24:27,822 - uvicorn.error - INFO - Application startup complete.
2024-04-30 18:24:31,630 - root - get_modes_admin - INFO - get_modes_admin: received payload <{'user_id': 1234}>
2024-04-30 18:24:31,653 - root - check_role_access - INFO - QUERY IS : <SELECT roleid FROM usertable WHERE id = 1234>
2024-04-30 18:24:31,669 - uvicorn.access - send - INFO - 127.0.0.1:45680 - "POST /getModesAdmin HTTP/1.1" 200
2024-04-30 18:26:18,361 - uvicorn.error - WARNING - StatReload detected file change in 'main.py'. Reloading...
2024-04-30 18:26:18,369 - uvicorn.error - INFO - Shutting down
2024-04-30 18:26:18,470 - uvicorn.error - INFO - Waiting for application shutdown.
2024-04-30 18:26:18,471 - uvicorn.error - INFO - Application shutdown complete.
2024-04-30 18:26:18,471 - uvicorn.error - INFO - Finished server process [25878]
2024-04-30 18:26:18,630 - asyncio - __init__ - DEBUG - Using selector: EpollSelector
2024-04-30 18:26:19,253 - main - <module> - INFO - program_started
2024-04-30 18:26:19,254 - uvicorn.error - INFO - Started server process [26328]
2024-04-30 18:26:19,254 - uvicorn.error - INFO - Waiting for application startup.
2024-04-30 18:26:19,255 - uvicorn.error - INFO - Application startup complete.
2024-04-30 18:26:22,112 - root - get_modes_admin - INFO - get_modes_admin: received payload <{'user_id': 1234}>
2024-04-30 18:26:22,138 - root - check_role_access - INFO - QUERY IS : <SELECT roleid FROM usertable WHERE id = 1234>
2024-04-30 18:26:22,154 - uvicorn.access - send - INFO - 127.0.0.1:43592 - "POST /getModesAdmin HTTP/1.1" 200
2024-04-30 18:27:19,403 - uvicorn.error - WARNING - StatReload detected file change in 'main.py'. Reloading...
2024-04-30 18:27:19,428 - uvicorn.error - INFO - Shutting down
2024-04-30 18:27:19,529 - uvicorn.error - INFO - Waiting for application shutdown.
2024-04-30 18:27:19,529 - uvicorn.error - INFO - Application shutdown complete.
2024-04-30 18:27:19,530 - uvicorn.error - INFO - Finished server process [26328]
2024-04-30 18:27:19,722 - asyncio - __init__ - DEBUG - Using selector: EpollSelector
2024-04-30 18:27:20,327 - main - <module> - INFO - program_started
2024-04-30 18:27:20,328 - uvicorn.error - INFO - Started server process [26574]
2024-04-30 18:27:20,328 - uvicorn.error - INFO - Waiting for application startup.
2024-04-30 18:27:20,328 - uvicorn.error - INFO - Application startup complete.
2024-04-30 18:27:23,724 - root - get_modes_admin - INFO - get_modes_admin: received payload <{'user_id': 1234}>
2024-04-30 18:27:23,764 - root - check_role_access - INFO - QUERY IS : <SELECT roleid FROM usertable WHERE id = 1234>
2024-04-30 18:27:23,784 - uvicorn.access - send - INFO - 127.0.0.1:60466 - "POST /getModesAdmin HTTP/1.1" 200
2024-04-30 18:28:24,059 - root - validate_credentials - INFO - validate_credentials: received payload <{'username': 'ruderaw', 'password': '1234567', 'company_key': 9632}>
2024-04-30 18:28:24,090 - root - validate_credentials - INFO - QUERY IS : <SELECT password,id,roleid FROM usertable where username = 'ruderaw'>
2024-04-30 18:28:24,104 - root - validate_credentials - INFO - QUERY IS : <SELECT EXISTS (SELECT 1 FROM companykey WHERE companycode = '9632')>
Traceback (most recent call last):
  File "/mnt/e/cura/cura_backend/./main.py", line 479, in validate_credentials
    return giveFailure("User does not exist")
TypeError: giveFailure() missing 2 required positional arguments: 'uid' and 'rid'
2024-04-30 18:28:24,112 - root - validate_credentials - ERROR - None
Traceback (most recent call last):
  File "/mnt/e/cura/cura_backend/./main.py", line 479, in validate_credentials
    return giveFailure("User does not exist")
TypeError: giveFailure() missing 2 required positional arguments: 'uid' and 'rid'
2024-04-30 18:28:24,114 - uvicorn.access - send - INFO - 127.0.0.1:38746 - "POST /validateCredentials HTTP/1.1" 200
2024-04-30 18:28:47,177 - root - validate_credentials - INFO - validate_credentials: received payload <{'username': 'ruderaw', 'password': 'abcdefg', 'company_key': 9632}>
2024-04-30 18:28:47,198 - root - validate_credentials - INFO - QUERY IS : <SELECT password,id,roleid FROM usertable where username = 'ruderaw'>
2024-04-30 18:28:47,210 - root - validate_credentials - INFO - QUERY IS : <SELECT EXISTS (SELECT 1 FROM companykey WHERE companycode = '9632')>
Traceback (most recent call last):
  File "/mnt/e/cura/cura_backend/./main.py", line 479, in validate_credentials
    return giveFailure("User does not exist")
TypeError: giveFailure() missing 2 required positional arguments: 'uid' and 'rid'
2024-04-30 18:28:47,211 - root - validate_credentials - ERROR - None
Traceback (most recent call last):
  File "/mnt/e/cura/cura_backend/./main.py", line 479, in validate_credentials
    return giveFailure("User does not exist")
TypeError: giveFailure() missing 2 required positional arguments: 'uid' and 'rid'
2024-04-30 18:28:47,213 - uvicorn.access - send - INFO - 127.0.0.1:48788 - "POST /validateCredentials HTTP/1.1" 200
2024-04-30 18:29:34,225 - root - validate_credentials - INFO - validate_credentials: received payload <{'username': 'ruderaw', 'password': 'abcdefg', 'company_key': '9632'}>
2024-04-30 18:29:34,246 - root - validate_credentials - INFO - QUERY IS : <SELECT password,id,roleid FROM usertable where username = 'ruderaw'>
2024-04-30 18:29:34,254 - root - validate_credentials - INFO - QUERY IS : <SELECT EXISTS (SELECT 1 FROM companykey WHERE companycode = '9632')>
Traceback (most recent call last):
  File "/mnt/e/cura/cura_backend/./main.py", line 479, in validate_credentials
    return giveFailure("User does not exist")
TypeError: giveFailure() missing 2 required positional arguments: 'uid' and 'rid'
2024-04-30 18:29:34,256 - root - validate_credentials - ERROR - None
Traceback (most recent call last):
  File "/mnt/e/cura/cura_backend/./main.py", line 479, in validate_credentials
    return giveFailure("User does not exist")
TypeError: giveFailure() missing 2 required positional arguments: 'uid' and 'rid'
2024-04-30 18:29:34,257 - uvicorn.access - send - INFO - 127.0.0.1:56920 - "POST /validateCredentials HTTP/1.1" 200
2024-04-30 18:29:49,884 - root - validate_credentials - INFO - validate_credentials: received payload <{'username': 'ruderaw', 'password': 'abcdefg', 'company_key': '9632'}>
2024-04-30 18:29:49,924 - root - validate_credentials - INFO - QUERY IS : <SELECT password,id,roleid FROM usertable where username = 'ruderaw'>
2024-04-30 18:29:49,945 - root - validate_credentials - INFO - QUERY IS : <SELECT EXISTS (SELECT 1 FROM companykey WHERE companycode = '9632')>
Traceback (most recent call last):
  File "/mnt/e/cura/cura_backend/./main.py", line 479, in validate_credentials
    return giveFailure("User does not exist")
TypeError: giveFailure() missing 2 required positional arguments: 'uid' and 'rid'
2024-04-30 18:29:49,946 - root - validate_credentials - ERROR - None
Traceback (most recent call last):
  File "/mnt/e/cura/cura_backend/./main.py", line 479, in validate_credentials
    return giveFailure("User does not exist")
TypeError: giveFailure() missing 2 required positional arguments: 'uid' and 'rid'
2024-04-30 18:29:49,948 - uvicorn.access - send - INFO - 127.0.0.1:42570 - "POST /validateCredentials HTTP/1.1" 200
2024-04-30 18:30:27,143 - uvicorn.error - WARNING - StatReload detected file change in 'main.py'. Reloading...
2024-04-30 18:30:27,152 - uvicorn.error - INFO - Shutting down
2024-04-30 18:30:27,253 - uvicorn.error - INFO - Waiting for application shutdown.
2024-04-30 18:30:27,253 - uvicorn.error - INFO - Application shutdown complete.
2024-04-30 18:30:27,254 - uvicorn.error - INFO - Finished server process [26574]
2024-04-30 18:30:27,446 - asyncio - __init__ - DEBUG - Using selector: EpollSelector
2024-04-30 18:30:28,063 - main - <module> - INFO - program_started
2024-04-30 18:30:28,064 - uvicorn.error - INFO - Started server process [27336]
2024-04-30 18:30:28,065 - uvicorn.error - INFO - Waiting for application startup.
2024-04-30 18:30:28,065 - uvicorn.error - INFO - Application startup complete.
2024-04-30 18:30:31,089 - root - validate_credentials - INFO - validate_credentials: received payload <{'username': 'ruderaw', 'password': 'abcdefg', 'company_key': '9632'}>
2024-04-30 18:30:31,117 - root - validate_credentials - INFO - QUERY IS : <SELECT password,id,roleid FROM usertable where username = 'ruderaw'>
2024-04-30 18:30:31,117 - root - validate_credentials - INFO - [('$2a$12$pT07xTktKj9e1KWuib8/z.riX4asy1vyk8jvIaGxtPELi9UhM9OQC', 1234, 1)]
2024-04-30 18:30:31,131 - root - validate_credentials - INFO - QUERY IS : <SELECT EXISTS (SELECT 1 FROM companykey WHERE companycode = '9632')>
Traceback (most recent call last):
  File "/mnt/e/cura/cura_backend/./main.py", line 480, in validate_credentials
    return giveFailure("User does not exist")
TypeError: giveFailure() missing 2 required positional arguments: 'uid' and 'rid'
2024-04-30 18:30:31,140 - root - validate_credentials - ERROR - None
Traceback (most recent call last):
  File "/mnt/e/cura/cura_backend/./main.py", line 480, in validate_credentials
    return giveFailure("User does not exist")
TypeError: giveFailure() missing 2 required positional arguments: 'uid' and 'rid'
2024-04-30 18:30:31,141 - uvicorn.access - send - INFO - 127.0.0.1:46124 - "POST /validateCredentials HTTP/1.1" 200
2024-04-30 18:31:22,662 - uvicorn.error - WARNING - StatReload detected file change in 'main.py'. Reloading...
2024-04-30 18:31:22,723 - uvicorn.error - INFO - Shutting down
2024-04-30 18:31:22,824 - uvicorn.error - INFO - Waiting for application shutdown.
2024-04-30 18:31:22,824 - uvicorn.error - INFO - Application shutdown complete.
2024-04-30 18:31:22,824 - uvicorn.error - INFO - Finished server process [27336]
2024-04-30 18:31:23,009 - asyncio - __init__ - DEBUG - Using selector: EpollSelector
2024-04-30 18:31:23,629 - main - <module> - INFO - program_started
2024-04-30 18:31:23,630 - uvicorn.error - INFO - Started server process [27561]
2024-04-30 18:31:23,630 - uvicorn.error - INFO - Waiting for application startup.
2024-04-30 18:31:23,631 - uvicorn.error - INFO - Application startup complete.
2024-04-30 18:31:25,375 - root - validate_credentials - INFO - validate_credentials: received payload <{'username': 'ruderaw', 'password': 'abcdefg', 'company_key': '9632'}>
2024-04-30 18:31:25,406 - root - validate_credentials - INFO - QUERY IS : <SELECT password,id,roleid FROM usertable where username = 'ruderaw'>
2024-04-30 18:31:25,417 - root - validate_credentials - INFO - QUERY IS : <SELECT EXISTS (SELECT 1 FROM companykey WHERE companycode = '9632')>
2024-04-30 18:31:25,418 - uvicorn.access - send - INFO - 127.0.0.1:45640 - "POST /validateCredentials HTTP/1.1" 200
2024-04-30 18:32:35,540 - uvicorn.error - WARNING - StatReload detected file change in 'main.py'. Reloading...
2024-04-30 18:32:35,638 - uvicorn.error - INFO - Shutting down
2024-04-30 18:32:35,739 - uvicorn.error - INFO - Waiting for application shutdown.
2024-04-30 18:32:35,739 - uvicorn.error - INFO - Application shutdown complete.
2024-04-30 18:32:35,740 - uvicorn.error - INFO - Finished server process [27561]
2024-04-30 18:32:35,921 - asyncio - __init__ - DEBUG - Using selector: EpollSelector
2024-04-30 18:32:36,566 - main - <module> - INFO - program_started
2024-04-30 18:32:36,567 - uvicorn.error - INFO - Started server process [27854]
2024-04-30 18:32:36,567 - uvicorn.error - INFO - Waiting for application startup.
2024-04-30 18:32:36,568 - uvicorn.error - INFO - Application startup complete.
2024-04-30 18:32:38,271 - root - validate_credentials - INFO - validate_credentials: received payload <{'username': 'ruderaw', 'password': 'abcdefg', 'company_key': '9632'}>
2024-04-30 18:32:38,298 - root - validate_credentials - INFO - QUERY IS : <SELECT password,id,roleid FROM usertable where username = 'ruderaw'>
2024-04-30 18:32:38,298 - root - validate_credentials - INFO - None
2024-04-30 18:32:38,315 - root - validate_credentials - INFO - QUERY IS : <SELECT EXISTS (SELECT 1 FROM companykey WHERE companycode = '9632')>
2024-04-30 18:32:38,316 - uvicorn.access - send - INFO - 127.0.0.1:54794 - "POST /validateCredentials HTTP/1.1" 200
2024-04-30 18:33:06,001 - uvicorn.error - WARNING - StatReload detected file change in 'main.py'. Reloading...
2024-04-30 18:33:06,097 - uvicorn.error - INFO - Shutting down
2024-04-30 18:33:06,198 - uvicorn.error - INFO - Waiting for application shutdown.
2024-04-30 18:33:06,199 - uvicorn.error - INFO - Application shutdown complete.
2024-04-30 18:33:06,199 - uvicorn.error - INFO - Finished server process [27854]
2024-04-30 18:33:06,376 - asyncio - __init__ - DEBUG - Using selector: EpollSelector
2024-04-30 18:33:07,010 - main - <module> - INFO - program_started
2024-04-30 18:33:07,011 - uvicorn.error - INFO - Started server process [27980]
2024-04-30 18:33:07,012 - uvicorn.error - INFO - Waiting for application startup.
2024-04-30 18:33:07,012 - uvicorn.error - INFO - Application startup complete.
2024-04-30 18:33:09,068 - root - validate_credentials - INFO - validate_credentials: received payload <{'username': 'ruderaw', 'password': 'abcdefg', 'company_key': '9632'}>
2024-04-30 18:33:09,094 - root - validate_credentials - INFO - QUERY IS : <SELECT password,id,roleid FROM usertable where username = 'ruderaw'>
2024-04-30 18:33:09,094 - root - validate_credentials - INFO - ('$2a$12$pT07xTktKj9e1KWuib8/z.riX4asy1vyk8jvIaGxtPELi9UhM9OQC', 1234, 1)
2024-04-30 18:33:09,109 - root - validate_credentials - INFO - QUERY IS : <SELECT EXISTS (SELECT 1 FROM companykey WHERE companycode = '9632')>
2024-04-30 18:33:09,109 - main - validate_credentials - INFO - $2a$12$pT07xTktKj9e1KWuib8/z.riX4asy1vyk8jvIaGxtPELi9UhM9OQC is password hashed
2024-04-30 18:33:09,109 - main - validate_credentials - INFO - <class 'bytes'> is type
2024-04-30 18:33:09,331 - main - validate_credentials - INFO - Password is ok
2024-04-30 18:33:09,332 - uvicorn.access - send - INFO - 127.0.0.1:36352 - "POST /validateCredentials HTTP/1.1" 200
2024-04-30 18:33:38,412 - uvicorn.error - WARNING - StatReload detected file change in 'main.py'. Reloading...
2024-04-30 18:33:38,416 - uvicorn.error - INFO - Shutting down
2024-04-30 18:33:38,517 - uvicorn.error - INFO - Waiting for application shutdown.
2024-04-30 18:33:38,517 - uvicorn.error - INFO - Application shutdown complete.
2024-04-30 18:33:38,518 - uvicorn.error - INFO - Finished server process [27980]
2024-04-30 18:33:38,688 - asyncio - __init__ - DEBUG - Using selector: EpollSelector
2024-04-30 18:33:39,336 - main - <module> - INFO - program_started
2024-04-30 18:33:39,337 - uvicorn.error - INFO - Started server process [28112]
2024-04-30 18:33:39,338 - uvicorn.error - INFO - Waiting for application startup.
2024-04-30 18:33:39,338 - uvicorn.error - INFO - Application startup complete.
2024-04-30 18:34:19,574 - root - add_country - INFO - add_country: received payload <{'user_id': 1234, 'country_name': 'testabce'}>
2024-04-30 18:34:19,614 - root - check_role_access - INFO - QUERY IS : <SELECT roleid FROM usertable WHERE id = 1234>
2024-04-30 18:34:19,631 - root - ifNotExist - INFO - 0
2024-04-30 18:34:19,650 - root - add_country - INFO - QUERY IS : <INSERT INTO country (name) VALUES ('testabce')>
2024-04-30 18:34:19,671 - uvicorn.access - send - INFO - 127.0.0.1:60622 - "POST /addCountry HTTP/1.1" 200
2024-04-30 18:35:35,865 - uvicorn.error - WARNING - StatReload detected file change in 'main.py'. Reloading...
2024-04-30 18:35:35,882 - uvicorn.error - INFO - Shutting down
2024-04-30 18:35:35,983 - uvicorn.error - INFO - Waiting for application shutdown.
2024-04-30 18:35:35,983 - uvicorn.error - INFO - Application shutdown complete.
2024-04-30 18:35:35,984 - uvicorn.error - INFO - Finished server process [28112]
2024-04-30 18:35:36,162 - asyncio - __init__ - DEBUG - Using selector: EpollSelector
2024-04-30 18:35:36,808 - main - <module> - INFO - program_started
2024-04-30 18:35:36,809 - uvicorn.error - INFO - Started server process [28586]
2024-04-30 18:35:36,809 - uvicorn.error - INFO - Waiting for application startup.
2024-04-30 18:35:36,810 - uvicorn.error - INFO - Application startup complete.
2024-04-30 19:21:35,075 - root - add_country - INFO - add_country: received payload <{'user_id': 1234, 'country_name': 'testabcde'}>
2024-04-30 19:21:35,097 - root - check_role_access - INFO - QUERY IS : <SELECT roleid FROM usertable WHERE id = 1234>
2024-04-30 19:21:35,108 - root - ifNotExist - INFO - 0
2024-04-30 19:21:35,118 - root - add_country - INFO - QUERY IS : <INSERT INTO country (name) VALUES ('testabcde')>
2024-04-30 19:21:35,134 - uvicorn.access - send - INFO - 127.0.0.1:45424 - "POST /addCountry HTTP/1.1" 200
2024-04-30 19:35:30,340 - uvicorn.error - WARNING - StatReload detected file change in 'main.py'. Reloading...
2024-04-30 19:35:30,390 - uvicorn.error - INFO - Shutting down
2024-04-30 19:35:30,491 - uvicorn.error - INFO - Waiting for application shutdown.
2024-04-30 19:35:30,491 - uvicorn.error - INFO - Application shutdown complete.
2024-04-30 19:35:30,492 - uvicorn.error - INFO - Finished server process [28586]
2024-04-30 19:35:30,724 - asyncio - __init__ - DEBUG - Using selector: EpollSelector
2024-04-30 19:35:31,370 - main - <module> - INFO - program_started
2024-04-30 19:35:31,371 - uvicorn.error - INFO - Started server process [42880]
2024-04-30 19:35:31,371 - uvicorn.error - INFO - Waiting for application startup.
2024-04-30 19:35:31,372 - uvicorn.error - INFO - Application startup complete.
2024-04-30 20:05:19,311 - uvicorn.error - WARNING - StatReload detected file change in 'main.py'. Reloading...
2024-04-30 20:05:19,320 - uvicorn.error - INFO - Shutting down
2024-04-30 20:05:19,421 - uvicorn.error - INFO - Waiting for application shutdown.
2024-04-30 20:05:19,422 - uvicorn.error - INFO - Application shutdown complete.
2024-04-30 20:05:19,422 - uvicorn.error - INFO - Finished server process [42880]
2024-04-30 20:05:19,633 - asyncio - __init__ - DEBUG - Using selector: EpollSelector
2024-04-30 20:05:20,321 - main - <module> - INFO - program_started
2024-04-30 20:05:20,321 - uvicorn.error - INFO - Started server process [49975]
2024-04-30 20:05:20,322 - uvicorn.error - INFO - Waiting for application startup.
2024-04-30 20:05:20,322 - uvicorn.error - INFO - Application startup complete.
2024-04-30 21:19:47,041 - uvicorn.error - INFO - Shutting down
2024-04-30 21:19:47,143 - uvicorn.error - INFO - Waiting for application shutdown.
2024-04-30 21:19:47,144 - uvicorn.error - INFO - Application shutdown complete.
2024-04-30 21:19:47,144 - uvicorn.error - INFO - Finished server process [49975]
2024-04-30 21:19:47,203 - uvicorn.error - INFO - Stopping reloader process [20485]
2024-05-01 09:29:21,392 - uvicorn.error - INFO - Will watch for changes in these directories: ['/mnt/e/cura/cura_backend']
2024-05-01 09:29:21,393 - uvicorn.error - ERROR - [Errno 98] Address already in use
2024-05-01 09:29:40,336 - uvicorn.error - INFO - Will watch for changes in these directories: ['/mnt/e/cura/cura_backend']
2024-05-01 09:29:40,336 - uvicorn.error - ERROR - [Errno 98] Address already in use
2024-05-01 09:30:35,981 - uvicorn.error - INFO - Will watch for changes in these directories: ['/mnt/e/cura/cura_backend']
2024-05-01 09:30:35,982 - uvicorn.error - INFO - Uvicorn running on http://127.0.0.1:8000 (Press CTRL+C to quit)
2024-05-01 09:30:35,983 - uvicorn.error - INFO - Started reloader process [117266] using statreload
2024-05-01 09:30:36,179 - asyncio - __init__ - DEBUG - Using selector: EpollSelector
2024-05-01 09:30:37,124 - main - <module> - INFO - program_started
2024-05-01 09:30:37,125 - uvicorn.error - INFO - Started server process [117269]
2024-05-01 09:30:37,125 - uvicorn.error - INFO - Waiting for application startup.
2024-05-01 09:30:37,126 - uvicorn.error - INFO - Application startup complete.
2024-05-01 09:30:38,225 - uvicorn.access - send - INFO - 127.0.0.1:52024 - "GET /docs HTTP/1.1" 200
2024-05-01 09:30:38,460 - uvicorn.access - send - INFO - 127.0.0.1:52024 - "GET /openapi.json HTTP/1.1" 200
Traceback (most recent call last):
  File "/mnt/e/cura/cura_backend/./main.py", line 4250, in forgot_password_email
    msg = logMessage(cursor,query,payload['username'])
  File "/mnt/e/cura/cura_backend/./main.py", line 15, in logMessage
    cursor.execute(query,arr)
TypeError: not all arguments converted during string formatting
2024-05-01 09:31:04,794 - root - forgot_password_email - INFO - None
2024-05-01 09:31:04,795 - uvicorn.access - send - INFO - 127.0.0.1:53904 - "POST /forgotPasswordEmail HTTP/1.1" 500
2024-05-01 09:31:04,796 - uvicorn.error - ERROR - Exception in ASGI application
Traceback (most recent call last):
  File "/mnt/e/cura/cura_backend/./main.py", line 4250, in forgot_password_email
    msg = logMessage(cursor,query,payload['username'])
  File "/mnt/e/cura/cura_backend/./main.py", line 15, in logMessage
    cursor.execute(query,arr)
TypeError: not all arguments converted during string formatting

During handling of the above exception, another exception occurred:

Traceback (most recent call last):
  File "/usr/lib/python3/dist-packages/uvicorn/protocols/http/h11_impl.py", line 373, in run_asgi
    result = await app(self.scope, self.receive, self.send)
  File "/usr/lib/python3/dist-packages/uvicorn/middleware/proxy_headers.py", line 75, in __call__
    return await self.app(scope, receive, send)
  File "/home/rudra/.local/lib/python3.10/site-packages/fastapi/applications.py", line 1054, in __call__
    await super().__call__(scope, receive, send)
  File "/home/rudra/.local/lib/python3.10/site-packages/starlette/applications.py", line 123, in __call__
    await self.middleware_stack(scope, receive, send)
  File "/home/rudra/.local/lib/python3.10/site-packages/starlette/middleware/errors.py", line 186, in __call__
    raise exc
  File "/home/rudra/.local/lib/python3.10/site-packages/starlette/middleware/errors.py", line 164, in __call__
    await self.app(scope, receive, _send)
  File "/home/rudra/.local/lib/python3.10/site-packages/starlette/middleware/cors.py", line 93, in __call__
    await self.simple_response(scope, receive, send, request_headers=headers)
  File "/home/rudra/.local/lib/python3.10/site-packages/starlette/middleware/cors.py", line 148, in simple_response
    await self.app(scope, receive, send)
  File "/home/rudra/.local/lib/python3.10/site-packages/starlette/middleware/exceptions.py", line 65, in __call__
    await wrap_app_handling_exceptions(self.app, conn)(scope, receive, send)
  File "/home/rudra/.local/lib/python3.10/site-packages/starlette/_exception_handler.py", line 64, in wrapped_app
    raise exc
  File "/home/rudra/.local/lib/python3.10/site-packages/starlette/_exception_handler.py", line 53, in wrapped_app
    await app(scope, receive, sender)
  File "/home/rudra/.local/lib/python3.10/site-packages/starlette/routing.py", line 756, in __call__
    await self.middleware_stack(scope, receive, send)
  File "/home/rudra/.local/lib/python3.10/site-packages/starlette/routing.py", line 776, in app
    await route.handle(scope, receive, send)
  File "/home/rudra/.local/lib/python3.10/site-packages/starlette/routing.py", line 297, in handle
    await self.app(scope, receive, send)
  File "/home/rudra/.local/lib/python3.10/site-packages/starlette/routing.py", line 77, in app
    await wrap_app_handling_exceptions(app, request)(scope, receive, send)
  File "/home/rudra/.local/lib/python3.10/site-packages/starlette/_exception_handler.py", line 64, in wrapped_app
    raise exc
  File "/home/rudra/.local/lib/python3.10/site-packages/starlette/_exception_handler.py", line 53, in wrapped_app
    await app(scope, receive, sender)
  File "/home/rudra/.local/lib/python3.10/site-packages/starlette/routing.py", line 72, in app
    response = await func(request)
  File "/home/rudra/.local/lib/python3.10/site-packages/fastapi/routing.py", line 278, in app
    raw_response = await run_endpoint_function(
  File "/home/rudra/.local/lib/python3.10/site-packages/fastapi/routing.py", line 191, in run_endpoint_function
    return await dependant.call(**values)
  File "/mnt/e/cura/cura_backend/./main.py", line 4262, in forgot_password_email
    return giveFailure('Invalid Credentials',payload['user_id'],role_access_status)
KeyError: 'user_id'
2024-05-01 09:31:19,695 - uvicorn.error - WARNING - StatReload detected file change in 'main.py'. Reloading...
2024-05-01 09:31:19,704 - uvicorn.error - INFO - Shutting down
2024-05-01 09:31:19,806 - uvicorn.error - INFO - Waiting for application shutdown.
2024-05-01 09:31:19,807 - uvicorn.error - INFO - Application shutdown complete.
2024-05-01 09:31:19,807 - uvicorn.error - INFO - Finished server process [117269]
2024-05-01 09:31:20,019 - asyncio - __init__ - DEBUG - Using selector: EpollSelector
2024-05-01 09:31:20,937 - main - <module> - INFO - program_started
2024-05-01 09:31:20,938 - uvicorn.error - INFO - Started server process [117452]
2024-05-01 09:31:20,938 - uvicorn.error - INFO - Waiting for application startup.
2024-05-01 09:31:20,939 - uvicorn.error - INFO - Application startup complete.
Traceback (most recent call last):
  File "/mnt/e/cura/cura_backend/./main.py", line 4250, in forgot_password_email
    msg = logMessage(cursor,query,payload['username'])
  File "/mnt/e/cura/cura_backend/./main.py", line 15, in logMessage
    cursor.execute(query,arr)
TypeError: not all arguments converted during string formatting
2024-05-01 09:31:22,816 - root - forgot_password_email - INFO - None
2024-05-01 09:31:22,818 - uvicorn.access - send - INFO - 127.0.0.1:42248 - "POST /forgotPasswordEmail HTTP/1.1" 200
2024-05-01 09:31:42,699 - uvicorn.error - WARNING - StatReload detected file change in 'main.py'. Reloading...
2024-05-01 09:31:42,714 - uvicorn.error - INFO - Shutting down
2024-05-01 09:31:42,815 - uvicorn.error - INFO - Waiting for application shutdown.
2024-05-01 09:31:42,816 - uvicorn.error - INFO - Application shutdown complete.
2024-05-01 09:31:42,816 - uvicorn.error - INFO - Finished server process [117452]
2024-05-01 09:31:43,058 - asyncio - __init__ - DEBUG - Using selector: EpollSelector
2024-05-01 09:31:43,889 - main - <module> - INFO - program_started
2024-05-01 09:31:43,890 - uvicorn.error - INFO - Started server process [117549]
2024-05-01 09:31:43,890 - uvicorn.error - INFO - Waiting for application startup.
2024-05-01 09:31:43,890 - uvicorn.error - INFO - Application startup complete.
2024-05-01 09:31:45,802 - root - forgot_password_email - INFO - QUERY IS : <SELECT email1 FROM usertable where username = 'ruderaw'>
2024-05-01 09:31:45,804 - uvicorn.access - send - INFO - 127.0.0.1:51412 - "POST /forgotPasswordEmail HTTP/1.1" 200
2024-05-01 09:31:53,550 - root - forgot_password_email - INFO - QUERY IS : <SELECT email1 FROM usertable where username = 'aryan'>
Traceback (most recent call last):
  File "/mnt/e/cura/cura_backend/./main.py", line 4258, in forgot_password_email
    return giveSuccess(None,None,{"Email ID":email[0]})
TypeError: 'NoneType' object is not subscriptable
2024-05-01 09:31:53,563 - root - forgot_password_email - INFO - None
2024-05-01 09:31:53,564 - uvicorn.access - send - INFO - 127.0.0.1:51428 - "POST /forgotPasswordEmail HTTP/1.1" 200
2024-05-01 09:32:50,029 - root - forgot_password_email - INFO - QUERY IS : <SELECT email1 FROM usertable where username = 'aryan_ashish'>
2024-05-01 09:32:50,031 - uvicorn.access - send - INFO - 127.0.0.1:41774 - "POST /forgotPasswordEmail HTTP/1.1" 200
2024-05-01 09:32:55,431 - root - forgot_password_email - INFO - QUERY IS : <SELECT email1 FROM usertable where username = ''>
Traceback (most recent call last):
  File "/mnt/e/cura/cura_backend/./main.py", line 4258, in forgot_password_email
    return giveSuccess(None,None,{"Email ID":email[0]})
TypeError: 'NoneType' object is not subscriptable
2024-05-01 09:32:55,433 - root - forgot_password_email - INFO - None
2024-05-01 09:32:55,434 - uvicorn.access - send - INFO - 127.0.0.1:41784 - "POST /forgotPasswordEmail HTTP/1.1" 200
2024-05-01 09:33:13,282 - uvicorn.error - WARNING - StatReload detected file change in 'main.py'. Reloading...
2024-05-01 09:33:13,335 - uvicorn.error - INFO - Shutting down
2024-05-01 09:33:13,435 - uvicorn.error - INFO - Waiting for application shutdown.
2024-05-01 09:33:13,436 - uvicorn.error - INFO - Application shutdown complete.
2024-05-01 09:33:13,437 - uvicorn.error - INFO - Finished server process [117549]
2024-05-01 09:33:13,669 - asyncio - __init__ - DEBUG - Using selector: EpollSelector
2024-05-01 09:33:14,401 - main - <module> - INFO - program_started
2024-05-01 09:33:14,402 - uvicorn.error - INFO - Started server process [117964]
2024-05-01 09:33:14,402 - uvicorn.error - INFO - Waiting for application startup.
2024-05-01 09:33:14,403 - uvicorn.error - INFO - Application startup complete.
2024-05-01 09:33:15,141 - root - forgot_password_email - INFO - QUERY IS : <SELECT email1 FROM usertable where username = ''>
2024-05-01 09:33:15,141 - root - forgot_password_email - INFO - None
Traceback (most recent call last):
  File "/mnt/e/cura/cura_backend/./main.py", line 4259, in forgot_password_email
    return giveSuccess(None,None,{"Email ID":email[0]})
TypeError: 'NoneType' object is not subscriptable
2024-05-01 09:33:15,158 - root - forgot_password_email - INFO - None
2024-05-01 09:33:15,159 - uvicorn.access - send - INFO - 127.0.0.1:40662 - "POST /forgotPasswordEmail HTTP/1.1" 200
2024-05-01 09:33:27,866 - uvicorn.error - WARNING - StatReload detected file change in 'main.py'. Reloading...
2024-05-01 09:33:27,902 - uvicorn.error - INFO - Shutting down
2024-05-01 09:33:28,003 - uvicorn.error - INFO - Waiting for application shutdown.
2024-05-01 09:33:28,003 - uvicorn.error - INFO - Application shutdown complete.
2024-05-01 09:33:28,004 - uvicorn.error - INFO - Finished server process [117964]
2024-05-01 09:33:28,302 - asyncio - __init__ - DEBUG - Using selector: EpollSelector
2024-05-01 09:33:29,183 - main - <module> - INFO - program_started
2024-05-01 09:33:29,184 - uvicorn.error - INFO - Started server process [118028]
2024-05-01 09:33:29,184 - uvicorn.error - INFO - Waiting for application startup.
2024-05-01 09:33:29,185 - uvicorn.error - INFO - Application startup complete.
2024-05-01 09:33:30,130 - root - forgot_password_email - INFO - QUERY IS : <SELECT email1 FROM usertable where username = ''>
2024-05-01 09:33:30,131 - root - forgot_password_email - INFO - None
2024-05-01 09:33:30,132 - uvicorn.access - send - INFO - 127.0.0.1:44072 - "POST /forgotPasswordEmail HTTP/1.1" 200
2024-05-01 09:34:36,080 - root - forgot_password_email - INFO - QUERY IS : <SELECT email1 FROM usertable where username = 'ruderaw'>
2024-05-01 09:34:36,081 - root - forgot_password_email - INFO - ('rudraemail1@email.com',)
2024-05-01 09:34:36,082 - uvicorn.access - send - INFO - 127.0.0.1:35576 - "POST /forgotPasswordEmail HTTP/1.1" 200
2024-05-01 09:34:53,320 - root - forgot_password_email - INFO - QUERY IS : <SELECT email1 FROM usertable where username = ''>
2024-05-01 09:34:53,321 - root - forgot_password_email - INFO - None
2024-05-01 09:34:53,322 - uvicorn.access - send - INFO - 127.0.0.1:37904 - "POST /forgotPasswordEmail HTTP/1.1" 200
2024-05-01 09:40:08,756 - uvicorn.error - WARNING - StatReload detected file change in 'main.py'. Reloading...
2024-05-01 09:40:08,816 - uvicorn.error - INFO - Shutting down
2024-05-01 09:40:08,917 - uvicorn.error - INFO - Waiting for application shutdown.
2024-05-01 09:40:08,918 - uvicorn.error - INFO - Application shutdown complete.
2024-05-01 09:40:08,918 - uvicorn.error - INFO - Finished server process [118028]
2024-05-01 09:40:09,131 - asyncio - __init__ - DEBUG - Using selector: EpollSelector
Process SpawnProcess-6:
Traceback (most recent call last):
  File "/usr/lib/python3.10/multiprocessing/process.py", line 314, in _bootstrap
    self.run()
  File "/usr/lib/python3.10/multiprocessing/process.py", line 108, in run
    self._target(*self._args, **self._kwargs)
  File "/usr/lib/python3/dist-packages/uvicorn/subprocess.py", line 76, in subprocess_started
    target(sockets=sockets)
  File "/usr/lib/python3/dist-packages/uvicorn/server.py", line 68, in run
    return asyncio.run(self.serve(sockets=sockets))
  File "/usr/lib/python3.10/asyncio/runners.py", line 44, in run
    return loop.run_until_complete(main)
  File "/usr/lib/python3.10/asyncio/base_events.py", line 649, in run_until_complete
    return future.result()
  File "/usr/lib/python3/dist-packages/uvicorn/server.py", line 76, in serve
    config.load()
  File "/usr/lib/python3/dist-packages/uvicorn/config.py", line 448, in load
    self.loaded_app = import_from_string(self.app)
  File "/usr/lib/python3/dist-packages/uvicorn/importer.py", line 21, in import_from_string
    module = importlib.import_module(module_str)
  File "/usr/lib/python3.10/importlib/__init__.py", line 126, in import_module
    return _bootstrap._gcd_import(name[level:], package, level)
  File "<frozen importlib._bootstrap>", line 1050, in _gcd_import
  File "<frozen importlib._bootstrap>", line 1027, in _find_and_load
  File "<frozen importlib._bootstrap>", line 1006, in _find_and_load_unlocked
  File "<frozen importlib._bootstrap>", line 688, in _load_unlocked
  File "<frozen importlib._bootstrap_external>", line 879, in exec_module
  File "<frozen importlib._bootstrap_external>", line 1017, in get_code
  File "<frozen importlib._bootstrap_external>", line 947, in source_to_code
  File "<frozen importlib._bootstrap>", line 241, in _call_with_frames_removed
  File "/mnt/e/cura/cura_backend/./main.py", line 4278
    logger.info("program_started")
SyntaxError: expected 'except' or 'finally' block
2024-05-01 09:41:09,514 - uvicorn.error - WARNING - StatReload detected file change in 'main.py'. Reloading...
2024-05-01 09:41:09,674 - asyncio - __init__ - DEBUG - Using selector: EpollSelector
2024-05-01 09:41:10,520 - main - <module> - INFO - program_started
2024-05-01 09:41:10,521 - uvicorn.error - INFO - Started server process [119894]
2024-05-01 09:41:10,522 - uvicorn.error - INFO - Waiting for application startup.
2024-05-01 09:41:10,523 - uvicorn.error - INFO - Application startup complete.
2024-05-01 09:41:10,525 - uvicorn.access - send - INFO - 127.0.0.1:46698 - "GET /docs HTTP/1.1" 200
2024-05-01 09:41:10,787 - uvicorn.access - send - INFO - 127.0.0.1:46698 - "GET /openapi.json HTTP/1.1" 200
Traceback (most recent call last):
  File "/mnt/e/cura/cura_backend/./main.py", line 4270, in reset_password
    newp = bcrypt.hashpw(payload['passoword'])
KeyError: 'passoword'
2024-05-01 09:42:46,593 - root - reset_password - INFO - None
2024-05-01 09:42:46,594 - uvicorn.access - send - INFO - 127.0.0.1:43020 - "POST /resetPassword HTTP/1.1" 200
2024-05-01 09:42:57,343 - uvicorn.error - WARNING - StatReload detected file change in 'main.py'. Reloading...
2024-05-01 09:42:57,392 - uvicorn.error - INFO - Shutting down
2024-05-01 09:42:57,493 - uvicorn.error - INFO - Waiting for application shutdown.
2024-05-01 09:42:57,494 - uvicorn.error - INFO - Application shutdown complete.
2024-05-01 09:42:57,494 - uvicorn.error - INFO - Finished server process [119894]
2024-05-01 09:42:57,751 - asyncio - __init__ - DEBUG - Using selector: EpollSelector
2024-05-01 09:42:58,596 - main - <module> - INFO - program_started
2024-05-01 09:42:58,597 - uvicorn.error - INFO - Started server process [120334]
2024-05-01 09:42:58,598 - uvicorn.error - INFO - Waiting for application startup.
2024-05-01 09:42:58,599 - uvicorn.error - INFO - Application startup complete.
Traceback (most recent call last):
  File "/mnt/e/cura/cura_backend/./main.py", line 4270, in reset_password
    newp = bcrypt.hashpw(payload['password'])
TypeError: hashpw() missing 1 required positional argument: 'salt'
2024-05-01 09:43:00,313 - root - reset_password - INFO - None
2024-05-01 09:43:00,314 - uvicorn.access - send - INFO - 127.0.0.1:55502 - "POST /resetPassword HTTP/1.1" 200
2024-05-01 09:43:25,530 - uvicorn.error - WARNING - StatReload detected file change in 'main.py'. Reloading...
2024-05-01 09:43:25,601 - uvicorn.error - INFO - Shutting down
2024-05-01 09:43:25,702 - uvicorn.error - INFO - Waiting for application shutdown.
2024-05-01 09:43:25,703 - uvicorn.error - INFO - Application shutdown complete.
2024-05-01 09:43:25,704 - uvicorn.error - INFO - Finished server process [120334]
2024-05-01 09:43:25,913 - asyncio - __init__ - DEBUG - Using selector: EpollSelector
2024-05-01 09:43:26,753 - main - <module> - INFO - program_started
2024-05-01 09:43:26,754 - uvicorn.error - INFO - Started server process [120450]
2024-05-01 09:43:26,754 - uvicorn.error - INFO - Waiting for application startup.
2024-05-01 09:43:26,755 - uvicorn.error - INFO - Application startup complete.
Traceback (most recent call last):
  File "/mnt/e/cura/cura_backend/./main.py", line 4270, in reset_password
    newp = bcrypt.hashpw(payload['password'],bcrypt.gensalt())
TypeError: argument 'password': 'str' object cannot be converted to 'PyBytes'
2024-05-01 09:43:29,022 - root - reset_password - INFO - None
2024-05-01 09:43:29,023 - uvicorn.access - send - INFO - 127.0.0.1:57572 - "POST /resetPassword HTTP/1.1" 200
2024-05-01 09:43:43,184 - uvicorn.error - WARNING - StatReload detected file change in 'main.py'. Reloading...
2024-05-01 09:43:43,213 - uvicorn.error - INFO - Shutting down
2024-05-01 09:43:43,314 - uvicorn.error - INFO - Waiting for application shutdown.
2024-05-01 09:43:43,315 - uvicorn.error - INFO - Application shutdown complete.
2024-05-01 09:43:43,315 - uvicorn.error - INFO - Finished server process [120450]
2024-05-01 09:43:43,539 - asyncio - __init__ - DEBUG - Using selector: EpollSelector
2024-05-01 09:43:44,409 - main - <module> - INFO - program_started
2024-05-01 09:43:44,410 - uvicorn.error - INFO - Started server process [120527]
2024-05-01 09:43:44,411 - uvicorn.error - INFO - Waiting for application startup.
2024-05-01 09:43:44,412 - uvicorn.error - INFO - Application startup complete.
2024-05-01 09:43:46,707 - root - reset_password - INFO - b'$2b$12$JRf8dr5B2ZNYlIUN1lq3z.MHfRwm9ScOYpxHvbOkxlzhq7i.VlvtG'
2024-05-01 09:43:46,708 - root - reset_password - INFO - b"UPDATE usertable SET password = '\\x243262243132244a52663864723542325a4e596c49554e316c71337a2e4d486652776d3953634f5970784876624f6b786c7a687137692e566c767447'::bytea WHERE username = 'ruderaw'"
2024-05-01 09:43:46,709 - uvicorn.access - send - INFO - 127.0.0.1:44104 - "POST /resetPassword HTTP/1.1" 200
2024-05-01 09:45:56,727 - uvicorn.error - WARNING - StatReload detected file change in 'main.py'. Reloading...
2024-05-01 09:45:56,750 - uvicorn.error - INFO - Shutting down
2024-05-01 09:45:56,851 - uvicorn.error - INFO - Waiting for application shutdown.
2024-05-01 09:45:56,851 - uvicorn.error - INFO - Application shutdown complete.
2024-05-01 09:45:56,852 - uvicorn.error - INFO - Finished server process [120527]
2024-05-01 09:45:57,055 - asyncio - __init__ - DEBUG - Using selector: EpollSelector
2024-05-01 09:45:57,916 - main - <module> - INFO - program_started
2024-05-01 09:45:57,917 - uvicorn.error - INFO - Started server process [121072]
2024-05-01 09:45:57,917 - uvicorn.error - INFO - Waiting for application startup.
2024-05-01 09:45:57,919 - uvicorn.error - INFO - Application startup complete.
2024-05-01 09:46:03,582 - root - reset_password - INFO - b'$2b$12$DEWmTusrhsiDSlkZBXx2Mu0NZVtJZorkJgzI1budwGsXSwUanrs7.'
2024-05-01 09:46:03,582 - root - reset_password - INFO - b"UPDATE usertable SET password = '\\x243262243132244445576d5475737268736944536c6b5a425878324d75304e5a56744a5a6f726b4a677a493162756477477358537755616e7273372e'::bytea WHERE username = 'ruderaw'"
2024-05-01 09:46:03,584 - uvicorn.access - send - INFO - 127.0.0.1:55292 - "POST /resetPassword HTTP/1.1" 200
2024-05-01 09:47:33,280 - uvicorn.error - WARNING - StatReload detected file change in 'main.py'. Reloading...
2024-05-01 09:47:33,283 - uvicorn.error - INFO - Shutting down
2024-05-01 09:47:33,384 - uvicorn.error - INFO - Waiting for application shutdown.
2024-05-01 09:47:33,385 - uvicorn.error - INFO - Application shutdown complete.
2024-05-01 09:47:33,385 - uvicorn.error - INFO - Finished server process [121072]
2024-05-01 09:47:33,667 - asyncio - __init__ - DEBUG - Using selector: EpollSelector
2024-05-01 09:47:34,510 - main - <module> - INFO - program_started
2024-05-01 09:47:34,511 - uvicorn.error - INFO - Started server process [121465]
2024-05-01 09:47:34,512 - uvicorn.error - INFO - Waiting for application startup.
2024-05-01 09:47:34,513 - uvicorn.error - INFO - Application startup complete.
2024-05-01 09:47:37,669 - root - reset_password - INFO - $2b$12$ntgbYR9NNw052U1VmJ1hKuhy7bh7bonERiZvciafKnMrYO7yZswFe
2024-05-01 09:47:37,670 - root - reset_password - INFO - b"UPDATE usertable SET password = '$2b$12$ntgbYR9NNw052U1VmJ1hKuhy7bh7bonERiZvciafKnMrYO7yZswFe' WHERE username = 'ruderaw'"
2024-05-01 09:47:37,671 - uvicorn.access - send - INFO - 127.0.0.1:44042 - "POST /resetPassword HTTP/1.1" 200
2024-05-01 16:09:52,768 - uvicorn.error - WARNING - StatReload detected file change in 'main.py'. Reloading...
2024-05-01 16:09:52,852 - uvicorn.error - INFO - Shutting down
2024-05-01 16:09:52,957 - uvicorn.error - INFO - Waiting for application shutdown.
2024-05-01 16:09:52,962 - uvicorn.error - INFO - Application shutdown complete.
2024-05-01 16:09:52,963 - uvicorn.error - INFO - Finished server process [121465]
2024-05-01 16:09:53,308 - asyncio - __init__ - DEBUG - Using selector: EpollSelector
2024-05-01 16:09:53,988 - main - <module> - INFO - program_started
2024-05-01 16:09:53,988 - uvicorn.error - INFO - Started server process [188063]
2024-05-01 16:09:53,989 - uvicorn.error - INFO - Waiting for application startup.
2024-05-01 16:09:53,989 - uvicorn.error - INFO - Application startup complete.
